Workbook

Sheet 29 - FIA
B1: =COUNTIF(B9:B222,">0") -> 70 | E1: =COUNTIF(E9:E222,">0") -> 79 | K1: Act Share | L1: Bmk | M1: Mandato | N1: Modelo 2.0 | O1: Meta | R1: Modelos | AE1: Interações | AK1: Clusters
K2: Meta | L2: =SQRT(SUMSQ(L9:L222)^2) -> 0.027432 | M2: =SQRT(SUMSQ(N9:N222)^2) -> 0.011518785 | N2: =SQRT(SUMSQ(Q9:Q222)^2) -> 0.019144169
E3: MF - Meta | F3: =SUMPRODUCT($D$9:$D$222,F9:F222) -> 0.03804 | K3: MF | L3: =SQRT(SUMSQ(C9:C222)^2) -> 0.02671025 | M3: =SQRT(SUMSQ(O9:O222)^2) -> 0.007646534 | O3: =SQRT(SUMSQ(D9:D222)^2) -> 0.00220325
E4: Meta - 2.0 | F4: =SUMPRODUCT($Q$9:$Q$222,F9:F222) -> 0.003124216 | Q4: MF - Meta | R4: =SUMPRODUCT($D$9:$D$222,R9:R222) -> -0.009286 | S4: =SUMPRODUCT($D$9:$D$222,S9:S222) -> 0.0183195 | T4: =SUMPRODUCT($D$9:$D$222,T9:T222) -> -0.0313 | U4: =SUMPRODUCT($D$9:$D$222,U9:U222) -> 0.0113745 | V4: =SUMPRODUCT($D$9:$D$222,V9:V222) -> 0.0011465 | W4: =SUMPRODUCT($D$9:$D$222,W9:W222) -> 0.02305 | X4: =SUMPRODUCT($D$9:$D$222,X9:X222) -> 0.025756 | Y4: =SUMPRODUCT($D$9:$D$222,Y9:Y222) -> 0.0449465 | ... BK4: =SUMPRODUCT($D$9:$D$222,BK9:BK222) -> -0.01505
E5: Meta - Mandato | F5: =SUMPRODUCT($N$9:$N$222,F9:F222) -> -0.34741047 | Q5: Meta - 2.0 | R5: =SUMPRODUCT($Q$9:$Q$222,R8:R221) -> -0.046471056 | S5: =SUMPRODUCT($Q$9:$Q$222,S8:S221) -> -0.040007952 | T5: =SUMPRODUCT($Q$9:$Q$222,T8:T221) -> -0.017175456 | U5: =SUMPRODUCT($Q$9:$Q$222,U8:U221) -> -0.014608024 | V5: =SUMPRODUCT($Q$9:$Q$222,V8:V221) -> -0.012961558 | W5: =SUMPRODUCT($Q$9:$Q$222,W8:W221) -> 0.00034341668 | X5: =SUMPRODUCT($Q$9:$Q$222,X8:X221) -> 0.014721161 | Y5: =SUMPRODUCT($Q$9:$Q$222,Y8:Y221) -> 0.049570181 | ... BK5: =SUMPRODUCT($Q$9:$Q$222,BK8:BK221) -> -0.072709137 | BM5: =SUMPRODUCT($E$9:$E$226,BM9:BM226) -> 0.095587825
E6: Meta - Bmk | F6: =SUMPRODUCT($L$9:$L$222,F9:F222) -> 0.906315 | G6: =SUMPRODUCT($L$9:$L$222,G9:G222) -> 0.452853 | Q6: Meta - Mandato | R6: =SUMPRODUCT($N$9:$N$222,R9:R222) -> -0.17557389 | S6: =SUMPRODUCT($N$9:$N$222,S9:S222) -> -0.18900412 | T6: =SUMPRODUCT($N$9:$N$222,T9:T222) -> -0.13280321 | U6: =SUMPRODUCT($N$9:$N$222,U9:U222) -> -0.19234175 | V6: =SUMPRODUCT($N$9:$N$222,V9:V222) -> -0.1852904 | W6: =SUMPRODUCT($N$9:$N$222,W9:W222) -> -0.16435662 | X6: =SUMPRODUCT($N$9:$N$222,X9:X222) -> -0.12849361 | Y6: =SUMPRODUCT($N$9:$N$222,Y9:Y222) -> -0.16076573 | ... BK6: =SUMPRODUCT($N$9:$N$222,BK9:BK222) -> -0.084940392 | BM6: =SUMPRODUCT($M$9:$M$226,BM9:BM226) -> 0.21611196
B7: =SUM(B9:B222) -> 0.9995 | E7: =SUM(E9:E222) -> 0.999 | K7: =SUM(K9:K222) -> 1.001 | M7: =SUM(M9:M222) -> 1 | P7: =SUM(P9:P222) -> 1 | Q7: Meta - Bmk | R7: =SUMPRODUCT($L$9:$L$226,R9:R226) -> 0.597192 | S7: =SUMPRODUCT($L$9:$L$226,S9:S226) -> 0.518743 | T7: =SUMPRODUCT($L$9:$L$226,T9:T226) -> 0.634127 | U7: =SUMPRODUCT($L$9:$L$226,U9:U226) -> 0.537394 | V7: =SUMPRODUCT($L$9:$L$226,V9:V226) -> 0.594603 | W7: =SUMPRODUCT($L$9:$L$226,W9:W226) -> 0.483733 | X7: =SUMPRODUCT($L$9:$L$226,X9:X226) -> 0.386664 | Y7: =SUMPRODUCT($L$9:$L$226,Y9:Y226) -> 0.425033 | ... BK7: =SUMPRODUCT($L$9:$L$226,BK9:BK226) -> 0.571743 | BM7: =SUMPRODUCT($K$9:$K$226,BM9:BM226) -> 0.1768178
A8: tickers | B8: MF | C8: MF - Ibov | D8: MF - META | E8: Bmk | F8: exp_ret_score_raw | G8: exp_ret_score | H8: sectors_c2 | I8: sectors_c1 | J8: sectors_dyn | K8: META | L8: act_weights | M8: mandato | N8: META - Mandato | O8: MF - Mandao | P8: modelo 2.0 | Q8: Meta - 2.0 | R8: ew | S8: sw_mom | T8: sw_val | U8: sw_lt_perf | V8: sw_overall | W8: rp_cc | X8: hrp_cc | Y8: mvo_overall_cc_con | Z8: ols | AA8: glmnet_bayes | AB8: rf_bayes | AC8: xgb_bayes | AD8: nn1_bayes | AE8: qv | AF8: garp | AG8: vm | AH8: sv | AI8: sm | AJ8: smcj | AK8: fac_inc_cs_value | AL8: fac_payout_yield | AM8: fac_bs_cs_value | AN8: fac_ts_value | AO8: fac_interm_momentum | AP8: fac_st_momentum | AQ8: fac_lt_profit_growth | AR8: fac_st_profit_growth | AS8: fac_surprise | AT8: fac_bs_profitability | AU8: fac_profit_margins | AV8: fac_quality | AW8: fac_mkt_risk | AX8: fac_leverage | AY8: fac_profit_vol | AZ8: fac_seasonality | BA8: fac_short_interest | BB8: fac_acc_growth | BC8: fac_accruals | BD8: fac_issuance | BE8: fac_st_reversal | BF8: fac_skewness | BG8: fac_max | BH8: fac_lt_reversal | BI8: fac_macro | BJ8: fac_liquidity | BK8: fac_size | BM8: Pessoal
A9: LOGG3 | B9: =K9 -> 0.01 | C9: =B9-E9 -> 0.01 | D9: =B9-K9 -> 0 | E9: =K9-L9 -> 0 | F9: 3.612 | G9: 3.907 | H9: bond_proxies | I9: =VLOOKUP(A9,Setores!$A$2:$C$215,2,0) -> real_estate | J9: =VLOOKUP(A9,Setores!$A$2:$C$215,3,0) -> neutral_beta | K9: 0.01 | L9: 0.01 | M9: =VLOOKUP(A9,'Mandato Ibov'!$B$1:$C$215,2,0) -> 0.017075746 | N9: =K9-M9 -> -0.0070757461 | O9: =B9-M9 -> -0.0070757461 | P9: =VLOOKUP(A9,'Mandato Ibov'!$B$2:$D$215,3,0) -> 0.0094309658 | Q9: =K9-P9 -> 0.00056903422 | R9: 0.753 | S9: 1 | T9: 0.511 | U9: 0.896 | V9: 0.882 | W9: 0.996 | X9: 1 | Y9: 1 | Z9: 0.535 | AA9: 0.54 | AB9: 1 | AC9: 0.991 | AD9: 1 | AE9: 1 | AF9: 0.092 | AG9: 0.797 | AH9: 0.298 | AI9: 0.918 | AJ9: -0.122 | AK9: -0.204 | AL9: 0.327 | AM9: -0.17 | AN9: 0.033 | AO9: 0.439 | AP9: 0.023 | AQ9: -0.072 | AR9: 0.527 | AS9: 0.52 | AT9: -0.109 | AU9: 0.759 | AV9: 0.419 | AW9: 0.344 | AX9: -0.735 | AY9: 0.03 | AZ9: -0.262 | BA9: -0.245 | BB9: 0.135 | BC9: 0.593 | BD9: 0.51 | BE9: -0.351 | BF9: -0.122 | BG9: 0.728 | BH9: -0.416 | BI9: 0.223 | BJ9: 0.369 | BK9: 0.297 | BM9: =10%*AK9+5%*AL9+2.5%*AM9+2.5%*AN9+10%*AO9+10%*AP9+10%*AQ9+5%*AR9+5%*AS9+10%*AT9+5%*AU9+5%*AY9+10%*AV9+10%*AW9 -> 0.188725
A10: FIQE3 | B10: =K10 -> 0.011 | C10: =B10-E10 -> 0.011 | D10: =B10-K10 -> 0 | E10: =K10-L10 -> 0 | F10: 3.612 | G10: 3.66 | H10: bond_proxies | I10: =VLOOKUP(A10,Setores!$A$2:$C$215,2,0) -> telecom | J10: =VLOOKUP(A10,Setores!$A$2:$C$215,3,0) -> low_beta | K10: 0.011 | L10: 0.011 | M10: =VLOOKUP(A10,'Mandato Ibov'!$B$1:$C$215,2,0) -> 0.017075746 | N10: =K10-M10 -> -0.0060757461 | O10: =B10-M10 -> -0.0060757461 | P10: =VLOOKUP(A10,'Mandato Ibov'!$B$2:$D$215,3,0) -> 0.013333522 | Q10: =K10-P10 -> -0.0023335222 | R10: 1 | S10: 1 | T10: 0.642 | U10: 1 | V10: 0.938 | W10: 1 | X10: 1 | Y10: 1 | Z10: 0.687 | AA10: 0.689 | AB10: 1 | AC10: 1 | AD10: 1 | AE10: 0.557 | AF10: 0.002 | AG10: 0.805 | AH10: -0.261 | AI10: 1 | AJ10: 0.752 | AK10: -0.205 | AL10: 0.133 | AM10: -0.805 | AN10: 0.064 | AO10: 0.751 | AP10: 1 | AQ10: 0.293 | AR10: 0.405 | AS10: 0.475 | AT10: 0.417 | AU10: 0.26 | AV10: 0.767 | AW10: 0.426 | AX10: 0.179 | AY10: 0.885 | AZ10: 0.104 | BA10: 0.583 | BB10: -0.299 | BC10: -0.201 | BD10: 0.293 | BE10: -0.371 | BF10: 0.371 | BG10: 0.682 | BH10: -0.527 | BI10: -0.401 | BJ10: 0.717 | BK10: 0.495 | BM10: =10%*AK10+5%*AL10+2.5%*AM10+2.5%*AN10+10%*AO10+10%*AP10+10%*AQ10+5%*AR10+5%*AS10+10%*AT10+5%*AU10+5%*AY10+10%*AV10+10%*AW10 -> 0.434275
A11: BMGB4 | B11: =K11 -> 0.012 | C11: =B11-E11 -> 0.012 | D11: =B11-K11 -> 0 | E11: =K11-L11 -> 0 | F11: 3.612 | G11: 3.634 | H11: pro_cyclicals | I11: =VLOOKUP(A11,Setores!$A$2:$C$215,2,0) -> banks | J11: =VLOOKUP(A11,Setores!$A$2:$C$215,3,0) -> high_beta | K11: 0.012 | L11: 0.012 | M11: =VLOOKUP(A11,'Mandato Ibov'!$B$1:$C$215,2,0) -> 0.017075746 | N11: =K11-M11 -> -0.0050757461 | O11: =B11-M11 -> -0.0050757461 | P11: =VLOOKUP(A11,'Mandato Ibov'!$B$2:$D$215,3,0) -> 0.013333522 | Q11: =K11-P11 -> -0.0013335222 | R11: 0.902 | S11: 1 | T11: 0.817 | U11: 0.911 | V11: 1 | W11: 1 | X11: 1 | Y11: 1 | Z11: 1 | AA11: 1 | AB11: 1 | AC11: 1 | AD11: 1 | AE11: 0.194 | AF11: 1 | AG11: 1 | AH11: 0.251 | AI11: 1 | AJ11: 0.23 | AK11: 0.073 | AL11: 0.54 | AM11: 0.42 | AN11: 0.223 | AO11: 0.561 | AP11: 0.813 | AQ11: 0.557 | AR11: 0.25 | AS11: -0.139 | AT11: 0.002 | AU11: -0.267 | AV11: -0.131 | AW11: 0.515 | AX11: -0.09 | AY11: 0.655 | AZ11: 0.249 | BA11: -0.003 | BB11: 0.126 | BC11: 0.215 | BD11: -0.732 | BE11: -0.363 | BF11: 0.186 | BG11: 0.936 | BH11: -0.81 | BI11: 0.082 | BJ11: 0.64 | BK11: 0.679 | BM11: =10%*AK11+5%*AL11+2.5%*AM11+2.5%*AN11+10%*AO11+10%*AP11+10%*AQ11+5%*AR11+5%*AS11+10%*AT11+5%*AU11+5%*AY11+10%*AV11+10%*AW11 -> 0.307025
A12: WIZC3 | B12: =K12 -> 0.013 | C12: =B12-E12 -> 0.013 | D12: =B12-K12 -> 0 | E12: =K12-L12 -> 0 | F12: 3.612 | G12: 3.59 | H12: defensives | I12: =VLOOKUP(A12,Setores!$A$2:$C$215,2,0) -> financial_services | J12: =VLOOKUP(A12,Setores!$A$2:$C$215,3,0) -> very_low_beta | K12: 0.013 | L12: 0.013 | M12: =VLOOKUP(A12,'Mandato Ibov'!$B$1:$C$215,2,0) -> 0.017075746 | N12: =K12-M12 -> -0.0040757461 | O12: =B12-M12 -> -0.0040757461 | P12: =VLOOKUP(A12,'Mandato Ibov'!$B$2:$D$215,3,0) -> 0.012109689 | Q12: =K12-P12 -> 0.00089031105 | R12: 1 | S12: 0.966 | T12: 1 | U12: 1 | V12: 1 | W12: 1 | X12: 1 | Y12: 0.631 | Z12: 0.724 | AA12: 0.723 | AB12: 1 | AC12: 1 | AD12: 0.99 | AE12: 1 | AF12: 0.205 | AG12: 0.421 | AH12: 0.546 | AI12: 0.997 | AJ12: 1 | AK12: 0.551 | AL12: -0.187 | AM12: -0.263 | AN12: 0.055 | AO12: 0.036 | AP12: 0.118 | AQ12: 0.271 | AR12: 0.157 | AS12: -0.346 | AT12: 0.724 | AU12: 0.403 | AV12: 1 | AW12: 0.363 | AX12: -0.062 | AY12: 0.804 | AZ12: 0.496 | BA12: -0.043 | BB12: 0.05 | BC12: 0.06 | BD12: 0.535 | BE12: -0.021 | BF12: 1 | BG12: 0.641 | BH12: -0.361 | BI12: -0.367 | BJ12: 0.614 | BK12: 0.693 | BM12: =10%*AK12+5%*AL12+2.5%*AM12+2.5%*AN12+10%*AO12+10%*AP12+10%*AQ12+5%*AR12+5%*AS12+10%*AT12+5%*AU12+5%*AY12+10%*AV12+10%*AW12 -> 0.34265
A13: JHSF3 | B13: =K13 -> 0.009 | C13: =B13-E13 -> 0.009 | D13: =B13-K13 -> 0 | E13: =K13-L13 -> 0 | F13: 3.612 | G13: 3.401 | H13: pro_cyclicals | I13: =VLOOKUP(A13,Setores!$A$2:$C$215,2,0) -> homebuilders | J13: =VLOOKUP(A13,Setores!$A$2:$C$215,3,0) -> very_high_beta | K13: 0.009 | L13: 0.009 | M13: =VLOOKUP(A13,'Mandato Ibov'!$B$1:$C$215,2,0) -> 0.017075746 | N13: =K13-M13 -> -0.0080757461 | O13: =B13-M13 -> -0.0080757461 | P13: =VLOOKUP(A13,'Mandato Ibov'!$B$2:$D$215,3,0) -> 0.013333522 | Q13: =K13-P13 -> -0.0043335222 | R13: 1 | S13: 1 | T13: 0.606 | U13: 1 | V13: 1 | W13: 1 | X13: 0.973 | Y13: 1 | Z13: 0.695 | AA13: 0.691 | AB13: 0.929 | AC13: 0.859 | AD13: 1 | AE13: 1 | AF13: 0.938 | AG13: 1 | AH13: -0.415 | AI13: 0.728 | AJ13: 0.253 | AK13: 0.296 | AL13: -0.053 | AM13: -0.411 | AN13: 0.313 | AO13: 0.632 | AP13: 0.927 | AQ13: 0.532 | AR13: 0.182 | AS13: 0.309 | AT13: 0.33 | AU13: 0.414 | AV13: 0.908 | AW13: -0.045 | AX13: 0.136 | AY13: -0.176 | AZ13: 0.537 | BA13: -0.253 | BB13: 0.008 | BC13: 0.541 | BD13: 0.647 | BE13: 0.217 | BF13: 0.151 | BG13: 0.142 | BH13: -0.857 | BI13: 0.704 | BJ13: -0.051 | BK13: -0.258 | BM13: =10%*AK13+5%*AL13+2.5%*AM13+2.5%*AN13+10%*AO13+10%*AP13+10%*AQ13+5%*AR13+5%*AS13+10%*AT13+5%*AU13+5%*AY13+10%*AV13+10%*AW13 -> 0.38935
A14: ALLD3 | B14: =K14 -> 0.007 | C14: =B14-E14 -> 0.007 | D14: =B14-K14 -> 0 | E14: =K14-L14 -> 0 | F14: 3.612 | G14: 2.765 | H14: pro_cyclicals | I14: =VLOOKUP(A14,Setores!$A$2:$C$215,2,0) -> consumer_durables | J14: =VLOOKUP(A14,Setores!$A$2:$C$215,3,0) -> very_low_beta | K14: 0.007 | L14: 0.007 | M14: =VLOOKUP(A14,'Mandato Ibov'!$B$1:$C$215,2,0) -> 0.017075746 | N14: =K14-M14 -> -0.010075746 | O14: =B14-M14 -> -0.010075746 | P14: =VLOOKUP(A14,'Mandato Ibov'!$B$2:$D$215,3,0) -> 0.013333522 | Q14: =K14-P14 -> -0.0063335222 | R14: 1 | S14: 0.646 | T14: 1 | U14: 1 | V14: 1 | W14: 1 | X14: 1 | Y14: 0.737 | Z14: 1 | AA14: 1 | AB14: 0.735 | AC14: 0.749 | AD14: 0.928 | AE14: 1 | AF14: 1 | AG14: -0.138 | AH14: 1 | AI14: -0.315 | AJ14: 1 | AK14: 0.882 | AL14: 1 | AM14: 0.451 | AN14: 0.652 | AO14: -0.808 | AP14: -0.665 | AQ14: 0.303 | AR14: 0.594 | AS14: 0.097 | AT14: 0.697 | AU14: -0.548 | AV14: 0.908 | AW14: 0.326 | AX14: 0.054 | AY14: 0.47 | AZ14: 0.604 | BA14: 0.25 | BB14: 0.292 | BC14: 0.303 | BD14: 0.594 | BE14: 0.043 | BF14: 0.097 | BG14: 0.907 | BH14: -0.345 | BI14: -0.437 | BJ14: 0.521 | BK14: 0.802 | BM14: =10%*AK14+5%*AL14+2.5%*AM14+2.5%*AN14+10%*AO14+10%*AP14+10%*AQ14+5%*AR14+5%*AS14+10%*AT14+5%*AU14+5%*AY14+10%*AV14+10%*AW14 -> 0.272525
A15: RIAA3 | B15: =K15 -> 0.01 | C15: =B15-E15 -> 0.01 | D15: =B15-K15 -> 0 | E15: =K15-L15 -> 0 | F15: 3.529 | G15: 2.727 | H15: pro_cyclicals | I15: =VLOOKUP(A15,Setores!$A$2:$C$215,2,0) -> apparel | J15: =VLOOKUP(A15,Setores!$A$2:$C$215,3,0) -> very_high_beta | K15: 0.01 | L15: 0.01 | M15: =VLOOKUP(A15,'Mandato Ibov'!$B$1:$C$215,2,0) -> 0.016684757 | N15: =K15-M15 -> -0.0066847573 | O15: =B15-M15 -> -0.0066847573 | P15: =VLOOKUP(A15,'Mandato Ibov'!$B$2:$D$215,3,0) -> 0.0098152609 | Q15: =K15-P15 -> 0.00018473915 | R15: 0.993 | S15: 0.849 | T15: 0.797 | U15: 1 | V15: 0.969 | W15: 0.786 | X15: 0.514 | Y15: 0.755 | Z15: 0.757 | AA15: 0.752 | AB15: 0.778 | AC15: 0.798 | AD15: 0.956 | AE15: 1 | AF15: 1 | AG15: 0.418 | AH15: 0.137 | AI15: 0.133 | AJ15: 0.61 | AK15: 0.556 | AL15: 0.091 | AM15: -0.118 | AN15: 0.478 | AO15: 0.227 | AP15: -0.081 | AQ15: 0.584 | AR15: 0.768 | AS15: 0.384 | AT15: 0.428 | AU15: -0.1 | AV15: 0.958 | AW15: -0.591 | AX15: 0.077 | AY15: 0.423 | AZ15: 0.629 | BA15: -0.314 | BB15: 0.211 | BC15: 0.019 | BD15: 0.625 | BE15: 0.234 | BF15: -0.288 | BG15: 0.204 | BH15: -0.488 | BI15: 0.292 | BJ15: 0.253 | BK15: 0.206 | BM15: =10%*AK15+5%*AL15+2.5%*AM15+2.5%*AN15+10%*AO15+10%*AP15+10%*AQ15+5%*AR15+5%*AS15+10%*AT15+5%*AU15+5%*AY15+10%*AV15+10%*AW15 -> 0.2954
A16: GRND3 | B16: =K16 -> 0.012 | C16: =B16-E16 -> 0.012 | D16: =B16-K16 -> 0 | E16: =K16-L16 -> 0 | F16: 3.497 | G16: 3.76 | H16: pro_cyclicals | I16: =VLOOKUP(A16,Setores!$A$2:$C$215,2,0) -> apparel | J16: =VLOOKUP(A16,Setores!$A$2:$C$215,3,0) -> very_low_beta | K16: 0.012 | L16: 0.012 | M16: =VLOOKUP(A16,'Mandato Ibov'!$B$1:$C$215,2,0) -> 0.016533418 | N16: =K16-M16 -> -0.0045334184 | O16: =B16-M16 -> -0.0045334184 | P16: =VLOOKUP(A16,'Mandato Ibov'!$B$2:$D$215,3,0) -> 0.010017892 | Q16: =K16-P16 -> 0.0019821083 | R16: 0.737 | S16: 0.61 | T16: 0.678 | U16: 0.687 | V16: 0.675 | W16: 1 | X16: 1 | Y16: 0.978 | Z16: 0.556 | AA16: 0.559 | AB16: 0.894 | AC16: 0.839 | AD16: 0.891 | AE16: 0.847 | AF16: 0.063 | AG16: -0.123 | AH16: 0.027 | AI16: 0.129 | AJ16: 0.847 | AK16: 0.135 | AL16: 0.948 | AM16: -0.477 | AN16: 0.54 | AO16: 0.169 | AP16: -0.258 | AQ16: -0.023 | AR16: 0.299 | AS16: -0.168 | AT16: 0.205 | AU16: 0.159 | AV16: 0.17 | AW16: 0.518 | AX16: 0.774 | AY16: 0.495 | AZ16: -0.049 | BA16: 0.102 | BB16: 0.553 | BC16: 0.507 | BD16: 0.546 | BE16: 0.211 | BF16: 0.048 | BG16: 0.829 | BH16: -0.075 | BI16: -0.358 | BJ16: 0.197 | BK16: 0.347 | BM16: =10%*AK16+5%*AL16+2.5%*AM16+2.5%*AN16+10%*AO16+10%*AP16+10%*AQ16+5%*AR16+5%*AS16+10%*AT16+5%*AU16+5%*AY16+10%*AV16+10%*AW16 -> 0.179825
A17: HBRE3 | B17: =K17 -> 0.008 | C17: =B17-E17 -> 0.008 | D17: =B17-K17 -> 0 | E17: =K17-L17 -> 0 | F17: 3.378 | G17: 2.579 | H17: bond_proxies | I17: =VLOOKUP(A17,Setores!$A$2:$C$215,2,0) -> real_estate | J17: =VLOOKUP(A17,Setores!$A$2:$C$215,3,0) -> very_high_beta | K17: 0.008 | L17: 0.008 | M17: =VLOOKUP(A17,'Mandato Ibov'!$B$1:$C$215,2,0) -> 0.015969711 | N17: =K17-M17 -> -0.0079697112 | O17: =B17-M17 -> -0.0079697112 | P17: =VLOOKUP(A17,'Mandato Ibov'!$B$2:$D$215,3,0) -> 0.0062313314 | Q17: =K17-P17 -> 0.0017686686 | R17: 1 | S17: 1 | T17: 1 | U17: 0.702 | V17: 1 | W17: 0.86 | X17: 0.81 | Y17: 0.47 | Z17: 0.557 | AA17: 0.556 | AB17: 0.644 | AC17: 0.81 | AD17: 0.978 | AE17: 0.237 | AF17: 1 | AG17: 1 | AH17: 1 | AI17: 0.384 | AJ17: -0.225 | AK17: 0.75 | AL17: -0.02 | AM17: 1 | AN17: 0.775 | AO17: -0.097 | AP17: -0.185 | AQ17: -0.221 | AR17: 0.343 | AS17: 0.114 | AT17: -0.228 | AU17: 0.47 | AV17: -0.336 | AW17: -0.048 | AX17: -0.714 | AY17: -0.344 | AZ17: 0.126 | BA17: 0.847 | BB17: 0.166 | BC17: 0.739 | BD17: 0.326 | BE17: -0.001 | BF17: 0.315 | BG17: 0.283 | BH17: 0.154 | BI17: 0.819 | BJ17: 0.621 | BK17: 0.974 | BM17: =10%*AK17+5%*AL17+2.5%*AM17+2.5%*AN17+10%*AO17+10%*AP17+10%*AQ17+5%*AR17+5%*AS17+10%*AT17+5%*AU17+5%*AY17+10%*AV17+10%*AW17 -> 0.036025
A18: POMO3 | B18: =K18 -> 0.009 | C18: =B18-E18 -> 0.009 | D18: =B18-K18 -> 0 | E18: =K18-L18 -> 0 | F18: 3.324 | G18: 2.979 | H18: industrials | I18: =VLOOKUP(A18,Setores!$A$2:$C$215,2,0) -> capital_goods | J18: =VLOOKUP(A18,Setores!$A$2:$C$215,3,0) -> neutral_beta | K18: 0.009 | L18: 0.009 | M18: =VLOOKUP(A18,'Mandato Ibov'!$B$1:$C$215,2,0) -> 0.015715049 | N18: =K18-M18 -> -0.0067150492 | O18: =B18-M18 -> -0.0067150492 | P18: =VLOOKUP(A18,'Mandato Ibov'!$B$2:$D$215,3,0) -> 0.010094922 | Q18: =K18-P18 -> -0.0010949224 | R18: 0.621 | S18: 0.14 | T18: 0.397 | U18: 0.923 | V18: 0.539 | W18: 0.848 | X18: 0.816 | Y18: 1 | Z18: 0.632 | AA18: 0.633 | AB18: 0.946 | AC18: 0.86 | AD18: 0.854 | AE18: 1 | AF18: 0.59 | AG18: 0.154 | AH18: -0.454 | AI18: -0.03 | AJ18: 0.096 | AK18: -0.035 | AL18: 0.628 | AM18: -0.685 | AN18: 0.375 | AO18: 0.287 | AP18: 0.448 | AQ18: 0.599 | AR18: 0.283 | AS18: -0.498 | AT18: 0.614 | AU18: -0.337 | AV18: 0.644 | AW18: 0.41 | AX18: 0.114 | AY18: 0.843 | AZ18: 0.741 | BA18: 0.226 | BB18: -0.159 | BC18: -0.188 | BD18: 0.438 | BE18: -0.417 | BF18: 0.146 | BG18: 0.346 | BH18: -0.961 | BI18: 0.172 | BJ18: 0.73 | BK18: -0.151 | BM18: =10%*AK18+5%*AL18+2.5%*AM18+2.5%*AN18+10%*AO18+10%*AP18+10%*AQ18+5%*AR18+5%*AS18+10%*AT18+5%*AU18+5%*AY18+10%*AV18+10%*AW18 -> 0.3349
A19: MTRE3 | B19: =K19 -> 0.017 | C19: =B19-E19 -> 0.017 | D19: =B19-K19 -> 0 | E19: =K19-L19 -> 0 | F19: 3.23 | G19: 3.533 | H19: pro_cyclicals | I19: =VLOOKUP(A19,Setores!$A$2:$C$215,2,0) -> homebuilders | J19: =VLOOKUP(A19,Setores!$A$2:$C$215,3,0) -> low_beta | K19: 0.017 | L19: 0.017 | M19: =VLOOKUP(A19,'Mandato Ibov'!$B$1:$C$215,2,0) -> 0.015271697 | N19: =K19-M19 -> 0.0017283027 | O19: =B19-M19 -> 0.0017283027 | P19: =VLOOKUP(A19,'Mandato Ibov'!$B$2:$D$215,3,0) -> 0.011876963 | Q19: =K19-P19 -> 0.0051230374 | R19: 0.688 | S19: 0.794 | T19: 0.801 | U19: 0.52 | V19: 0.767 | W19: 0.688 | X19: 0.667 | Y19: 0.602 | Z19: 0.676 | AA19: 0.672 | AB19: 1 | AC19: 0.934 | AD19: 0.937 | AE19: -0.026 | AF19: 1 | AG19: 0.535 | AH19: 1 | AI19: 0.456 | AJ19: 0.016 | AK19: 0.147 | AL19: 0.699 | AM19: 0.319 | AN19: 0.416 | AO19: -0.131 | AP19: -0.245 | AQ19: 0.252 | AR19: 0.546 | AS19: 0.171 | AT19: -0.031 | AU19: -0.327 | AV19: -0.239 | AW19: -0.015 | AX19: -0.326 | AY19: 0.678 | AZ19: 0.185 | BA19: 0.058 | BB19: -0.186 | BC19: -0.07 | BD19: 0.244 | BE19: -0.151 | BF19: 0.367 | BG19: 0.853 | BH19: -0.061 | BI19: 0.12 | BJ19: 0.609 | BK19: 0.875 | BM19: =10%*AK19+5%*AL19+2.5%*AM19+2.5%*AN19+10%*AO19+10%*AP19+10%*AQ19+5%*AR19+5%*AS19+10%*AT19+5%*AU19+5%*AY19+10%*AV19+10%*AW19 -> 0.080525
A20: MLAS3 | B20: =K20 -> 0.006 | C20: =B20-E20 -> 0.006 | D20: =B20-K20 -> 0 | E20: =K20-L20 -> 0 | F20: 2.937 | G20: 2.169 | H20: pro_cyclicals | I20: =VLOOKUP(A20,Setores!$A$2:$C$215,2,0) -> tech | J20: =VLOOKUP(A20,Setores!$A$2:$C$215,3,0) -> high_beta | K20: 0.006 | L20: 0.006 | M20: =VLOOKUP(A20,'Mandato Ibov'!$B$1:$C$215,2,0) -> 0.013885916 | N20: =K20-M20 -> -0.0078859164 | O20: =B20-M20 -> -0.0078859164 | P20: =VLOOKUP(A20,'Mandato Ibov'!$B$2:$D$215,3,0) -> 0.010388373 | Q20: =K20-P20 -> -0.0043883734 | R20: 1 | S20: 1 | T20: 1 | U20: 1 | V20: 1 | W20: 0.184 | X20: -0.575 | Y20: 0.389 | Z20: 0.348 | AA20: 0.347 | AB20: 0.766 | AC20: 0.793 | AD20: 1 | AE20: 1 | AF20: 1 | AG20: 1 | AH20: 0.588 | AI20: 0.898 | AJ20: 1 | AK20: 0.424 | AL20: -0.809 | AM20: 0.445 | AN20: 0.341 | AO20: 0.355 | AP20: 0.382 | AQ20: 0.7 | AR20: 0.664 | AS20: 0.366 | AT20: 0.137 | AU20: -0.445 | AV20: 0.858 | AW20: -0.528 | AX20: 0.358 | AY20: 0.413 | AZ20: -0.318 | BA20: 0.932 | BB20: 0.336 | BC20: 0.234 | BD20: 0.799 | BE20: -1 | BF20: -0.382 | BG20: -1 | BH20: 0.533 | BI20: -0.127 | BJ20: 0.917 | BK20: 0.464 | BM20: =10%*AK20+5%*AL20+2.5%*AM20+2.5%*AN20+10%*AO20+10%*AP20+10%*AQ20+5%*AR20+5%*AS20+10%*AT20+5%*AU20+5%*AY20+10%*AV20+10%*AW20 -> 0.2619
... A24: MILS3 | B24: =K24 -> 0.014 | C24: =B24-E24 -> 0.014 | D24: =B24-K24 -> 0 | E24: =K24-L24 -> 0 | F24: 2.64 | G24: 3.318 | H24: industrials | I24: =VLOOKUP(A24,Setores!$A$2:$C$215,2,0) -> building_materials | J24: =VLOOKUP(A24,Setores!$A$2:$C$215,3,0) -> neutral_beta | K24: 0.014 | L24: 0.014 | M24: =VLOOKUP(A24,'Mandato Ibov'!$B$1:$C$215,2,0) -> 0.012479044 | N24: =K24-M24 -> 0.0015209563 | O24: =B24-M24 -> 0.0015209563 | P24: =VLOOKUP(A24,'Mandato Ibov'!$B$2:$D$215,3,0) -> 0.0065569514 | Q24: =K24-P24 -> 0.0074430486 | R24: 0.499 | S24: 0.281 | T24: 0.11 | U24: 0.375 | V24: 0.126 | W24: 0.673 | X24: 0.953 | Y24: 0.191 | Z24: 0.702 | AA24: 0.697 | AB24: 0.904 | AC24: 0.888 | AD24: 0.845 | AE24: 0.022 | AF24: 0.116 | AG24: -0.165 | AH24: -0.341 | AI24: 0.346 | AJ24: 0.006 | AK24: -0.056 | AL24: -0.236 | AM24: -0.617 | AN24: 0.825 | AO24: 0.209 | AP24: -0.249 | AQ24: 0.34 | AR24: 0.864 | AS24: 0.258 | AT24: 0.436 | AU24: 0.442 | AV24: 0.325 | AW24: 0.397 | AX24: 0.044 | AY24: 0.384 | AZ24: 0.607 | BA24: 0.466 | BB24: -0.293 | BC24: -0.375 | BD24: 0.399 | BE24: -0.373 | BF24: -0.309 | BG24: 0.808 | BH24: -0.483 | BI24: 0.215 | BJ24: 0.295 | BK24: 0.047 | BM24: =10%*AK24+5%*AL24+2.5%*AM24+2.5%*AN24+10%*AO24+10%*AP24+10%*AQ24+5%*AR24+5%*AS24+10%*AT24+5%*AU24+5%*AY24+10%*AV24+10%*AW24 -> 0.231
A25: AURA33 | B25: 0.005 | C25: =B25-E25 -> 0.005 | D25: =B25-K25 -> 0 | E25: =K25-L25 -> 0 | F25: 2.624 | G25: 1.869 | H25: commodities | I25: =VLOOKUP(A25,Setores!$A$2:$C$215,2,0) -> basic_materials | J25: =VLOOKUP(A25,Setores!$A$2:$C$215,3,0) -> very_high_beta | K25: 0.005 | L25: 0.005 | M25: =VLOOKUP(A25,'Mandato Ibov'!$B$1:$C$215,2,0) -> 0.012407119 | N25: =K25-M25 -> -0.0074071192 | O25: =B25-M25 -> -0.0074071192 | P25: =VLOOKUP(A25,'Mandato Ibov'!$B$2:$D$215,3,0) -> 0.011528512 | Q25: =K25-P25 -> -0.0065285117 | R25: 0.33 | S25: 0.658 | T25: -0.467 | U25: 0.589 | V25: 0.203 | W25: 0.227 | X25: -0.08 | Y25: 0.47 | Z25: 1 | AA25: 1 | AB25: 0.871 | AC25: 0.996 | AD25: 0.966 | AE25: -0.265 | AF25: -0.508 | AG25: 1 | AH25: -0.754 | AI25: 0.041 | AJ25: -0.678 | AK25: 0.101 | AL25: -0.546 | AM25: -0.202 | AN25: -0.543 | AO25: 0.834 | AP25: 0.811 | AQ25: 0.495 | AR25: 0.922 | AS25: 0.363 | AT25: 0.956 | AU25: 0.373 | AV25: 0.835 | AW25: 0.046 | AX25: 0.167 | AY25: -0.353 | AZ25: 0.141 | BA25: 0.657 | BB25: -0.282 | BC25: 0.33 | BD25: 0.646 | BE25: 1 | BF25: -0.364 | BG25: -0.786 | BH25: -1 | BI25: 0.361 | BJ25: -0.019 | BK25: -0.455 | BM25: =10%*AK25+5%*AL25+2.5%*AM25+2.5%*AN25+10%*AO25+10%*AP25+10%*AQ25+5%*AR25+5%*AS25+10%*AT25+5%*AU25+5%*AY25+10%*AV25+10%*AW25 -> 0.427125
A26: BRAP4 | B26: 0.015 | C26: =B26-E26 -> 0.013 | D26: =B26-K26 -> 0.015 | E26: =K26-L26 -> 0.002 | F26: 2.61 | G26: 3.517 | H26: commodities | I26: =VLOOKUP(A26,Setores!$A$2:$C$215,2,0) -> basic_materials | J26: =VLOOKUP(A26,Setores!$A$2:$C$215,3,0) -> neutral_beta | K26: 0 | L26: -0.002 | M26: =VLOOKUP(A26,'Mandato Ibov'!$B$1:$C$215,2,0) -> 0.014702989 | N26: =K26-M26 -> -0.014702989 | O26: =B26-M26 -> 0.00029701084 | P26: =VLOOKUP(A26,'Mandato Ibov'!$B$2:$D$215,3,0) -> 0.010668914 | Q26: =K26-P26 -> -0.010668914 | R26: -0.117 | S26: 0.408 | T26: -0.566 | U26: 0.127 | V26: 0.055 | W26: 0.433 | X26: 0.593 | Y26: 0.848 | Z26: 0.813 | AA26: 0.809 | AB26: 0.865 | AC26: 0.767 | AD26: 0.939 | AE26: -0.158 | AF26: -0.605 | AG26: 0.574 | AH26: -0.65 | AI26: 0.298 | AJ26: -0.491 | AK26: -0.306 | AL26: 0.621 | AM26: -0.439 | AN26: -0.491 | AO26: 0.871 | AP26: 0.225 | AQ26: -0.772 | AR26: 0.686 | AS26: 0.403 | AT26: 0.044 | AU26: 0.12 | AV26: 0.119 | AW26: 0.563 | AX26: 0.02 | AY26: 0.553 | AZ26: -0.787 | BA26: 0.341 | BB26: -0.091 | BC26: 0.377 | BD26: 0.602 | BE26: -0.327 | BF26: 0.335 | BG26: 0.673 | BH26: -0.403 | BI26: -0.36 | BJ26: -0.277 | BK26: 0.096 | BM26: =10%*AK26+5%*AL26+2.5%*AM26+2.5%*AN26+10%*AO26+10%*AP26+10%*AQ26+5%*AR26+5%*AS26+10%*AT26+5%*AU26+5%*AY26+10%*AV26+10%*AW26 -> 0.1703
A27: INTB3 | B27: =K27 -> 0.009 | C27: =B27-E27 -> 0.009 | D27: =B27-K27 -> 0 | E27: =K27-L27 -> 0 | F27: 2.602 | G27: 2.255 | H27: pro_cyclicals | I27: =VLOOKUP(A27,Setores!$A$2:$C$215,2,0) -> tech | J27: =VLOOKUP(A27,Setores!$A$2:$C$215,3,0) -> high_beta | K27: 0.009 | L27: 0.009 | M27: =VLOOKUP(A27,'Mandato Ibov'!$B$1:$C$215,2,0) -> 0.012303015 | N27: =K27-M27 -> -0.0033030146 | O27: =B27-M27 -> -0.0033030146 | P27: =VLOOKUP(A27,'Mandato Ibov'!$B$2:$D$215,3,0) -> 0.0088324624 | Q27: =K27-P27 -> 0.00016753762 | R27: 0.713 | S27: 0.611 | T27: 0.232 | U27: 0.683 | V27: 0.433 | W27: 0.275 | X27: -0.007 | Y27: 0.343 | Z27: 0.233 | AA27: 0.236 | AB27: 0.994 | AC27: 0.89 | AD27: 0.877 | AE27: 0.834 | AF27: -0.139 | AG27: 0.116 | AH27: -0.401 | AI27: 0.139 | AJ27: 0.278 | AK27: 0.113 | AL27: -0.288 | AM27: -0.698 | AN27: 0.721 | AO27: 0.292 | AP27: 0.791 | AQ27: 0.076 | AR27: 0.815 | AS27: 0.804 | AT27: 0.594 | AU27: -0.229 | AV27: 0.842 | AW27: 0.182 | AX27: 0.495 | AY27: 0.755 | AZ27: -0.271 | BA27: 0.618 | BB27: 0.087 | BC27: 0.413 | BD27: 0.444 | BE27: -0.994 | BF27: -1 | BG27: -0.447 | BH27: 0.165 | BI27: 0.038 | BJ27: 0.025 | BK27: -0.151 | BM27: =10%*AK27+5%*AL27+2.5%*AM27+2.5%*AN27+10%*AO27+10%*AP27+10%*AQ27+5%*AR27+5%*AS27+10%*AT27+5%*AU27+5%*AY27+10%*AV27+10%*AW27 -> 0.382425
A28: SEER3 | B28: =K28 -> 0.007 | C28: =B28-E28 -> 0.007 | D28: =B28-K28 -> 0 | E28: =K28-L28 -> 0 | F28: 2.593 | G28: 1.861 | H28: pro_cyclicals | I28: =VLOOKUP(A28,Setores!$A$2:$C$215,2,0) -> education | J28: =VLOOKUP(A28,Setores!$A$2:$C$215,3,0) -> high_beta | K28: 0.007 | L28: 0.007 | M28: =VLOOKUP(A28,'Mandato Ibov'!$B$1:$C$215,2,0) -> 0.012257287 | N28: =K28-M28 -> -0.0052572869 | O28: =B28-M28 -> -0.0052572869 | P28: =VLOOKUP(A28,'Mandato Ibov'!$B$2:$D$215,3,0) -> 0.008440764 | Q28: =K28-P28 -> -0.001440764 | R28: 0.799 | S28: 0.628 | T28: 0.588 | U28: 0.725 | V28: 0.601 | W28: 0.413 | X28: 0.161 | Y28: 0.164 | Z28: 0.2 | AA28: 0.2 | AB28: 0.822 | AC28: 0.583 | AD28: 0.888 | AE28: 0.877 | AF28: 0.457 | AG28: 0.337 | AH28: -0.034 | AI28: 1 | AJ28: 1 | AK28: 0.184 | AL28: -0.76 | AM28: -0.528 | AN28: 0.457 | AO28: 0.25 | AP28: 0.472 | AQ28: 0.472 | AR28: 0.559 | AS28: 0.038 | AT28: 0.459 | AU28: 0.08 | AV28: 0.998 | AW28: -0.629 | AX28: 0.002 | AY28: 0.747 | AZ28: 0.525 | BA28: 0.273 | BB28: -0.008 | BC28: 0.049 | BD28: 0.526 | BE28: -0.135 | BF28: 0.544 | BG28: 0.223 | BH28: -0.623 | BI28: 0.273 | BJ28: -0.049 | BK28: 0.547 | BM28: =10%*AK28+5%*AL28+2.5%*AM28+2.5%*AN28+10%*AO28+10%*AP28+10%*AQ28+5%*AR28+5%*AS28+10%*AT28+5%*AU28+5%*AY28+10%*AV28+10%*AW28 -> 0.252025
A29: PETR4 | B29: 0.05 | C29: =B29-E29 -> -0.03 | D29: =B29-K29 -> 0.02 | E29: =K29-L29 -> 0.08 | F29: 2.559 | G29: 5.077 | H29: commodities | I29: =VLOOKUP(A29,Setores!$A$2:$C$215,2,0) -> crude_oil | J29: =VLOOKUP(A29,Setores!$A$2:$C$215,3,0) -> very_low_beta | K29: 0.03 | L29: -0.05 | M29: =VLOOKUP(A29,'Mandato Ibov'!$B$1:$C$215,2,0) -> 0.066604102 | N29: =K29-M29 -> -0.036604102 | O29: =B29-M29 -> -0.016604102 | P29: =VLOOKUP(A29,'Mandato Ibov'!$B$2:$D$215,3,0) -> 0.073419563 | Q29: =K29-P29 -> -0.043419563 | R29: -0.294 | S29: 0.28 | T29: -0.853 | U29: 0.315 | V29: -0.04 | W29: 0.447 | X29: 0.531 | Y29: 1 | Z29: 1 | AA29: 1 | AB29: 0.561 | AC29: 0.73 | AD29: 0.889 | AE29: -0.018 | AF29: -0.745 | AG29: 1 | AH29: -0.935 | AI29: -0.544 | AJ29: -0.922 | AK29: 0.151 | AL29: 0.432 | AM29: -0.542 | AN29: -0.647 | AO29: 0.944 | AP29: 1 | AQ29: -0.335 | AR29: 0.145 | AS29: 0.035 | AT29: 0.412 | AU29: 0.269 | AV29: 0.23 | AW29: 0.503 | AX29: -0.212 | AY29: 0.743 | AZ29: 0.389 | BA29: 0.391 | BB29: -0.151 | BC29: -0.213 | BD29: 0.601 | BE29: -0.679 | BF29: 0.293 | BG29: 0.392 | BH29: -0.907 | BI29: -1 | BJ29: -0.247 | BK29: -0.898 | BM29: =10%*AK29+5%*AL29+2.5%*AM29+2.5%*AN29+10%*AO29+10%*AP29+10%*AQ29+5%*AR29+5%*AS29+10%*AT29+5%*AU29+5%*AY29+10%*AV29+10%*AW29 -> 0.341975
A30: PINE4 | B30: =K30 -> 0.008 | C30: =B30-E30 -> 0.008 | D30: =B30-K30 -> 0 | E30: =K30-L30 -> 0 | F30: 2.523 | G30: 1.934 | H30: pro_cyclicals | I30: =VLOOKUP(A30,Setores!$A$2:$C$215,2,0) -> banks | J30: =VLOOKUP(A30,Setores!$A$2:$C$215,3,0) -> neutral_beta | K30: 0.008 | L30: 0.008 | M30: =VLOOKUP(A30,'Mandato Ibov'!$B$1:$C$215,2,0) -> 0.011926821 | N30: =K30-M30 -> -0.0039268207 | O30: =B30-M30 -> -0.0039268207 | P30: =VLOOKUP(A30,'Mandato Ibov'!$B$2:$D$215,3,0) -> 0.013333522 | Q30: =K30-P30 -> -0.0053335222 | R30: 0.326 | S30: 0.392 | T30: 0.235 | U30: 0.476 | V30: 0.399 | W30: 0.138 | X30: -0.048 | Y30: 0.493 | Z30: 0.473 | AA30: 0.47 | AB30: 0.884 | AC30: 0.924 | AD30: 0.946 | AE30: -0.175 | AF30: 0.657 | AG30: 0.655 | AH30: -0.403 | AI30: 1 | AJ30: 0.653 | AK30: -0.112 | AL30: -0.07 | AM30: -0.407 | AN30: 0.058 | AO30: 0.543 | AP30: 0.466 | AQ30: 0.992 | AR30: 0.512 | AS30: -0.163 | AT30: 0.192 | AU30: -0.232 | AV30: 0.085 | AW30: 0.364 | AX30: -0.141 | AY30: 0.476 | AZ30: 0.444 | BA30: 0.333 | BB30: -0.502 | BC30: -0.023 | BD30: -0.603 | BE30: -0.496 | BF30: 0.188 | BG30: -0.108 | BH30: -1 | BI30: -0.204 | BJ30: 0.437 | BK30: 0.638 | BM30: =10%*AK30+5%*AL30+2.5%*AM30+2.5%*AN30+10%*AO30+10%*AP30+10%*AQ30+5%*AR30+5%*AS30+10%*AT30+5%*AU30+5%*AY30+10%*AV30+10%*AW30 -> 0.270425
A31: POMO4 | B31: 0.01 | C31: =B31-E31 -> 0.008 | D31: =B31-K31 -> -0.001 | E31: =K31-L31 -> 0.002 | F31: 2.518 | G31: 2.471 | H31: industrials | I31: =VLOOKUP(A31,Setores!$A$2:$C$215,2,0) -> capital_goods | J31: =VLOOKUP(A31,Setores!$A$2:$C$215,3,0) -> high_beta | K31: 0.011 | L31: 0.009 | M31: =VLOOKUP(A31,'Mandato Ibov'!$B$1:$C$215,2,0) -> 0.013461488 | N31: =K31-M31 -> -0.0024614881 | O31: =B31-M31 -> -0.0034614881 | P31: =VLOOKUP(A31,'Mandato Ibov'!$B$2:$D$215,3,0) -> 0.0083488415 | Q31: =K31-P31 -> 0.0026511585 | R31: 0.34 | S31: -0.216 | T31: -0.007 | U31: 0.643 | V31: 0.168 | W31: 0.679 | X31: 0.757 | Y31: 0.581 | Z31: 0.311 | AA31: 0.313 | AB31: 0.798 | AC31: 0.779 | AD31: 0.693 | AE31: 1 | AF31: 0.575 | AG31: -0.214 | AH31: -0.459 | AI31: -0.306 | AJ31: 0.088 | AK31: -0.035 | AL31: 0.433 | AM31: -0.685 | AN31: 0.428 | AO31: 0.057 | AP31: 0.312 | AQ31: 0.599 | AR31: 0.283 | AS31: -0.498 | AT31: 0.614 | AU31: -0.337 | AV31: 0.639 | AW31: 0.414 | AX31: 0.114 | AY31: 0.843 | AZ31: 0.561 | BA31: 0.448 | BB31: -0.159 | BC31: -0.188 | BD31: 0.3 | BE31: -0.187 | BF31: 0.027 | BG31: 0.588 | BH31: -0.854 | BI31: 0.346 | BJ31: -0.382 | BK31: -0.151 | BM31: =10%*AK31+5%*AL31+2.5%*AM31+2.5%*AN31+10%*AO31+10%*AP31+10%*AQ31+5%*AR31+5%*AS31+10%*AT31+5%*AU31+5%*AY31+10%*AV31+10%*AW31 -> 0.289775
A32: PETR3 | B32: 0.044 | C32: =B32-E32 -> 0 | D32: =B32-K32 -> 0.014 | E32: =K32-L32 -> 0.044 | F32: 2.471 | G32: 4.491 | H32: commodities | I32: =VLOOKUP(A32,Setores!$A$2:$C$215,2,0) -> crude_oil | J32: =VLOOKUP(A32,Setores!$A$2:$C$215,3,0) -> very_low_beta | K32: 0.03 | L32: -0.014 | M32: =VLOOKUP(A32,'Mandato Ibov'!$B$1:$C$215,2,0) -> 0.064329874 | N32: =K32-M32 -> -0.034329874 | O32: =B32-M32 -> -0.020329874 | P32: =VLOOKUP(A32,'Mandato Ibov'!$B$2:$D$215,3,0) -> 0.072962312 | Q32: =K32-P32 -> -0.042962312 | R32: -0.308 | S32: 0.263 | T32: -0.848 | U32: 0.265 | V32: -0.067 | W32: 0.358 | X32: 0.396 | Y32: 0.946 | Z32: 1 | AA32: 1 | AB32: 0.596 | AC32: 0.756 | AD32: 0.885 | AE32: -0.089 | AF32: -0.771 | AG32: 1 | AH32: -0.944 | AI32: -0.568 | AJ32: -0.926 | AK32: 0.151 | AL32: 0.357 | AM32: -0.542 | AN32: -0.658 | AO32: 0.935 | AP32: 1 | AQ32: -0.335 | AR32: 0.145 | AS32: 0.035 | AT32: 0.412 | AU32: 0.269 | AV32: 0.223 | AW32: 0.409 | AX32: -0.212 | AY32: 0.743 | AZ32: 0.438 | BA32: 0.498 | BB32: -0.151 | BC32: -0.213 | BD32: 0.624 | BE32: -0.705 | BF32: 0.311 | BG32: 0.27 | BH32: -0.893 | BI32: -1 | BJ32: -0.085 | BK32: -0.898 | BM32: =10%*AK32+5%*AL32+2.5%*AM32+2.5%*AN32+10%*AO32+10%*AP32+10%*AQ32+5%*AR32+5%*AS32+10%*AT32+5%*AU32+5%*AY32+10%*AV32+10%*AW32 -> 0.32695
A33: CSED3 | B33: =K33 -> 0.009 | C33: =B33-E33 -> 0.009 | D33: =B33-K33 -> 0 | E33: =K33-L33 -> 0 | F33: 2.425 | G33: 1.842 | H33: pro_cyclicals | I33: =VLOOKUP(A33,Setores!$A$2:$C$215,2,0) -> education | J33: =VLOOKUP(A33,Setores!$A$2:$C$215,3,0) -> very_high_beta | K33: 0.009 | L33: 0.009 | M33: =VLOOKUP(A33,'Mandato Ibov'!$B$1:$C$215,2,0) -> 0.011465595 | N33: =K33-M33 -> -0.0024655947 | O33: =B33-M33 -> -0.0024655947 | P33: =VLOOKUP(A33,'Mandato Ibov'!$B$2:$D$215,3,0) -> 0.0089832565 | Q33: =K33-P33 -> 1.6743491e-05 | R33: 0.691 | S33: -0.014 | T33: 0.99 | U33: 0.688 | V33: 0.603 | W33: 0.487 | X33: 0.433 | Y33: 0.112 | Z33: 0.149 | AA33: 0.148 | AB33: 0.905 | AC33: 0.701 | AD33: 0.643 | AE33: 1 | AF33: 1 | AG33: -0.461 | AH33: 0.728 | AI33: -0.228 | AJ33: 1 | AK33: 0.633 | AL33: 0.309 | AM33: -0.392 | AN33: 0.609 | AO33: -0.624 | AP33: -0.604 | AQ33: 0.734 | AR33: 0.021 | AS33: -0.567 | AT33: 0.41 | AU33: 0.08 | AV33: 0.897 | AW33: -0.286 | AX33: 0.03 | AY33: 0.744 | AZ33: 0.218 | BA33: 0.45 | BB33: 0.098 | BC33: 0.171 | BD33: 0.268 | BE33: 1 | BF33: 1 | BG33: 0.056 | BH33: -0.295 | BI33: 0.285 | BJ33: 0.734 | BK33: 0.557 | BM33: =10%*AK33+5%*AL33+2.5%*AM33+2.5%*AN33+10%*AO33+10%*AP33+10%*AQ33+5%*AR33+5%*AS33+10%*AT33+5%*AU33+5%*AY33+10%*AV33+10%*AW33 -> 0.150775
A34: OPCT3 | B34: =K34 -> 0.013 | C34: =B34-E34 -> 0.013 | D34: =B34-K34 -> 0 | E34: =K34-L34 -> 0 | F34: 2.366 | G34: 2.579 | H34: commodities | I34: =VLOOKUP(A34,Setores!$A$2:$C$215,2,0) -> crude_oil | J34: =VLOOKUP(A34,Setores!$A$2:$C$215,3,0) -> very_low_beta | K34: 0.013 | L34: 0.013 | M34: =VLOOKUP(A34,'Mandato Ibov'!$B$1:$C$215,2,0) -> 0.011187025 | N34: =K34-M34 -> 0.0018129752 | O34: =B34-M34 -> 0.0018129752 | P34: =VLOOKUP(A34,'Mandato Ibov'!$B$2:$D$215,3,0) -> 0.010894229 | Q34: =K34-P34 -> 0.0021057713 | R34: 0.331 | S34: 0.409 | T34: -0.131 | U34: 0.324 | V34: 0.119 | W34: 0.484 | X34: 0.35 | Y34: 0.062 | Z34: 0.723 | AA34: 0.718 | AB34: 0.75 | AC34: 0.86 | AD34: 0.991 | AE34: -0.318 | AF34: -0.084 | AG34: 0.574 | AH34: -0.499 | AI34: 1 | AJ34: 0.29 | AK34: -0.305 | AL34: -0.943 | AM34: -0.722 | AN34: 0.556 | AO34: 0.765 | AP34: 0.74 | AQ34: 0.813 | AR34: 0.696 | AS34: 0.12 | AT34: 0.191 | AU34: -0.289 | AV34: 0.546 | AW34: 0.503 | AX34: -0.163 | AY34: 0.671 | AZ34: -0.49 | BA34: 0.966 | BB34: -0.371 | BC34: -0.73 | BD34: 0.546 | BE34: -0.593 | BF34: 0.241 | BG34: 0.809 | BH34: -0.615 | BI34: -0.838 | BJ34: 0.66 | BK34: 0.645 | BM34: =10%*AK34+5%*AL34+2.5%*AM34+2.5%*AN34+10%*AO34+10%*AP34+10%*AQ34+5%*AR34+5%*AS34+10%*AT34+5%*AU34+5%*AY34+10%*AV34+10%*AW34 -> 0.3339
A35: ESPA3 | B35: 0.003 | C35: =B35-E35 -> 0.003 | D35: =B35-K35 -> -0.007 | E35: =K35-L35 -> 0 | F35: 2.359 | G35: 1.747 | H35: pro_cyclicals | I35: =VLOOKUP(A35,Setores!$A$2:$C$215,2,0) -> consumer_services | J35: =VLOOKUP(A35,Setores!$A$2:$C$215,3,0) -> very_low_beta | K35: 0.01 | L35: 0.01 | M35: =VLOOKUP(A35,'Mandato Ibov'!$B$1:$C$215,2,0) -> 0.011150627 | N35: =K35-M35 -> -0.0011506275 | O35: =B35-M35 -> -0.0081506275 | P35: =VLOOKUP(A35,'Mandato Ibov'!$B$2:$D$215,3,0) -> 0 | Q35: =K35-P35 -> 0.01 | R35: 0.847 | S35: 0.872 | T35: 1 | U35: 0.537 | V35: 0.863 | W35: 0.231 | X35: -0.08 | Y35: -0.224 | Z35: 0.215 | AA35: 0.214 | AB35: 0.807 | AC35: 0.766 | AD35: 0.792 | AE35: 0.964 | AF35: 1 | AG35: 0.189 | AH35: 1 | AI35: 0.649 | AJ35: 0.617 | AK35: 0.176 | AL35: -0.723 | AM35: 0.641 | AN35: 0.601 | AO35: -0.322 | AP35: 0.136 | AQ35: 0.471 | AR35: 0.252 | AS35: -0.143 | AT35: -0.041 | AU35: -0.282 | AV35: 0.462 | AW35: -0.194 | AX35: -0.33 | AY35: 0.943 | AZ35: -0.359 | BA35: 0.985 | BB35: 0.148 | BC35: 0.035 | BD35: 0.35 | BE35: 1 | BF35: 0.468 | BG35: 0.3 | BH35: 0.645 | BI35: -0.68 | BJ35: 0.815 | BK35: 1 | BM35: =10%*AK35+5%*AL35+2.5%*AM35+2.5%*AN35+10%*AO35+10%*AP35+10%*AQ35+5%*AR35+5%*AS35+10%*AT35+5%*AU35+5%*AY35+10%*AV35+10%*AW35 -> 0.1022
A36: VTRU3 | B36: =K36 -> 0.007 | C36: =B36-E36 -> 0.007 | D36: =B36-K36 -> 0 | E36: =K36-L36 -> 0 | F36: 2.358 | G36: 1.836 | H36: pro_cyclicals | I36: =VLOOKUP(A36,Setores!$A$2:$C$215,2,0) -> education | J36: =VLOOKUP(A36,Setores!$A$2:$C$215,3,0) -> neutral_beta | K36: 0.007 | L36: 0.007 | M36: =VLOOKUP(A36,'Mandato Ibov'!$B$1:$C$215,2,0) -> 0.011147111 | N36: =K36-M36 -> -0.0041471111 | O36: =B36-M36 -> -0.0041471111 | P36: =VLOOKUP(A36,'Mandato Ibov'!$B$2:$D$215,3,0) -> 0.010586825 | Q36: =K36-P36 -> -0.0035868248 | R36: 0.55 | S36: 0.588 | T36: 0.402 | U36: 0.602 | V36: 0.547 | W36: 0.17 | X36: 0.128 | Y36: -0.117 | Z36: 0.564 | AA36: 0.565 | AB36: 0.926 | AC36: 0.911 | AD36: 0.882 | AE36: 0.504 | AF36: 1 | AG36: 0.472 | AH36: 0.102 | AI36: 0.195 | AJ36: 0.479 | AK36: -0.04 | AL36: -0.912 | AM36: 0.172 | AN36: 0.367 | AO36: -0.056 | AP36: -0.225 | AQ36: 0.617 | AR36: 1 | AS36: 0.251 | AT36: 0.432 | AU36: 0.659 | AV36: 0.518 | AW36: -0.34 | AX36: -0.298 | AY36: 0.583 | AZ36: 0.238 | BA36: 0.65 | BB36: -0.21 | BC36: -0.646 | BD36: 0.424 | BE36: -0.813 | BF36: 0.372 | BG36: -0.075 | BH36: -0.44 | BI36: -0.157 | BJ36: 0.347 | BK36: 0.387 | BM36: =10%*AK36+5%*AL36+2.5%*AM36+2.5%*AN36+10%*AO36+10%*AP36+10%*AQ36+5%*AR36+5%*AS36+10%*AT36+5%*AU36+5%*AY36+10%*AV36+10%*AW36 -> 0.183125
A37: ITSA3 | B37: 0 | C37: =B37-E37 -> 0 | D37: =B37-K37 -> -0.024 | E37: =K37-L37 -> 0 | F37: 2.34 | G37: 3.177 | H37: pro_cyclicals | I37: =VLOOKUP(A37,Setores!$A$2:$C$215,2,0) -> banks | J37: =VLOOKUP(A37,Setores!$A$2:$C$215,3,0) -> neutral_beta | K37: 0.024 | L37: 0.024 | M37: =VLOOKUP(A37,'Mandato Ibov'!$B$1:$C$215,2,0) -> 0.011060813 | N37: =K37-M37 -> 0.012939187 | O37: =B37-M37 -> -0.011060813 | P37: =VLOOKUP(A37,'Mandato Ibov'!$B$2:$D$215,3,0) -> 0.0071802677 | Q37: =K37-P37 -> 0.016819732 | R37: -0.02 | S37: -0.124 | T37: -0.477 | U37: 0.216 | V37: -0.156 | W37: 0.425 | X37: 0.67 | Y37: 0.54 | Z37: 0.676 | AA37: 0.675 | AB37: 0.872 | AC37: 0.845 | AD37: 0.864 | AE37: 0.147 | AF37: -0.222 | AG37: 0.09 | AH37: -0.964 | AI37: -0.758 | AJ37: -0.816 | AK37: -0.174 | AL37: 0.211 | AM37: -0.679 | AN37: -0.208 | AO37: 0.498 | AP37: -0.056 | AQ37: 0.009 | AR37: 0.306 | AS37: 0.413 | AT37: -0.001 | AU37: -0.002 | AV37: 0.403 | AW37: 0.499 | AX37: -0.401 | AY37: 0.91 | AZ37: 0.668 | BA37: 0.967 | BB37: -0.207 | BC37: 0.014 | BD37: 0.557 | BE37: -0.215 | BF37: -0.339 | BG37: 0.841 | BH37: -0.656 | BI37: -0.146 | BJ37: 0.903 | BK37: -0.709 | BM37: =10%*AK37+5%*AL37+2.5%*AM37+2.5%*AN37+10%*AO37+10%*AP37+10%*AQ37+5%*AR37+5%*AS37+10%*AT37+5%*AU37+5%*AY37+10%*AV37+10%*AW37 -> 0.187525
A38: ABCB4 | B38: =K38 -> 0.016 | C38: =B38-E38 -> 0.016 | D38: =B38-K38 -> 0 | E38: =K38-L38 -> 0 | F38: 2.264 | G38: 2.965 | H38: pro_cyclicals | I38: =VLOOKUP(A38,Setores!$A$2:$C$215,2,0) -> banks | J38: =VLOOKUP(A38,Setores!$A$2:$C$215,3,0) -> low_beta | K38: 0.016 | L38: 0.016 | M38: =VLOOKUP(A38,'Mandato Ibov'!$B$1:$C$215,2,0) -> 0.010702296 | N38: =K38-M38 -> 0.0052977041 | O38: =B38-M38 -> 0.0052977041 | P38: =VLOOKUP(A38,'Mandato Ibov'!$B$2:$D$215,3,0) -> 0.0055117039 | Q38: =K38-P38 -> 0.010488296 | R38: -0.02 | S38: 0.153 | T38: -0.277 | U38: -0.017 | V38: -0.049 | W38: 0.306 | X38: 0.439 | Y38: 0.384 | Z38: 0.757 | AA38: 0.753 | AB38: 0.848 | AC38: 0.874 | AD38: 0.903 | AE38: -0.611 | AF38: 0.412 | AG38: 0.618 | AH38: -0.285 | AI38: 0.053 | AJ38: -0.779 | AK38: -0.119 | AL38: 0.261 | AM38: -0.092 | AN38: 0.169 | AO38: 0.277 | AP38: -0.112 | AQ38: 0.043 | AR38: 0.208 | AS38: -0.34 | AT38: -0.135 | AU38: -0.277 | AV38: -0.551 | AW38: 0.648 | AX38: 0.097 | AY38: 0.807 | AZ38: 0.584 | BA38: 0.52 | BB38: -0.337 | BC38: -0.107 | BD38: 0.472 | BE38: -0.176 | BF38: 0.848 | BG38: 0.921 | BH38: -0.594 | BI38: -0.251 | BJ38: 0.419 | BK38: 0.433 | BM38: =10%*AK38+5%*AL38+2.5%*AM38+2.5%*AN38+10%*AO38+10%*AP38+10%*AQ38+5%*AR38+5%*AS38+10%*AT38+5%*AU38+5%*AY38+10%*AV38+10%*AW38 -> 0.039975
A39: MELK3 | B39: =K39 -> 0.014 | C39: =B39-E39 -> 0.014 | D39: =B39-K39 -> 0 | E39: =K39-L39 -> 0 | F39: 2.248 | G39: 2.456 | H39: pro_cyclicals | I39: =VLOOKUP(A39,Setores!$A$2:$C$215,2,0) -> homebuilders | J39: =VLOOKUP(A39,Setores!$A$2:$C$215,3,0) -> low_beta | K39: 0.014 | L39: 0.014 | M39: =VLOOKUP(A39,'Mandato Ibov'!$B$1:$C$215,2,0) -> 0.0106272 | N39: =K39-M39 -> 0.0033727999 | O39: =B39-M39 -> 0.0033727999 | P39: =VLOOKUP(A39,'Mandato Ibov'!$B$2:$D$215,3,0) -> 0.0087400116 | Q39: =K39-P39 -> 0.0052599884 | R39: 0.059 | S39: -0.075 | T39: 0.403 | U39: 0.029 | V39: 0.168 | W39: 0.288 | X39: 0.456 | Y39: 0.35 | Z39: 0.568 | AA39: 0.566 | AB39: 0.854 | AC39: 0.908 | AD39: 0.771 | AE39: 0.137 | AF39: 0.117 | AG39: -0.407 | AH39: 0.853 | AI39: 0.068 | AJ39: -0.022 | AK39: -0.361 | AL39: 0.978 | AM39: -0.036 | AN39: -0.103 | AO39: -0.282 | AP39: -0.551 | AQ39: 0.006 | AR39: 0.554 | AS39: 0.476 | AT39: -0.105 | AU39: -0.446 | AV39: -0.04 | AW39: 0.591 | AX39: -0.293 | AY39: 0.534 | AZ39: 0.366 | BA39: -0.034 | BB39: -0.383 | BC39: -0.692 | BD39: -0.154 | BE39: -0.43 | BF39: -0.336 | BG39: 0.788 | BH39: -0.278 | BI39: 0.104 | BJ39: 0.737 | BK39: 0.693 | BM39: =10%*AK39+5%*AL39+2.5%*AM39+2.5%*AN39+10%*AO39+10%*AP39+10%*AQ39+5%*AR39+5%*AS39+10%*AT39+5%*AU39+5%*AY39+10%*AV39+10%*AW39 -> 0.027125
A40: BMOB3 | B40: =K40 -> 0.014 | C40: =B40-E40 -> 0.014 | D40: =B40-K40 -> 0 | E40: =K40-L40 -> 0 | F40: 2.205 | G40: 2.151 | H40: pro_cyclicals | I40: =VLOOKUP(A40,Setores!$A$2:$C$215,2,0) -> tech | J40: =VLOOKUP(A40,Setores!$A$2:$C$215,3,0) -> neutral_beta | K40: 0.014 | L40: 0.014 | M40: =VLOOKUP(A40,'Mandato Ibov'!$B$1:$C$215,2,0) -> 0.010425588 | N40: =K40-M40 -> 0.0035744123 | O40: =B40-M40 -> 0.0035744123 | P40: =VLOOKUP(A40,'Mandato Ibov'!$B$2:$D$215,3,0) -> 0.0091537294 | Q40: =K40-P40 -> 0.0048462706 | R40: 0.416 | S40: 0.146 | T40: 0.371 | U40: 0.236 | V40: 0.135 | W40: 0.381 | X40: 0.26 | Y40: 0.126 | Z40: 0.144 | AA40: 0.141 | AB40: 0.777 | AC40: 0.938 | AD40: 0.844 | AE40: 0.222 | AF40: -0.113 | AG40: -0.274 | AH40: -0.377 | AI40: 0.998 | AJ40: 1 | AK40: -0.342 | AL40: -0.163 | AM40: -0.866 | AN40: -0.075 | AO40: 0.182 | AP40: 0.683 | AQ40: 0.432 | AR40: 0.367 | AS40: 0.391 | AT40: 0.381 | AU40: -0.434 | AV40: 0.663 | AW40: 0.22 | AX40: 0.517 | AY40: 0.928 | AZ40: 0.551 | BA40: 0.902 | BB40: -0.032 | BC40: -0.052 | BD40: -0.782 | BE40: -0.45 | BF40: 0.568 | BG40: 0.69 | BH40: -0.583 | BI40: -0.098 | BJ40: 0.304 | BK40: 0.208 | BM40: =10%*AK40+5%*AL40+2.5%*AM40+2.5%*AN40+10%*AO40+10%*AP40+10%*AQ40+5%*AR40+5%*AS40+10%*AT40+5%*AU40+5%*AY40+10%*AV40+10%*AW40 -> 0.252825
A41: LEVE3 | B41: =K41 -> 0.012 | C41: =B41-E41 -> 0.012 | D41: =B41-K41 -> 0 | E41: =K41-L41 -> 0 | F41: 2.179 | G41: 2.562 | H41: industrials | I41: =VLOOKUP(A41,Setores!$A$2:$C$215,2,0) -> capital_goods | J41: =VLOOKUP(A41,Setores!$A$2:$C$215,3,0) -> very_low_beta | K41: 0.012 | L41: 0.012 | M41: =VLOOKUP(A41,'Mandato Ibov'!$B$1:$C$215,2,0) -> 0.010299107 | N41: =K41-M41 -> 0.0017008928 | O41: =B41-M41 -> 0.0017008928 | P41: =VLOOKUP(A41,'Mandato Ibov'!$B$2:$D$215,3,0) -> 0.011600843 | Q41: =K41-P41 -> 0.00039915689 | R41: 0.03 | S41: -0.222 | T41: -0.037 | U41: 0.252 | V41: -0.023 | W41: 0.34 | X41: 0.51 | Y41: 0.333 | Z41: 0.715 | AA41: 0.714 | AB41: 0.836 | AC41: 0.765 | AD41: 0.736 | AE41: 0.228 | AF41: -0.329 | AG41: -0.275 | AH41: -0.49 | AI41: 0.063 | AJ41: 0.273 | AK41: -0.146 | AL41: 0.28 | AM41: -0.886 | AN41: 0.019 | AO41: 0.088 | AP41: 0.331 | AQ41: 0.237 | AR41: 0.377 | AS41: -0.077 | AT41: 0.995 | AU41: -0.306 | AV41: 0.542 | AW41: 0.654 | AX41: -0.048 | AY41: 0.71 | AZ41: 0.696 | BA41: -0.584 | BB41: -0.238 | BC41: -0.558 | BD41: 0.076 | BE41: -0.569 | BF41: 0.086 | BG41: 0.664 | BH41: -0.472 | BI41: -0.04 | BJ41: 0.472 | BK41: 0.034 | BM41: =10%*AK41+5%*AL41+2.5%*AM41+2.5%*AN41+10%*AO41+10%*AP41+10%*AQ41+5%*AR41+5%*AS41+10%*AT41+5%*AU41+5%*AY41+10%*AV41+10%*AW41 -> 0.297625
A42: EUCA4 | B42: =K42 -> 0.009 | C42: =B42-E42 -> 0.009 | D42: =B42-K42 -> 0 | E42: =K42-L42 -> 0 | F42: 2.174 | G42: 2.337 | H42: industrials | I42: =VLOOKUP(A42,Setores!$A$2:$C$215,2,0) -> building_materials | J42: =VLOOKUP(A42,Setores!$A$2:$C$215,3,0) -> very_low_beta | K42: 0.009 | L42: 0.009 | M42: =VLOOKUP(A42,'Mandato Ibov'!$B$1:$C$215,2,0) -> 0.010277042 | N42: =K42-M42 -> -0.0012770424 | O42: =B42-M42 -> -0.0012770424 | P42: =VLOOKUP(A42,'Mandato Ibov'!$B$2:$D$215,3,0) -> 0.0080345058 | Q42: =K42-P42 -> 0.00096549416 | R42: 0.285 | S42: 0.098 | T42: 0.184 | U42: 0.269 | V42: 0.104 | W42: 0.074 | X42: -0.014 | Y42: 0.023 | Z42: 0.772 | AA42: 0.768 | AB42: 1 | AC42: 0.912 | AD42: 0.897 | AE42: 0.07 | AF42: -0.052 | AG42: -0.122 | AH42: -0.228 | AI42: -0.026 | AJ42: 0.157 | AK42: 0.144 | AL42: -0.28 | AM42: -0.201 | AN42: -0.511 | AO42: 0.139 | AP42: 0.035 | AQ42: 0.334 | AR42: 0.636 | AS42: 0.342 | AT42: 0.361 | AU42: -0.133 | AV42: 0.346 | AW42: 0.61 | AX42: 0.124 | AY42: 0.762 | AZ42: 0.511 | BA42: 0.663 | BB42: -0.267 | BC42: -0.322 | BD42: 0.682 | BE42: -1 | BF42: -0.024 | BG42: -0.069 | BH42: -0.693 | BI42: -0.025 | BJ42: 0.979 | BK42: 0.14 | BM42: =10%*AK42+5%*AL42+2.5%*AM42+2.5%*AN42+10%*AO42+10%*AP42+10%*AQ42+5%*AR42+5%*AS42+10%*AT42+5%*AU42+5%*AY42+10%*AV42+10%*AW42 -> 0.24545
A43: CSUD3 | B43: =K43 -> 0.013 | C43: =B43-E43 -> 0.013 | D43: =B43-K43 -> 0 | E43: =K43-L43 -> 0 | F43: 2.159 | G43: 2.298 | H43: pro_cyclicals | I43: =VLOOKUP(A43,Setores!$A$2:$C$215,2,0) -> financial_services | J43: =VLOOKUP(A43,Setores!$A$2:$C$215,3,0) -> very_low_beta | K43: 0.013 | L43: 0.013 | M43: =VLOOKUP(A43,'Mandato Ibov'!$B$1:$C$215,2,0) -> 0.010205892 | N43: =K43-M43 -> 0.0027941085 | O43: =B43-M43 -> 0.0027941085 | P43: =VLOOKUP(A43,'Mandato Ibov'!$B$2:$D$215,3,0) -> 0.0062863823 | Q43: =K43-P43 -> 0.0067136177 | R43: 0.23 | S43: -0.169 | T43: 0.541 | U43: 0.184 | V43: 0.206 | W43: 0.298 | X43: 0.467 | Y43: 0.17 | Z43: 0.41 | AA43: 0.411 | AB43: 0.785 | AC43: 0.709 | AD43: 0.752 | AE43: 0.527 | AF43: -0.121 | AG43: -0.722 | AH43: 0.476 | AI43: 0.028 | AJ43: 1 | AK43: -0.072 | AL43: 0.325 | AM43: -0.604 | AN43: 0.364 | AO43: -0.131 | AP43: -0.337 | AQ43: 0.006 | AR43: 0.096 | AS43: -0.35 | AT43: 0.572 | AU43: 0.023 | AV43: 0.43 | AW43: 0.646 | AX43: -0.078 | AY43: 0.889 | AZ43: 0.367 | BA43: 0.907 | BB43: -0.3 | BC43: -0.32 | BD43: -0.096 | BE43: -0.632 | BF43: 0.044 | BG43: 0.376 | BH43: -0.394 | BI43: -0.68 | BJ43: 0.874 | BK43: 0.903 | BM43: =10%*AK43+5%*AL43+2.5%*AM43+2.5%*AN43+10%*AO43+10%*AP43+10%*AQ43+5%*AR43+5%*AS43+10%*AT43+5%*AU43+5%*AY43+10%*AV43+10%*AW43 -> 0.15455
...

Sheet 35 - SMLL
B1: =COUNTIF(B9:B222,">0") -> 64 | E1: =COUNTIF(E9:E222,">0") -> 107 | K1: Act Share | L1: Bmk | M1: Mandato | N1: Modelo 2.0 | O1: Meta | S1: Modelos | AF1: Interações | AL1: Clusters
K2: Meta | L2: =SQRT(SUMSQ(L9:L222)^2) -> 0.025911 | M2: =SQRT(SUMSQ(O9:O222)^2) -> 0.0056573174 | N2: =SQRT(SUMSQ(R9:R222)^2) -> 0.016580346
E3: MF - Meta | F3: =SUMPRODUCT($D$9:$D$222,F9:F222) -> 0.01944 | K3: MF | L3: =SQRT(SUMSQ(C9:C222)^2) -> 0.02466625 | M3: =SQRT(SUMSQ(P9:P222)^2) -> 0.003230955 | O3: =SQRT(SUMSQ(D9:D222)^2) -> 0.00280425
E4: Meta - 2.0 | F4: =SUMPRODUCT($R$9:$R$222,F9:F222) -> 0.28664574 | R4: MF - Meta | S4: =SUMPRODUCT($D$9:$D$226,S9:S226) -> 0.0096685 | T4: =SUMPRODUCT($D$9:$D$226,T9:T226) -> 0.029332 | U4: =SUMPRODUCT($D$9:$D$226,U9:U226) -> 0.008372 | V4: =SUMPRODUCT($D$9:$D$226,V9:V226) -> 0.0092695 | W4: =SUMPRODUCT($D$9:$D$226,W9:W226) -> 0.0213305 | X4: =SUMPRODUCT($D$9:$D$226,X9:X226) -> 0.008898 | Y4: =SUMPRODUCT($D$9:$D$226,Y9:Y226) -> 0.000838 | Z4: =SUMPRODUCT($D$9:$D$226,Z9:Z226) -> 0.009817 | ... BL4: =SUMPRODUCT($D$9:$D$226,BL9:BL226) -> 0.0505145
E5: Meta - Mandato | F5: =SUMPRODUCT($O$9:$O$222,F9:F222) -> -0.16852387 | R5: Meta - 2.0 | S5: =SUMPRODUCT($R$9:$R$226,S9:S226) -> 0.22174161 | T5: =SUMPRODUCT($R$9:$R$226,T9:T226) -> 0.10194263 | U5: =SUMPRODUCT($R$9:$R$226,U9:U226) -> 0.29679101 | V5: =SUMPRODUCT($R$9:$R$226,V9:V226) -> 0.1692171 | W5: =SUMPRODUCT($R$9:$R$226,W9:W226) -> 0.19721738 | X5: =SUMPRODUCT($R$9:$R$226,X9:X226) -> 0.16364992 | Y5: =SUMPRODUCT($R$9:$R$226,Y9:Y226) -> 0.13382343 | Z5: =SUMPRODUCT($R$9:$R$226,Z9:Z226) -> 0.072871613 | ... BL5: =SUMPRODUCT($R$9:$R$226,BL9:BL226) -> 0.09172254
E6: Meta - Bmk | F6: =SUMPRODUCT($L$9:$L$222,F9:F222) -> 1.16829 | G6: =SUMPRODUCT($L$9:$L$222,G9:G222) -> 0.985298 | R6: Meta - Mandato | S6: =SUMPRODUCT($O$9:$O$226,S8:S225) -> -0.083684056 | T6: =SUMPRODUCT($O$9:$O$226,T8:T225) -> -0.093971221 | U6: =SUMPRODUCT($O$9:$O$226,U8:U225) -> -0.10467822 | V6: =SUMPRODUCT($O$9:$O$226,V8:V225) -> -0.057609762 | W6: =SUMPRODUCT($O$9:$O$226,W8:W225) -> -0.091990103 | X6: =SUMPRODUCT($O$9:$O$226,X8:X225) -> -0.037293004 | Y6: =SUMPRODUCT($O$9:$O$226,Y8:Y225) -> 0.0036994201 | Z6: =SUMPRODUCT($O$9:$O$226,Z8:Z225) -> -0.03305356 | ... BL6: =SUMPRODUCT($O$9:$O$226,BL8:BL225) -> -0.094285101
B7: =SUM(B9:B222) -> 0.9995 | E7: =SUM(E9:E222) -> 1.005 | K7: =SUM(K9:K222) -> 1 | N7: =SUM(N9:N222) -> 1 | Q7: =SUM(Q9:Q222) -> 1 | R7: Meta - Bmk | S7: =SUMPRODUCT($L$9:$L$226,S9:S226) -> 0.669161 | T7: =SUMPRODUCT($L$9:$L$226,T9:T226) -> 0.611905 | U7: =SUMPRODUCT($L$9:$L$226,U9:U226) -> 0.634624 | V7: =SUMPRODUCT($L$9:$L$226,V9:V226) -> 0.679227 | W7: =SUMPRODUCT($L$9:$L$226,W9:W226) -> 0.670947 | X7: =SUMPRODUCT($L$9:$L$226,X9:X226) -> 0.663008 | Y7: =SUMPRODUCT($L$9:$L$226,Y9:Y226) -> 0.592108 | Z7: =SUMPRODUCT($L$9:$L$226,Z9:Z226) -> 0.682796 | ... BL7: =SUMPRODUCT($L$9:$L$226,BL9:BL226) -> 0.151208
A8: tickers | B8: MF | C8: MF - Smll | D8: MF - META | E8: Bmk | F8: exp_ret_score_raw | G8: exp_ret_score | H8: sectors_c2 | I8: sectors_c1 | J8: sectors_dyn | K8: META | L8: act_weights | M8: ibov_rank | N8: mandato | O8: Meta - Mandato | P8: MF - Mandao | Q8: modelo 2.0 | R8: Meta - 2.0 | S8: ew | T8: sw_mom | U8: sw_val | V8: sw_lt_perf | W8: sw_overall | X8: rp_cc | Y8: hrp_cc | Z8: mvo_overall_cc_con | AA8: ols | AB8: glmnet_bayes | AC8: rf_bayes | AD8: xgb_bayes | AE8: nn1_bayes | AF8: qv | AG8: garp | AH8: vm | AI8: sv | AJ8: sm | AK8: smcj | AL8: fac_inc_cs_value | AM8: fac_payout_yield | AN8: fac_bs_cs_value | AO8: fac_ts_value | AP8: fac_interm_momentum | AQ8: fac_st_momentum | AR8: fac_lt_profit_growth | AS8: fac_st_profit_growth | AT8: fac_surprise | AU8: fac_bs_profitability | AV8: fac_profit_margins | AW8: fac_quality | AX8: fac_mkt_risk | AY8: fac_leverage | AZ8: fac_profit_vol | BA8: fac_seasonality | BB8: fac_short_interest | BC8: fac_acc_growth | BD8: fac_accruals | BE8: fac_issuance | BF8: fac_st_reversal | BG8: fac_skewness | BH8: fac_max | BI8: fac_lt_reversal | BJ8: fac_macro | BK8: fac_liquidity | BL8: fac_size
A9: JHSF3 | B9: 0.026 | C9: =B9-E9 -> 0.018 | D9: =B9-K9 -> 0.01 | E9: =K9-L9 -> 0.008 | F9: 3.612 | G9: 4.683 | H9: pro_cyclicals | I9: =VLOOKUP(A9,Setores!$A$2:$C$215,2,0) -> homebuilders | J9: =VLOOKUP(A9,Setores!$A$2:$C$215,3,0) -> very_high_beta | K9: 0.016 | L9: 0.008 | M9: 80 | N9: =VLOOKUP(A9,'Mandato Smll'!$A$2:$C$215,2,0) -> 0.036202388 | O9: =K9-N9 -> -0.020202388 | P9: =B9-N9 -> -0.010202388 | Q9: =VLOOKUP(A9,'Mandato Smll'!$A$2:$C$215,3,0) -> 0.032680853 | R9: =K9-Q9 -> -0.016680853 | S9: 1 | T9: 1 | U9: 0.606 | V9: 1 | W9: 1 | X9: 1 | Y9: 0.973 | Z9: 1 | AA9: 0.695 | AB9: 0.691 | AC9: 0.929 | AD9: 0.859 | AE9: 1 | AF9: 1 | AG9: 0.938 | AH9: 1 | AI9: -0.415 | AJ9: 0.728 | AK9: 0.253 | AL9: 0.296 | AM9: -0.053 | AN9: -0.411 | AO9: 0.313 | AP9: 0.632 | AQ9: 0.927 | AR9: 0.532 | AS9: 0.182 | AT9: 0.309 | AU9: 0.33 | AV9: 0.414 | AW9: 0.908 | AX9: -0.045 | AY9: 0.136 | AZ9: -0.176 | BA9: 0.537 | BB9: -0.253 | BC9: 0.008 | BD9: 0.541 | BE9: 0.647 | BF9: 0.217 | BG9: 0.151 | BH9: 0.142 | BI9: -0.857 | BJ9: 0.704 | BK9: -0.051 | BL9: -0.258
A10: WIZC3 | B10: 0.015 | C10: =B10-E10 -> 0.015 | D10: =B10-K10 -> 0 | E10: =K10-L10 -> 0 | F10: 3.612 | G10: 3.511 | H10: defensives | I10: =VLOOKUP(A10,Setores!$A$2:$C$215,2,0) -> financial_services | J10: =VLOOKUP(A10,Setores!$A$2:$C$215,3,0) -> very_low_beta | K10: 0.015 | L10: 0.015 | M10: 80 | N10: =VLOOKUP(A10,'Mandato Smll'!$A$2:$C$215,2,0) -> 0.016068234 | O10: =K10-N10 -> -0.0010682341 | P10: =B10-N10 -> -0.0010682341 | Q10: =VLOOKUP(A10,'Mandato Smll'!$A$2:$C$215,3,0) -> 0.0096893833 | R10: =K10-Q10 -> 0.0053106167 | S10: 1 | T10: 0.966 | U10: 1 | V10: 1 | W10: 1 | X10: 1 | Y10: 1 | Z10: 0.631 | AA10: 0.724 | AB10: 0.723 | AC10: 1 | AD10: 1 | AE10: 0.99 | AF10: 1 | AG10: 0.205 | AH10: 0.421 | AI10: 0.546 | AJ10: 0.997 | AK10: 1 | AL10: 0.551 | AM10: -0.187 | AN10: -0.263 | AO10: 0.055 | AP10: 0.036 | AQ10: 0.118 | AR10: 0.271 | AS10: 0.157 | AT10: -0.346 | AU10: 0.724 | AV10: 0.403 | AW10: 1 | AX10: 0.363 | AY10: -0.062 | AZ10: 0.804 | BA10: 0.496 | BB10: -0.043 | BC10: 0.05 | BD10: 0.06 | BE10: 0.535 | BF10: -0.021 | BG10: 1 | BH10: 0.641 | BI10: -0.361 | BJ10: -0.367 | BK10: 0.614 | BL10: 0.693
A11: LOGG3 | B11: 0.018 | C11: =B11-E11 -> 0.014 | D11: =B11-K11 -> 0.003 | E11: =K11-L11 -> 0.004 | F11: 3.612 | G11: 4.551 | H11: bond_proxies | I11: =VLOOKUP(A11,Setores!$A$2:$C$215,2,0) -> real_estate | J11: =VLOOKUP(A11,Setores!$A$2:$C$215,3,0) -> neutral_beta | K11: 0.015 | L11: 0.011 | M11: 80 | N11: =VLOOKUP(A11,'Mandato Smll'!$A$2:$C$215,2,0) -> 0.022252393 | O11: =K11-N11 -> -0.0072523931 | P11: =B11-N11 -> -0.0042523931 | Q11: =VLOOKUP(A11,'Mandato Smll'!$A$2:$C$215,3,0) -> 0.011704847 | R11: =K11-Q11 -> 0.0032951526 | S11: 0.753 | T11: 1 | U11: 0.511 | V11: 0.896 | W11: 0.882 | X11: 0.996 | Y11: 1 | Z11: 1 | AA11: 0.535 | AB11: 0.54 | AC11: 1 | AD11: 0.991 | AE11: 1 | AF11: 1 | AG11: 0.092 | AH11: 0.797 | AI11: 0.298 | AJ11: 0.918 | AK11: -0.122 | AL11: -0.204 | AM11: 0.327 | AN11: -0.17 | AO11: 0.033 | AP11: 0.439 | AQ11: 0.023 | AR11: -0.072 | AS11: 0.527 | AT11: 0.52 | AU11: -0.109 | AV11: 0.759 | AW11: 0.419 | AX11: 0.344 | AY11: -0.735 | AZ11: 0.03 | BA11: -0.262 | BB11: -0.245 | BC11: 0.135 | BD11: 0.593 | BE11: 0.51 | BF11: -0.351 | BG11: -0.122 | BH11: 0.728 | BI11: -0.416 | BJ11: 0.223 | BK11: 0.369 | BL11: 0.297
A12: FIQE3 | B12: 0.015 | C12: =B12-E12 -> 0.015 | D12: =B12-K12 -> 0 | E12: =K12-L12 -> 0 | F12: 3.612 | G12: 3.585 | H12: bond_proxies | I12: =VLOOKUP(A12,Setores!$A$2:$C$215,2,0) -> telecom | J12: =VLOOKUP(A12,Setores!$A$2:$C$215,3,0) -> low_beta | K12: 0.015 | L12: 0.015 | M12: 80 | N12: =VLOOKUP(A12,'Mandato Smll'!$A$2:$C$215,2,0) -> 0.016068234 | O12: =K12-N12 -> -0.0010682341 | P12: =B12-N12 -> -0.0010682341 | Q12: =VLOOKUP(A12,'Mandato Smll'!$A$2:$C$215,3,0) -> 0.014190228 | R12: =K12-Q12 -> 0.00080977182 | S12: 1 | T12: 1 | U12: 0.642 | V12: 1 | W12: 0.938 | X12: 1 | Y12: 1 | Z12: 1 | AA12: 0.687 | AB12: 0.689 | AC12: 1 | AD12: 1 | AE12: 1 | AF12: 0.557 | AG12: 0.002 | AH12: 0.805 | AI12: -0.261 | AJ12: 1 | AK12: 0.752 | AL12: -0.205 | AM12: 0.133 | AN12: -0.805 | AO12: 0.064 | AP12: 0.751 | AQ12: 1 | AR12: 0.293 | AS12: 0.405 | AT12: 0.475 | AU12: 0.417 | AV12: 0.26 | AW12: 0.767 | AX12: 0.426 | AY12: 0.179 | AZ12: 0.885 | BA12: 0.104 | BB12: 0.583 | BC12: -0.299 | BD12: -0.201 | BE12: 0.293 | BF12: -0.371 | BG12: 0.371 | BH12: 0.682 | BI12: -0.527 | BJ12: -0.401 | BK12: 0.717 | BL12: 0.495
A13: BMGB4 | B13: 0.014 | C13: =B13-E13 -> 0.014 | D13: =B13-K13 -> 0 | E13: =K13-L13 -> 0 | F13: 3.612 | G13: 3.556 | H13: pro_cyclicals | I13: =VLOOKUP(A13,Setores!$A$2:$C$215,2,0) -> banks | J13: =VLOOKUP(A13,Setores!$A$2:$C$215,3,0) -> high_beta | K13: 0.014 | L13: 0.014 | M13: 80 | N13: =VLOOKUP(A13,'Mandato Smll'!$A$2:$C$215,2,0) -> 0.016068234 | O13: =K13-N13 -> -0.0020682341 | P13: =B13-N13 -> -0.0020682341 | Q13: =VLOOKUP(A13,'Mandato Smll'!$A$2:$C$215,3,0) -> 0.01450522 | R13: =K13-Q13 -> -0.00050521981 | S13: 0.902 | T13: 1 | U13: 0.817 | V13: 0.911 | W13: 1 | X13: 1 | Y13: 1 | Z13: 1 | AA13: 1 | AB13: 1 | AC13: 1 | AD13: 1 | AE13: 1 | AF13: 0.194 | AG13: 1 | AH13: 1 | AI13: 0.251 | AJ13: 1 | AK13: 0.23 | AL13: 0.073 | AM13: 0.54 | AN13: 0.42 | AO13: 0.223 | AP13: 0.561 | AQ13: 0.813 | AR13: 0.557 | AS13: 0.25 | AT13: -0.139 | AU13: 0.002 | AV13: -0.267 | AW13: -0.131 | AX13: 0.515 | AY13: -0.09 | AZ13: 0.655 | BA13: 0.249 | BB13: -0.003 | BC13: 0.126 | BD13: 0.215 | BE13: -0.732 | BF13: -0.363 | BG13: 0.186 | BH13: 0.936 | BI13: -0.81 | BJ13: 0.082 | BK13: 0.64 | BL13: 0.679
A14: ALLD3 | B14: 0.011 | C14: =B14-E14 -> 0.011 | D14: =B14-K14 -> 0.003 | E14: =K14-L14 -> 0 | F14: 3.612 | G14: 2.69 | H14: pro_cyclicals | I14: =VLOOKUP(A14,Setores!$A$2:$C$215,2,0) -> consumer_durables | J14: =VLOOKUP(A14,Setores!$A$2:$C$215,3,0) -> very_low_beta | K14: 0.008 | L14: 0.008 | M14: 80 | N14: =VLOOKUP(A14,'Mandato Smll'!$A$2:$C$215,2,0) -> 0.016068234 | O14: =K14-N14 -> -0.0080682341 | P14: =B14-N14 -> -0.0050682341 | Q14: =VLOOKUP(A14,'Mandato Smll'!$A$2:$C$215,3,0) -> 0.0092479761 | R14: =K14-Q14 -> -0.0012479761 | S14: 1 | T14: 0.646 | U14: 1 | V14: 1 | W14: 1 | X14: 1 | Y14: 1 | Z14: 0.737 | AA14: 1 | AB14: 1 | AC14: 0.735 | AD14: 0.749 | AE14: 0.928 | AF14: 1 | AG14: 1 | AH14: -0.138 | AI14: 1 | AJ14: -0.315 | AK14: 1 | AL14: 0.882 | AM14: 1 | AN14: 0.451 | AO14: 0.652 | AP14: -0.808 | AQ14: -0.665 | AR14: 0.303 | AS14: 0.594 | AT14: 0.097 | AU14: 0.697 | AV14: -0.548 | AW14: 0.908 | AX14: 0.326 | AY14: 0.054 | AZ14: 0.47 | BA14: 0.604 | BB14: 0.25 | BC14: 0.292 | BD14: 0.303 | BE14: 0.594 | BF14: 0.043 | BG14: 0.097 | BH14: 0.907 | BI14: -0.345 | BJ14: -0.437 | BK14: 0.521 | BL14: 0.802
A15: RIAA3 | B15: 0.015 | C15: =B15-E15 -> 0.013 | D15: =B15-K15 -> 0 | E15: =K15-L15 -> 0.002 | F15: 3.529 | G15: 2.708 | H15: pro_cyclicals | I15: =VLOOKUP(A15,Setores!$A$2:$C$215,2,0) -> apparel | J15: =VLOOKUP(A15,Setores!$A$2:$C$215,3,0) -> very_high_beta | K15: 0.015 | L15: 0.013 | M15: 80 | N15: =VLOOKUP(A15,'Mandato Smll'!$A$2:$C$215,2,0) -> 0.017842949 | O15: =K15-N15 -> -0.0028429486 | P15: =B15-N15 -> -0.0028429486 | Q15: =VLOOKUP(A15,'Mandato Smll'!$A$2:$C$215,3,0) -> 0.010739004 | R15: =K15-Q15 -> 0.0042609957 | S15: 0.993 | T15: 0.849 | U15: 0.797 | V15: 1 | W15: 0.969 | X15: 0.786 | Y15: 0.514 | Z15: 0.755 | AA15: 0.757 | AB15: 0.752 | AC15: 0.778 | AD15: 0.798 | AE15: 0.956 | AF15: 1 | AG15: 1 | AH15: 0.418 | AI15: 0.137 | AJ15: 0.133 | AK15: 0.61 | AL15: 0.556 | AM15: 0.091 | AN15: -0.118 | AO15: 0.478 | AP15: 0.227 | AQ15: -0.081 | AR15: 0.584 | AS15: 0.768 | AT15: 0.384 | AU15: 0.428 | AV15: -0.1 | AW15: 0.958 | AX15: -0.591 | AY15: 0.077 | AZ15: 0.423 | BA15: 0.629 | BB15: -0.314 | BC15: 0.211 | BD15: 0.019 | BE15: 0.625 | BF15: 0.234 | BG15: -0.288 | BH15: 0.204 | BI15: -0.488 | BJ15: 0.292 | BK15: 0.253 | BL15: 0.206
A16: GRND3 | B16: 0.015 | C16: =B16-E16 -> 0.013 | D16: =B16-K16 -> 0 | E16: =K16-L16 -> 0.002 | F16: 3.497 | G16: 4.141 | H16: pro_cyclicals | I16: =VLOOKUP(A16,Setores!$A$2:$C$215,2,0) -> apparel | J16: =VLOOKUP(A16,Setores!$A$2:$C$215,3,0) -> very_low_beta | K16: 0.015 | L16: 0.013 | M16: 80 | N16: =VLOOKUP(A16,'Mandato Smll'!$A$2:$C$215,2,0) -> 0.01888876 | O16: =K16-N16 -> -0.0038887601 | P16: =B16-N16 -> -0.0038887601 | Q16: =VLOOKUP(A16,'Mandato Smll'!$A$2:$C$215,3,0) -> 0.0095426165 | R16: =K16-Q16 -> 0.0054573835 | S16: 0.737 | T16: 0.61 | U16: 0.678 | V16: 0.687 | W16: 0.675 | X16: 1 | Y16: 1 | Z16: 0.978 | AA16: 0.556 | AB16: 0.559 | AC16: 0.894 | AD16: 0.839 | AE16: 0.891 | AF16: 0.847 | AG16: 0.063 | AH16: -0.123 | AI16: 0.027 | AJ16: 0.129 | AK16: 0.847 | AL16: 0.135 | AM16: 0.948 | AN16: -0.477 | AO16: 0.54 | AP16: 0.169 | AQ16: -0.258 | AR16: -0.023 | AS16: 0.299 | AT16: -0.168 | AU16: 0.205 | AV16: 0.159 | AW16: 0.17 | AX16: 0.518 | AY16: 0.774 | AZ16: 0.495 | BA16: -0.049 | BB16: 0.102 | BC16: 0.553 | BD16: 0.507 | BE16: 0.546 | BF16: 0.211 | BG16: 0.048 | BH16: 0.829 | BI16: -0.075 | BJ16: -0.358 | BK16: 0.197 | BL16: 0.347
A17: HBRE3 | B17: 0.014 | C17: =B17-E17 -> 0.014 | D17: =B17-K17 -> 0 | E17: =K17-L17 -> 0 | F17: 3.378 | G17: 2.51 | H17: bond_proxies | I17: =VLOOKUP(A17,Setores!$A$2:$C$215,2,0) -> real_estate | J17: =VLOOKUP(A17,Setores!$A$2:$C$215,3,0) -> very_high_beta | K17: 0.014 | L17: 0.014 | M17: 80 | N17: =VLOOKUP(A17,'Mandato Smll'!$A$2:$C$215,2,0) -> 0.015027458 | O17: =K17-N17 -> -0.0010274581 | P17: =B17-N17 -> -0.0010274581 | Q17: =VLOOKUP(A17,'Mandato Smll'!$A$2:$C$215,3,0) -> 0 | R17: =K17-Q17 -> 0.014 | S17: 1 | T17: 1 | U17: 1 | V17: 0.702 | W17: 1 | X17: 0.86 | Y17: 0.81 | Z17: 0.47 | AA17: 0.557 | AB17: 0.556 | AC17: 0.644 | AD17: 0.81 | AE17: 0.978 | AF17: 0.237 | AG17: 1 | AH17: 1 | AI17: 1 | AJ17: 0.384 | AK17: -0.225 | AL17: 0.75 | AM17: -0.02 | AN17: 1 | AO17: 0.775 | AP17: -0.097 | AQ17: -0.185 | AR17: -0.221 | AS17: 0.343 | AT17: 0.114 | AU17: -0.228 | AV17: 0.47 | AW17: -0.336 | AX17: -0.048 | AY17: -0.714 | AZ17: -0.344 | BA17: 0.126 | BB17: 0.847 | BC17: 0.166 | BD17: 0.739 | BE17: 0.326 | BF17: -0.001 | BG17: 0.315 | BH17: 0.283 | BI17: 0.154 | BJ17: 0.819 | BK17: 0.621 | BL17: 0.974
