Workbook

Sheet 29 - FIA
B1: =COUNTIF(B9:B222,">0") -> 70 | E1: =COUNTIF(E9:E222,">0") -> 82 | K1: Act Share | L1: Bmk | M1: Mandato | N1: Modelo 2.0 | O1: Meta | R1: Modelos | AE1: Interações | AK1: Clusters
K2: Meta | L2: =SQRT(SUMSQ(L9:L222)^2) -> 0.028648 | M2: =SQRT(SUMSQ(N9:N222)^2) -> 0.011613963 | N2: =SQRT(SUMSQ(Q9:Q222)^2) -> 0.016104689
E3: MF - Meta | F3: =SUMPRODUCT($D$9:$D$222,F9:F222) -> 0.0453245 | K3: MF | L3: =SQRT(SUMSQ(C9:C222)^2) -> 0.025881 | M3: =SQRT(SUMSQ(O9:O222)^2) -> 0.0077695005 | O3: =SQRT(SUMSQ(D9:D222)^2) -> 0.001755
E4: Meta - 2.0 | F4: =SUMPRODUCT($Q$9:$Q$222,F9:F222) -> 0.14824029 | Q4: MF - Meta | R4: =SUMPRODUCT($D$9:$D$222,R9:R222) -> 0.002224 | S4: =SUMPRODUCT($D$9:$D$222,S9:S222) -> 0.036637 | T4: =SUMPRODUCT($D$9:$D$222,T9:T222) -> -0.0214555 | U4: =SUMPRODUCT($D$9:$D$222,U9:U222) -> 0.027442 | V4: =SUMPRODUCT($D$9:$D$222,V9:V222) -> 0.024823 | W4: =SUMPRODUCT($D$9:$D$222,W9:W222) -> 0.0323545 | X4: =SUMPRODUCT($D$9:$D$222,X9:X222) -> 0.0320335 | Y4: =SUMPRODUCT($D$9:$D$222,Y9:Y222) -> 0.039434 | ... BK4: =SUMPRODUCT($D$9:$D$222,BK9:BK222) -> -0.0395335
E5: Meta - Mandato | F5: =SUMPRODUCT($N$9:$N$222,F9:F222) -> -0.29501619 | Q5: Meta - 2.0 | R5: =SUMPRODUCT($Q$9:$Q$222,R8:R221) -> 0.069992677 | S5: =SUMPRODUCT($Q$9:$Q$222,S8:S221) -> 0.059022074 | T5: =SUMPRODUCT($Q$9:$Q$222,T8:T221) -> 0.049883926 | U5: =SUMPRODUCT($Q$9:$Q$222,U8:U221) -> 0.092977471 | V5: =SUMPRODUCT($Q$9:$Q$222,V8:V221) -> 0.081574548 | W5: =SUMPRODUCT($Q$9:$Q$222,W8:W221) -> 0.067072081 | X5: =SUMPRODUCT($Q$9:$Q$222,X8:X221) -> 0.029411808 | Y5: =SUMPRODUCT($Q$9:$Q$222,Y8:Y221) -> 0.060329438 | ... BK5: =SUMPRODUCT($Q$9:$Q$222,BK8:BK221) -> 0.0021132287
E6: Meta - Bmk | F6: =SUMPRODUCT($L$9:$L$222,F9:F222) -> 0.945976 | G6: =SUMPRODUCT($L$9:$L$222,G9:G222) -> 0.491052 | Q6: Meta - Mandato | R6: =SUMPRODUCT($N$9:$N$222,R9:R222) -> -0.16380101 | S6: =SUMPRODUCT($N$9:$N$222,S9:S222) -> -0.16830965 | T6: =SUMPRODUCT($N$9:$N$222,T9:T222) -> -0.10476061 | U6: =SUMPRODUCT($N$9:$N$222,U9:U222) -> -0.20004875 | V6: =SUMPRODUCT($N$9:$N$222,V9:V222) -> -0.18217704 | W6: =SUMPRODUCT($N$9:$N$222,W9:W222) -> -0.17646254 | X6: =SUMPRODUCT($N$9:$N$222,X9:X222) -> -0.14720546 | Y6: =SUMPRODUCT($N$9:$N$222,Y9:Y222) -> -0.14473658 | ... BK6: =SUMPRODUCT($N$9:$N$222,BK9:BK222) -> -0.017758614
B7: =SUM(B9:B222) -> 1 | E7: =SUM(E9:E222) -> 1 | K7: =SUM(K9:K222) -> 1.002 | M7: =SUM(M9:M222) -> 1 | P7: =SUM(P9:P222) -> 1 | Q7: Meta - Bmk | R7: =SUMPRODUCT($L$9:$L$226,R9:R226) -> 0.645657 | S7: =SUMPRODUCT($L$9:$L$226,S9:S226) -> 0.450684 | T7: =SUMPRODUCT($L$9:$L$226,T9:T226) -> 0.715184 | U7: =SUMPRODUCT($L$9:$L$226,U9:U226) -> 0.532446 | V7: =SUMPRODUCT($L$9:$L$226,V9:V226) -> 0.608712 | W7: =SUMPRODUCT($L$9:$L$226,W9:W226) -> 0.527245 | X7: =SUMPRODUCT($L$9:$L$226,X9:X226) -> 0.437461 | Y7: =SUMPRODUCT($L$9:$L$226,Y9:Y226) -> 0.474667 | ... BK7: =SUMPRODUCT($L$9:$L$226,BK9:BK226) -> 0.589495
A8: tickers | B8: MF | C8: MF - Ibov | D8: MF - META | E8: Bmk | F8: exp_ret_score_raw | G8: exp_ret_score | H8: sectors_c2 | I8: sectors_c1 | J8: sectors_dyn | K8: META | L8: act_weights | M8: mandato | N8: META - Mandato | O8: MF - Mandao | P8: modelo 2.0 | Q8: Meta - 2.0 | R8: ew | S8: sw_mom | T8: sw_val | U8: sw_lt_perf | V8: sw_overall | W8: rp_cc | X8: hrp_cc | Y8: mvo_overall_cc_con | Z8: ols | AA8: glmnet_bayes | AB8: rf_bayes | AC8: xgb_bayes | AD8: nn1_bayes | AE8: qv | AF8: garp | AG8: vm | AH8: sv | AI8: sm | AJ8: smcj | AK8: fac_inc_cs_value | AL8: fac_payout_yield | AM8: fac_bs_cs_value | AN8: fac_ts_value | AO8: fac_interm_momentum | AP8: fac_st_momentum | AQ8: fac_lt_profit_growth | AR8: fac_st_profit_growth | AS8: fac_surprise | AT8: fac_bs_profitability | AU8: fac_profit_margins | AV8: fac_quality | AW8: fac_mkt_risk | AX8: fac_leverage | AY8: fac_profit_vol | AZ8: fac_seasonality | BA8: fac_short_interest | BB8: fac_acc_growth | BC8: fac_accruals | BD8: fac_issuance | BE8: fac_st_reversal | BF8: fac_skewness | BG8: fac_max | BH8: fac_lt_reversal | BI8: fac_macro | BJ8: fac_liquidity | BK8: fac_size
A9: WIZC3 | B9: =K9 -> 0.014 | C9: =B9-E9 -> 0.014 | D9: =B9-K9 -> 0 | E9: =K9-L9 -> 0 | F9: 3.261 | G9: 3.444 | H9: defensives | I9: =VLOOKUP(A9,Planilha6!$BL$9:$BN$222,2,0) -> financial_services | J9: =VLOOKUP(A9,Planilha6!$BL$9:$BN$222,3,0) -> low_beta | K9: 0.014 | L9: 0.014 | M9: =VLOOKUP(A9,'Mandato Ibov'!$B$1:$C$215,2,0) -> 0.014696516 | N9: =K9-M9 -> -0.00069651617 | O9: =B9-M9 -> -0.00069651617 | P9: =VLOOKUP(A9,'Mandato Ibov'!$B$2:$D$215,3,0) -> 0.010528639 | Q9: =K9-P9 -> 0.0034713605 | R9: 1 | S9: 1 | T9: 1 | U9: 1 | V9: 1 | W9: 1 | X9: 1 | Y9: 0.903 | Z9: 0.817 | AA9: 0.826 | AB9: 1 | AC9: 1 | AD9: 1 | AE9: 1 | AF9: 0.241 | AG9: 0.49 | AH9: 0.447 | AI9: 0.841 | AJ9: 1 | AK9: 0.477 | AL9: -0.271 | AM9: -0.236 | AN9: -0.056 | AO9: 0.114 | AP9: 0.015 | AQ9: 0.304 | AR9: 0.173 | AS9: 0.233 | AT9: 0.847 | AU9: 0.517 | AV9: 0.759 | AW9: 0.418 | AX9: -0.066 | AY9: 0.636 | AZ9: 1 | BA9: 0.851 | BB9: -0.177 | BC9: 0.006 | BD9: 0.393 | BE9: 0.134 | BF9: 0.783 | BG9: 0.809 | BH9: -0.469 | BI9: -0.202 | BJ9: 0.615 | BK9: 0.798 | BM9: =SUMPRODUCT(R9:AD9,$R$225:$AD$225) -> 0.9637631
A10: JHSF3 | B10: =K10 -> 0.011 | C10: =B10-E10 -> 0.011 | D10: =B10-K10 -> 0 | E10: =K10-L10 -> 0 | F10: 3.261 | G10: 3.158 | H10: pro_cyclicals | I10: =VLOOKUP(A10,Planilha6!$BL$9:$BN$222,2,0) -> homebuilders | J10: =VLOOKUP(A10,Planilha6!$BL$9:$BN$222,3,0) -> very_high_beta | K10: 0.011 | L10: 0.011 | M10: =VLOOKUP(A10,'Mandato Ibov'!$B$1:$C$215,2,0) -> 0.014696516 | N10: =K10-M10 -> -0.0036965162 | O10: =B10-M10 -> -0.0036965162 | P10: =VLOOKUP(A10,'Mandato Ibov'!$B$2:$D$215,3,0) -> 0.011222419 | Q10: =K10-P10 -> -0.00022241857 | R10: 1 | S10: 1 | T10: 0.907 | U10: 1 | V10: 1 | W10: 1 | X10: 1 | Y10: 0.989 | Z10: 0.919 | AA10: 0.922 | AB10: 0.908 | AC10: 0.952 | AD10: 1 | AE10: 1 | AF10: 1 | AG10: 1 | AH10: -0.45 | AI10: 0.31 | AJ10: 0.34 | AK10: 0.287 | AL10: -0.104 | AM10: -0.455 | AN10: 0.136 | AO10: 0.8 | AP10: 0.769 | AQ10: 0.615 | AR10: 0.414 | AS10: 0.976 | AT10: 0.525 | AU10: 0.913 | AV10: 0.997 | AW10: -0.029 | AX10: 0.216 | AY10: 0.188 | AZ10: 0.763 | BA10: 0.149 | BB10: -0.1 | BC10: 0.573 | BD10: 0.306 | BE10: -1 | BF10: 0.248 | BG10: -0.132 | BH10: -0.672 | BI10: 0.631 | BJ10: 0.025 | BK10: -0.268 | BM10: =SUMPRODUCT(R10:AD10,$R$225:$AD$225) -> 0.9805947
A11: BMGB4 | B11: =K11 -> 0.01 | C11: =B11-E11 -> 0.01 | D11: =B11-K11 -> 0 | E11: =K11-L11 -> 0 | F11: 3.261 | G11: 3.335 | H11: pro_cyclicals | I11: =VLOOKUP(A11,Planilha6!$BL$9:$BN$222,2,0) -> banks | J11: =VLOOKUP(A11,Planilha6!$BL$9:$BN$222,3,0) -> high_beta | K11: 0.01 | L11: 0.01 | M11: =VLOOKUP(A11,'Mandato Ibov'!$B$1:$C$215,2,0) -> 0.014696516 | N11: =K11-M11 -> -0.0046965162 | O11: =B11-M11 -> -0.0046965162 | P11: =VLOOKUP(A11,'Mandato Ibov'!$B$2:$D$215,3,0) -> 0.011222419 | Q11: =K11-P11 -> -0.0012224186 | R11: 0.916 | S11: 0.882 | T11: 0.789 | U11: 0.877 | V11: 0.975 | W11: 0.701 | X11: 0.542 | Y11: 0.732 | Z11: 1 | AA11: 1 | AB11: 1 | AC11: 0.973 | AD11: 1 | AE11: 0.053 | AF11: 1 | AG11: 1 | AH11: 0.061 | AI11: 0.609 | AJ11: 0.345 | AK11: 0.076 | AL11: 0.43 | AM11: 0.453 | AN11: 0.057 | AO11: 0.652 | AP11: 0.106 | AQ11: 0.544 | AR11: 1 | AS11: -0.031 | AT11: 0.056 | AU11: -0.204 | AV11: -0.217 | AW11: 0.525 | AX11: -0.14 | AY11: 0.812 | AZ11: 0.15 | BA11: -0.238 | BB11: 0.064 | BC11: 0.001 | BD11: 0.647 | BE11: -0.457 | BF11: -0.309 | BG11: 0.337 | BH11: -0.754 | BI11: 0.07 | BJ11: 0.654 | BK11: 0.642 | BM11: =SUMPRODUCT(R11:AD11,$R$225:$AD$225) -> 0.8631715
A12: RIAA3 | B12: =K12 -> 0.009 | C12: =B12-E12 -> 0.009 | D12: =B12-K12 -> 0 | E12: =K12-L12 -> 0 | F12: 3.261 | G12: 2.528 | H12: pro_cyclicals | I12: =VLOOKUP(A12,Planilha6!$BL$9:$BN$222,2,0) -> apparel | J12: =VLOOKUP(A12,Planilha6!$BL$9:$BN$222,3,0) -> very_high_beta | K12: 0.009 | L12: 0.009 | M12: =VLOOKUP(A12,'Mandato Ibov'!$B$1:$C$215,2,0) -> 0.014696516 | N12: =K12-M12 -> -0.0056965162 | O12: =B12-M12 -> -0.0056965162 | P12: =VLOOKUP(A12,'Mandato Ibov'!$B$2:$D$215,3,0) -> 0.010796721 | Q12: =K12-P12 -> -0.0017967207 | R12: 1 | S12: 1 | T12: 1 | U12: 1 | V12: 1 | W12: 0.975 | X12: 0.688 | Y12: 0.586 | Z12: 0.955 | AA12: 0.959 | AB12: 0.804 | AC12: 0.855 | AD12: 0.968 | AE12: 1 | AF12: 1 | AG12: 0.652 | AH12: 0.03 | AI12: 0.265 | AJ12: 0.681 | AK12: 0.459 | AL12: 0.101 | AM12: -0.148 | AN12: 0.505 | AO12: 0.282 | AP12: 0.441 | AQ12: 0.612 | AR12: 0.999 | AS12: 0.662 | AT12: 0.657 | AU12: 0.118 | AV12: 0.782 | AW12: -0.567 | AX12: 0.214 | AY12: 0.626 | AZ12: 0.553 | BA12: -0.497 | BB12: 0.179 | BC12: 0.057 | BD12: 0.609 | BE12: -0.773 | BF12: -0.537 | BG12: 0.242 | BH12: -0.523 | BI12: 0.428 | BJ12: 0.235 | BK12: 0.131 | BM12: =SUMPRODUCT(R12:AD12,$R$225:$AD$225) -> 0.8715232
A13: CSED3 | B13: =K13 -> 0.009 | C13: =B13-E13 -> 0.009 | D13: =B13-K13 -> 0 | E13: =K13-L13 -> 0 | F13: 3.261 | G13: 2.574 | H13: pro_cyclicals | I13: =VLOOKUP(A13,Planilha6!$BL$9:$BN$222,2,0) -> education | J13: =VLOOKUP(A13,Planilha6!$BL$9:$BN$222,3,0) -> high_beta | K13: 0.009 | L13: 0.009 | M13: =VLOOKUP(A13,'Mandato Ibov'!$B$1:$C$215,2,0) -> 0.014696516 | N13: =K13-M13 -> -0.0056965162 | O13: =B13-M13 -> -0.0056965162 | P13: =VLOOKUP(A13,'Mandato Ibov'!$B$2:$D$215,3,0) -> 0.010573984 | Q13: =K13-P13 -> -0.0015739839 | R13: 1 | S13: 1 | T13: 1 | U13: 1 | V13: 1 | W13: 1 | X13: 0.941 | Y13: 0.768 | Z13: 0.614 | AA13: 0.616 | AB13: 1 | AC13: 0.951 | AD13: 0.935 | AE13: 1 | AF13: 1 | AG13: 0.124 | AH13: 0.206 | AI13: 0.403 | AJ13: 1 | AK13: 0.371 | AL13: 0.099 | AM13: -0.603 | AN13: 0.331 | AO13: 0.06 | AP13: -0.193 | AQ13: 0.8 | AR13: 1 | AS13: 0.849 | AT13: 0.506 | AU13: 0.042 | AV13: 0.926 | AW13: -0.17 | AX13: -0.052 | AY13: 0.81 | AZ13: 0.998 | BA13: 0.872 | BB13: -0.051 | BC13: -0.103 | BD13: 0.232 | BE13: 0.298 | BF13: 1 | BG13: 0.517 | BH13: -0.445 | BI13: 0.139 | BJ13: 0.715 | BK13: 0.318 | BM13: =SUMPRODUCT(R13:AD13,$R$225:$AD$225) -> 0.9005612
A14: ALLD3 | B14: 0.009 | C14: =B14-E14 -> 0.009 | D14: =B14-K14 -> 0.001 | E14: =K14-L14 -> 0 | F14: 3.261 | G14: 2.528 | H14: pro_cyclicals | I14: =VLOOKUP(A14,Planilha6!$BL$9:$BN$222,2,0) -> consumer_durables | J14: =VLOOKUP(A14,Planilha6!$BL$9:$BN$222,3,0) -> very_low_beta | K14: 0.008 | L14: 0.008 | M14: =VLOOKUP(A14,'Mandato Ibov'!$B$1:$C$215,2,0) -> 0.014696516 | N14: =K14-M14 -> -0.0066965162 | O14: =B14-M14 -> -0.0056965162 | P14: =VLOOKUP(A14,'Mandato Ibov'!$B$2:$D$215,3,0) -> 0.011222419 | Q14: =K14-P14 -> -0.0032224186 | R14: 1 | S14: 0.906 | T14: 1 | U14: 1 | V14: 1 | W14: 1 | X14: 1 | Y14: 1 | Z14: 1 | AA14: 1 | AB14: 0.847 | AC14: 0.809 | AD14: 0.966 | AE14: 1 | AF14: 1 | AG14: 0.174 | AH14: 1 | AI14: -0.036 | AJ14: 1 | AK14: 0.893 | AL14: 1 | AM14: 0.503 | AN14: 0.722 | AO14: -0.354 | AP14: -0.493 | AQ14: 0.369 | AR14: -0.124 | AS14: -0.006 | AT14: 0.808 | AU14: -0.377 | AV14: 0.637 | AW14: 0.361 | AX14: 0.097 | AY14: 0.674 | AZ14: 0.223 | BA14: 0.655 | BB14: 0.318 | BC14: 0.317 | BD14: 0.509 | BE14: 0.864 | BF14: 1 | BG14: 0.732 | BH14: -0.456 | BI14: -0.442 | BJ14: 0.471 | BK14: 0.792 | BM14: =SUMPRODUCT(R14:AD14,$R$225:$AD$225) -> 0.9766646
A15: SYNE3 | B15: =K15 -> 0.008 | C15: =B15-E15 -> 0.008 | D15: =B15-K15 -> 0 | E15: =K15-L15 -> 0 | F15: 3.257 | G15: 2.537 | H15: bond_proxies | I15: =VLOOKUP(A15,Planilha6!$BL$9:$BN$222,2,0) -> real_estate | J15: =VLOOKUP(A15,Planilha6!$BL$9:$BN$222,3,0) -> neutral_beta | K15: 0.008 | L15: 0.008 | M15: =VLOOKUP(A15,'Mandato Ibov'!$B$1:$C$215,2,0) -> 0.014680455 | N15: =K15-M15 -> -0.0066804553 | O15: =B15-M15 -> -0.0066804553 | P15: =VLOOKUP(A15,'Mandato Ibov'!$B$2:$D$215,3,0) -> 0.0074194024 | Q15: =K15-P15 -> 0.0005805976 | R15: 0.977 | S15: 0.59 | T15: 1 | U15: 0.907 | V15: 0.966 | W15: 0.964 | X15: 0.959 | Y15: 0.973 | Z15: 0.642 | AA15: 0.642 | AB15: 0.626 | AC15: 0.457 | AD15: 0.799 | AE15: 1 | AF15: 1 | AG15: -0.379 | AH15: 1 | AI15: 0.193 | AJ15: 1 | AK15: 0.334 | AL15: 1 | AM15: 0.199 | AN15: -0.225 | AO15: -0.224 | AP15: -0.278 | AQ15: 0.719 | AR15: -0.751 | AS15: 0.011 | AT15: 0.004 | AU15: 0.18 | AV15: 0.533 | AW15: 0.247 | AX15: -0.371 | AY15: 0.352 | AZ15: 0.256 | BA15: 0.145 | BB15: 0.686 | BC15: 1 | BD15: 0.72 | BE15: 0.834 | BF15: 1 | BG15: 0.335 | BH15: -0.906 | BI15: 0.26 | BJ15: 0.618 | BK15: 0.771 | BM15: =SUMPRODUCT(R15:AD15,$R$225:$AD$225) -> 0.8603519
A16: POMO3 | B16: =K16 -> 0.009 | C16: =B16-E16 -> 0.009 | D16: =B16-K16 -> 0 | E16: =K16-L16 -> 0 | F16: 3.228 | G16: 2.949 | H16: industrials | I16: =VLOOKUP(A16,Planilha6!$BL$9:$BN$222,2,0) -> capital_goods | J16: =VLOOKUP(A16,Planilha6!$BL$9:$BN$222,3,0) -> neutral_beta | K16: 0.009 | L16: 0.009 | M16: =VLOOKUP(A16,'Mandato Ibov'!$B$1:$C$215,2,0) -> 0.014549271 | N16: =K16-M16 -> -0.0055492711 | O16: =B16-M16 -> -0.0055492711 | P16: =VLOOKUP(A16,'Mandato Ibov'!$B$2:$D$215,3,0) -> 0.0068122102 | Q16: =K16-P16 -> 0.0021877898 | R16: 0.839 | S16: 0.877 | T16: 0.672 | U16: 0.932 | V16: 1 | W16: 1 | X16: 1 | Y16: 1 | Z16: 0.642 | AA16: 0.647 | AB16: 0.808 | AC16: 0.756 | AD16: 0.704 | AE16: 1 | AF16: 1 | AG16: -0.197 | AH16: -0.419 | AI16: -0.261 | AJ16: 0.405 | AK16: -0.003 | AL16: 0.601 | AM16: -0.614 | AN16: 0.429 | AO16: -0.103 | AP16: 0.286 | AQ16: 0.941 | AR16: 0.126 | AS16: -0.527 | AT16: 0.719 | AU16: -0.029 | AV16: 0.539 | AW16: 0.42 | AX16: 0.163 | AY16: 0.91 | AZ16: 1 | BA16: 0.581 | BB16: -0.046 | BC16: -0.167 | BD16: 0.22 | BE16: -0.345 | BF16: -0.617 | BG16: 0.563 | BH16: -0.989 | BI16: 0.355 | BJ16: 0.72 | BK16: -0.209 | BM16: =SUMPRODUCT(R16:AD16,$R$225:$AD$225) -> 0.8499682
A17: SHUL4 | B17: =K17 -> 0.012 | C17: =B17-E17 -> 0.012 | D17: =B17-K17 -> 0 | E17: =K17-L17 -> 0 | F17: 3.132 | G17: 3.876 | H17: industrials | I17: =VLOOKUP(A17,Planilha6!$BL$9:$BN$222,2,0) -> capital_goods | J17: =VLOOKUP(A17,Planilha6!$BL$9:$BN$222,3,0) -> low_beta | K17: 0.012 | L17: 0.012 | M17: =VLOOKUP(A17,'Mandato Ibov'!$B$1:$C$215,2,0) -> 0.014117597 | N17: =K17-M17 -> -0.0021175971 | O17: =B17-M17 -> -0.0021175971 | P17: =VLOOKUP(A17,'Mandato Ibov'!$B$2:$D$215,3,0) -> 0.0077194535 | Q17: =K17-P17 -> 0.0042805465 | R17: 0.721 | S17: 0.878 | T17: 0.708 | U17: 0.282 | V17: 0.706 | W17: 0.778 | X17: 0.84 | Y17: 0.77 | Z17: 0.982 | AA17: 0.982 | AB17: 0.921 | AC17: 0.974 | AD17: 0.976 | AE17: -0.334 | AF17: -0.296 | AG17: 0.308 | AH17: 0.127 | AI17: 0.947 | AJ17: -0.135 | AK17: -0.046 | AL17: 0.33 | AM17: -0.426 | AN17: 0.436 | AO17: 0.439 | AP17: 0.294 | AQ17: -0.044 | AR17: 0.28 | AS17: 0.169 | AT17: 0.36 | AU17: -0.143 | AV17: -0.152 | AW17: 0.733 | AX17: 0.494 | AY17: 0.905 | AZ17: 0.706 | BA17: 0.814 | BB17: -0.144 | BC17: -0.183 | BD17: -0.045 | BE17: 0.269 | BF17: 0.31 | BG17: 1 | BH17: -0.443 | BI17: -0.023 | BJ17: 0.858 | BK17: 0.286 | BM17: =SUMPRODUCT(R17:AD17,$R$225:$AD$225) -> 0.8160552
A18: FIQE3 | B18: =K18 -> 0.012 | C18: =B18-E18 -> 0.012 | D18: =B18-K18 -> 0 | E18: =K18-L18 -> 0 | F18: 3.082 | G18: 3.174 | H18: bond_proxies | I18: =VLOOKUP(A18,Planilha6!$BL$9:$BN$222,2,0) -> telecom | J18: =VLOOKUP(A18,Planilha6!$BL$9:$BN$222,3,0) -> low_beta | K18: 0.012 | L18: 0.012 | M18: =VLOOKUP(A18,'Mandato Ibov'!$B$1:$C$215,2,0) -> 0.013891662 | N18: =K18-M18 -> -0.0018916623 | O18: =B18-M18 -> -0.0018916623 | P18: =VLOOKUP(A18,'Mandato Ibov'!$B$2:$D$215,3,0) -> 0.011222419 | Q18: =K18-P18 -> 0.00077758143 | R18: 0.886 | S18: 0.823 | T18: 0.713 | U18: 0.994 | V18: 0.952 | W18: 0.642 | X18: 0.616 | Y18: 0.585 | Z18: 0.668 | AA18: 0.676 | AB18: 1 | AC18: 1 | AD18: 1 | AE18: 0.629 | AF18: -0.012 | AG18: 0.847 | AH18: -0.234 | AI18: 1 | AJ18: 1 | AK18: -0.23 | AL18: 0.091 | AM18: -0.768 | AN18: 0.009 | AO18: 0.871 | AP18: 0.813 | AQ18: 0.298 | AR18: 0.199 | AS18: 0.439 | AT18: 0.523 | AU18: 0.36 | AV18: 0.722 | AW18: 0.446 | AX18: -0.068 | AY18: 0.93 | AZ18: -0.661 | BA18: 0.851 | BB18: -0.161 | BC18: -0.297 | BD18: 0.597 | BE18: -1 | BF18: -0.32 | BG18: -0.17 | BH18: -0.541 | BI18: -0.361 | BJ18: 0.7 | BK18: 0.468 | BM18: =SUMPRODUCT(R18:AD18,$R$225:$AD$225) -> 0.7981371
A19: MTRE3 | B19: 0.014 | C19: =B19-E19 -> 0.014 | D19: =B19-K19 -> -0.001 | E19: =K19-L19 -> 0 | F19: 3.077 | G19: 3.096 | H19: pro_cyclicals | I19: =VLOOKUP(A19,Planilha6!$BL$9:$BN$222,2,0) -> homebuilders | J19: =VLOOKUP(A19,Planilha6!$BL$9:$BN$222,3,0) -> neutral_beta | K19: 0.015 | L19: 0.015 | M19: =VLOOKUP(A19,'Mandato Ibov'!$B$1:$C$215,2,0) -> 0.013869747 | N19: =K19-M19 -> 0.0011302531 | O19: =B19-M19 -> 0.00013025315 | P19: =VLOOKUP(A19,'Mandato Ibov'!$B$2:$D$215,3,0) -> 0.010241009 | Q19: =K19-P19 -> 0.0047589907 | R19: 0.879 | S19: 0.604 | T19: 0.947 | U19: 0.578 | V19: 0.76 | W19: 0.77 | X19: 0.732 | Y19: 0.685 | Z19: 0.685 | AA19: 0.687 | AB19: 1 | AC19: 0.953 | AD19: 0.917 | AE19: 0.527 | AF19: 0.465 | AG19: 0.502 | AH19: 1 | AI19: 0.966 | AJ19: 0.018 | AK19: -0.107 | AL19: 0.714 | AM19: 0.319 | AN19: 0.349 | AO19: 0.011 | AP19: 0.21 | AQ19: 0.263 | AR19: 0.136 | AS19: -0.081 | AT19: 0.013 | AU19: -0.221 | AV19: 0.077 | AW19: -0.064 | AX19: -0.285 | AY19: 0.765 | AZ19: 0.183 | BA19: 0.558 | BB19: 0.048 | BC19: -0.275 | BD19: 0.131 | BE19: 0.064 | BF19: 0.003 | BG19: 0.917 | BH19: -0.142 | BI19: 0.233 | BJ19: 0.595 | BK19: 0.837 | BM19: =SUMPRODUCT(R19:AD19,$R$225:$AD$225) -> 0.7963066
A20: BRSR6 | B20: =K20 -> 0.012 | C20: =B20-E20 -> 0.012 | D20: =B20-K20 -> 0 | E20: =K20-L20 -> 0 | F20: 3.053 | G20: 3.259 | H20: pro_cyclicals | I20: =VLOOKUP(A20,Planilha6!$BL$9:$BN$222,2,0) -> banks | J20: =VLOOKUP(A20,Planilha6!$BL$9:$BN$222,3,0) -> high_beta | K20: 0.012 | L20: 0.012 | M20: =VLOOKUP(A20,'Mandato Ibov'!$B$1:$C$215,2,0) -> 0.013762926 | N20: =K20-M20 -> -0.0017629263 | O20: =B20-M20 -> -0.0017629263 | P20: =VLOOKUP(A20,'Mandato Ibov'!$B$2:$D$215,3,0) -> 0.011060179 | Q20: =K20-P20 -> 0.00093982079 | R20: 0.722 | S20: 0.822 | T20: 0.383 | U20: 0.77 | V20: 0.835 | W20: 0.662 | X20: 0.569 | Y20: 0.682 | Z20: 1 | AA20: 1 | AB20: 0.957 | AC20: 0.985 | AD20: 1 | AE20: 0.002 | AF20: 0.92 | AG20: 1 | AH20: -0.092 | AI20: 0.3 | AJ20: -0.516 | AK20: 0.067 | AL20: 0.284 | AM20: 0.456 | AN20: 0.401 | AO20: 0.626 | AP20: 0.129 | AQ20: 0.239 | AR20: 0.566 | AS20: 0.683 | AT20: 0.074 | AU20: -0.176 | AV20: -0.128 | AW20: 0.455 | AX20: -0.563 | AY20: 0.714 | AZ20: 0.397 | BA20: 0.39 | BB20: -0.151 | BC20: -0.066 | BD20: 0.454 | BE20: 0.494 | BF20: 1 | BG20: 0.466 | BH20: -0.58 | BI20: 0.035 | BJ20: 0.207 | BK20: 0.403 | BM20: =SUMPRODUCT(R20:AD20,$R$225:$AD$225) -> 0.7880018
A21: GRND3 | B21: =K21 -> 0.009 | C21: =B21-E21 -> 0.009 | D21: =B21-K21 -> 0 | E21: =K21-L21 -> 0 | F21: 3.007 | G21: 3.076 | H21: pro_cyclicals | I21: =VLOOKUP(A21,Planilha6!$BL$9:$BN$222,2,0) -> apparel | J21: =VLOOKUP(A21,Planilha6!$BL$9:$BN$222,3,0) -> very_low_beta | K21: 0.009 | L21: 0.009 | M21: =VLOOKUP(A21,'Mandato Ibov'!$B$1:$C$215,2,0) -> 0.013552612 | N21: =K21-M21 -> -0.0045526118 | O21: =B21-M21 -> -0.0045526118 | P21: =VLOOKUP(A21,'Mandato Ibov'!$B$2:$D$215,3,0) -> 0.0088452433 | Q21: =K21-P21 -> 0.00015475669 | R21: 0.69 | S21: 0.625 | T21: 0.448 | U21: 0.532 | V21: 0.623 | W21: 0.907 | X21: 1 | Y21: 1 | Z21: 0.59 | AA21: 0.597 | AB21: 0.791 | AC21: 0.77 | AD21: 0.747 | AE21: 0.934 | AF21: -0.051 | AG21: -0.365 | AH21: -0.082 | AI21: -0.23 | AJ21: 1 | AK21: -0.094 | AL21: 0.948 | AM21: -0.506 | AN21: 0.657 | AO21: 0.14 | AP21: 0.013 | AQ21: 0.081 | AR21: -0.001 | AS21: -0.467 | AT21: 0.308 | AU21: -0.007 | AV21: 0.386 | AW21: 0.495 | AX21: 0.835 | AY21: 0.66 | AZ21: -0.102 | BA21: 0.446 | BB21: 0.826 | BC21: 0.453 | BD21: 0.583 | BE21: 0.176 | BF21: 0.005 | BG21: 0.93 | BH21: -0.235 | BI21: -0.371 | BJ21: 0.129 | BK21: 0.293 | BM21: =SUMPRODUCT(R21:AD21,$R$225:$AD$225) -> 0.7714426
A22: TIMS3 | B22: =K22 -> 0.019 | C22: =B22-E22 -> 0.011 | D22: =B22-K22 -> 0 | E22: =K22-L22 -> 0.008 | F22: 2.998 | G22: 4.584 | H22: bond_proxies | I22: =VLOOKUP(A22,Planilha6!$BL$9:$BN$222,2,0) -> telecom | J22: =VLOOKUP(A22,Planilha6!$BL$9:$BN$222,3,0) -> very_low_beta | K22: 0.019 | L22: 0.011 | M22: =VLOOKUP(A22,'Mandato Ibov'!$B$1:$C$215,2,0) -> 0.029194607 | N22: =K22-M22 -> -0.010194607 | O22: =B22-M22 -> -0.010194607 | P22: =VLOOKUP(A22,'Mandato Ibov'!$B$2:$D$215,3,0) -> 0.018920006 | Q22: =K22-P22 -> 7.9994089e-05 | R22: 0.542 | S22: 1 | T22: -0.201 | U22: 0.855 | V22: 0.795 | W22: 1 | X22: 1 | Y22: 0.898 | Z22: 0.802 | AA22: 0.81 | AB22: 0.85 | AC22: 0.845 | AD22: 0.79 | AE22: 0.838 | AF22: 0.034 | AG22: 0.287 | AH22: -0.92 | AI22: -0.582 | AJ22: -0.423 | AK22: 0.231 | AL22: -0.068 | AM22: -0.848 | AN22: -0.478 | AO22: 0.382 | AP22: 0.671 | AQ22: 0.579 | AR22: 0.237 | AS22: 0.149 | AT22: 0.552 | AU22: 0.407 | AV22: 1 | AW22: 0.766 | AX22: 0.163 | AY22: 0.846 | AZ22: 0.277 | BA22: 0.813 | BB22: 0.36 | BC22: 0.37 | BD22: 0.67 | BE22: 0.271 | BF22: 0.39 | BG22: 0.946 | BH22: -0.771 | BI22: -0.359 | BJ22: -0.017 | BK22: -0.547 | BM22: =SUMPRODUCT(R22:AD22,$R$225:$AD$225) -> 0.7684141
A23: SAPR4 | B23: =K23 -> 0.011 | C23: =B23-E23 -> 0.011 | D23: =B23-K23 -> 0 | E23: =K23-L23 -> 0 | F23: 2.933 | G23: 3.163 | H23: bond_proxies | I23: =VLOOKUP(A23,Planilha6!$BL$9:$BN$222,2,0) -> utilities | J23: =VLOOKUP(A23,Planilha6!$BL$9:$BN$222,3,0) -> low_beta | K23: 0.011 | L23: 0.011 | M23: =VLOOKUP(A23,'Mandato Ibov'!$B$1:$C$215,2,0) -> 0.013222209 | N23: =K23-M23 -> -0.0022222087 | O23: =B23-M23 -> -0.0022222087 | P23: =VLOOKUP(A23,'Mandato Ibov'!$B$2:$D$215,3,0) -> 0.0078670833 | Q23: =K23-P23 -> 0.0031329167 | R23: 0.575 | S23: 0.876 | T23: 0.247 | U23: 0.806 | V23: 0.885 | W23: 0.812 | X23: 0.899 | Y23: 0.776 | Z23: 0.753 | AA23: 0.763 | AB23: 0.863 | AC23: 0.846 | AD23: 0.795 | AE23: 0.875 | AF23: 0.438 | AG23: 0.582 | AH23: -0.452 | AI23: -0.556 | AJ23: -0.145 | AK23: 0.484 | AL23: -0.202 | AM23: -0.316 | AN23: -0.052 | AO23: 0.212 | AP23: -0.205 | AQ23: 0.276 | AR23: -0.09 | AS23: -0.061 | AT23: 0.395 | AU23: 0.424 | AV23: 0.532 | AW23: 0.756 | AX23: -0.08 | AY23: 0.149 | AZ23: 0.837 | BA23: 0.898 | BB23: -0.133 | BC23: 0.179 | BD23: 0.183 | BE23: 0.246 | BF23: 1 | BG23: 0.439 | BH23: -0.752 | BI23: -0.085 | BJ23: 0.6 | BK23: 0.118 | BM23: =SUMPRODUCT(R23:AD23,$R$225:$AD$225) -> 0.7451919
A24: PFRM3 | B24: =K24 -> 0.008 | C24: =B24-E24 -> 0.008 | D24: =B24-K24 -> 0 | E24: =K24-L24 -> 0 | F24: 2.887 | G24: 2.303 | H24: defensives | I24: =VLOOKUP(A24,Planilha6!$BL$9:$BN$222,2,0) -> healthcare | J24: =VLOOKUP(A24,Planilha6!$BL$9:$BN$222,3,0) -> high_beta | K24: 0.008 | L24: 0.008 | M24: =VLOOKUP(A24,'Mandato Ibov'!$B$1:$C$215,2,0) -> 0.013012017 | N24: =K24-M24 -> -0.0050120171 | O24: =B24-M24 -> -0.0050120171 | P24: =VLOOKUP(A24,'Mandato Ibov'!$B$2:$D$215,3,0) -> 0.0089002949 | Q24: =K24-P24 -> -0.00090029494 | R24: 1 | S24: 0.464 | T24: 1 | U24: 1 | V24: 0.93 | W24: 0.613 | X24: 0.377 | Y24: 0.37 | Z24: 0.624 | AA24: 0.63 | AB24: 0.947 | AC24: 0.819 | AD24: 0.926 | AE24: 1 | AF24: 0.977 | AG24: 0.581 | AH24: 1 | AI24: 0.694 | AJ24: 0.719 | AK24: 0.655 | AL24: 0.1 | AM24: 0.107 | AN24: 0.075 | AO24: 0.138 | AP24: -0.038 | AQ24: 0.417 | AR24: 0.118 | AS24: -0.218 | AT24: 0.475 | AU24: -0.481 | AV24: 0.457 | AW24: 0.291 | AX24: -0.128 | AY24: 0.919 | AZ24: -0.172 | BA24: 0.741 | BB24: -0.122 | BC24: -0.038 | BD24: 0.101 | BE24: 0.463 | BF24: -0.099 | BG24: 0.161 | BH24: -0.688 | BI24: 0.081 | BJ24: 0.815 | BK24: 0.715 | BM24: =SUMPRODUCT(R24:AD24,$R$225:$AD$225) -> 0.7290081
A25: SAPR3 | B25: 0 | C25: =B25-E25 -> 0 | D25: =B25-K25 -> -0.009 | E25: =K25-L25 -> 0 | F25: 2.85 | G25: 2.454 | H25: bond_proxies | I25: =VLOOKUP(A25,Planilha6!$BL$9:$BN$222,2,0) -> utilities | J25: =VLOOKUP(A25,Planilha6!$BL$9:$BN$222,3,0) -> high_beta | K25: 0.009 | L25: 0.009 | M25: =VLOOKUP(A25,'Mandato Ibov'!$B$1:$C$215,2,0) -> 0.012847823 | N25: =K25-M25 -> -0.0038478228 | O25: =B25-M25 -> -0.012847823 | P25: =VLOOKUP(A25,'Mandato Ibov'!$B$2:$D$215,3,0) -> 0.0079549626 | Q25: =K25-P25 -> 0.0010450374 | R25: 0.558 | S25: 0.864 | T25: 0.327 | U25: 0.802 | V25: 0.903 | W25: 0.689 | X25: 0.706 | Y25: 0.667 | Z25: 0.835 | AA25: 0.845 | AB25: 0.874 | AC25: 0.814 | AD25: 0.827 | AE25: 0.811 | AF25: 0.4 | AG25: 0.739 | AH25: -0.467 | AI25: -0.518 | AJ25: -0.145 | AK25: 0.484 | AL25: -0.333 | AM25: -0.316 | AN25: -0.103 | AO25: 0.304 | AP25: -0.214 | AQ25: 0.276 | AR25: -0.09 | AS25: -0.061 | AT25: 0.395 | AU25: 0.424 | AV25: 0.532 | AW25: 0.648 | AX25: -0.08 | AY25: 0.149 | AZ25: 0.954 | BA25: 0.456 | BB25: -0.133 | BC25: 0.179 | BD25: 0.293 | BE25: 0.008 | BF25: 0.449 | BG25: 0.239 | BH25: -0.872 | BI25: 0.109 | BJ25: 0.962 | BK25: 0.118 | BM25: =SUMPRODUCT(R25:AD25,$R$225:$AD$225) -> 0.7159515
A26: DEXP3 | B26: =K26 -> 0.011 | C26: =B26-E26 -> 0.011 | D26: =B26-K26 -> 0 | E26: =K26-L26 -> 0 | F26: 2.829 | G26: 2.69 | H26: industrials | I26: =VLOOKUP(A26,Planilha6!$BL$9:$BN$222,2,0) -> chemicals | J26: =VLOOKUP(A26,Planilha6!$BL$9:$BN$222,3,0) -> very_low_beta | K26: 0.011 | L26: 0.011 | M26: =VLOOKUP(A26,'Mandato Ibov'!$B$1:$C$215,2,0) -> 0.012750222 | N26: =K26-M26 -> -0.0017502219 | O26: =B26-M26 -> -0.0017502219 | P26: =VLOOKUP(A26,'Mandato Ibov'!$B$2:$D$215,3,0) -> 0 | Q26: =K26-P26 -> 0.011 | R26: 0.69 | S26: 0.584 | T26: 0.855 | U26: 0.288 | V26: 0.627 | W26: 0.639 | X26: 0.652 | Y26: 0.613 | Z26: 0.885 | AA26: 0.89 | AB26: 0.865 | AC26: 0.777 | AD26: 0.838 | AE26: 0.547 | AF26: -0.463 | AG26: -0.245 | AH26: 0.75 | AI26: 0.262 | AJ26: 0.52 | AK26: 0.352 | AL26: 0.183 | AM26: -0.093 | AN26: 0.36 | AO26: 0.096 | AP26: -0.436 | AQ26: -0.057 | AR26: -0.17 | AS26: -0.479 | AT26: 0.551 | AU26: -0.246 | AV26: 0.248 | AW26: 0.583 | AX26: 0.479 | AY26: 0.869 | AZ26: 0.773 | BA26: 0.881 | BB26: -0.037 | BC26: -0.094 | BD26: 0.248 | BE26: 0.272 | BF26: -0.091 | BG26: 0.918 | BH26: -0.312 | BI26: -0.254 | BJ26: 0.927 | BK26: 0.883 | BM26: =SUMPRODUCT(R26:AD26,$R$225:$AD$225) -> 0.7084624
A27: PETR4 | B27: 0.055 | C27: =B27-E27 -> -0.018 | D27: =B27-K27 -> 0.028 | E27: =K27-L27 -> 0.073 | F27: 2.806 | G27: 5.734 | H27: commodities | I27: =VLOOKUP(A27,Planilha6!$BL$9:$BN$222,2,0) -> crude_oil | J27: =VLOOKUP(A27,Planilha6!$BL$9:$BN$222,3,0) -> very_low_beta | K27: 0.027 | L27: -0.046 | M27: =VLOOKUP(A27,'Mandato Ibov'!$B$1:$C$215,2,0) -> 0.07042607 | N27: =K27-M27 -> -0.04342607 | O27: =B27-M27 -> -0.01542607 | P27: =VLOOKUP(A27,'Mandato Ibov'!$B$2:$D$215,3,0) -> 0.062482534 | Q27: =K27-P27 -> -0.035482534 | R27: 0.112 | S27: 1 | T27: -0.544 | U27: 0.651 | V27: 0.729 | W27: 0.842 | X27: 0.869 | Y27: 1 | Z27: 1 | AA27: 1 | AB27: 0.644 | AC27: 0.867 | AD27: 0.912 | AE27: 0.399 | AF27: -0.306 | AG27: 1 | AH27: -0.912 | AI27: -0.555 | AJ27: -0.906 | AK27: 0.218 | AL27: 0.453 | AM27: -0.514 | AN27: -0.652 | AO27: 0.985 | AP27: 1 | AQ27: -0.241 | AR27: 0.669 | AS27: 0.465 | AT27: 0.465 | AU27: 0.344 | AV27: 0.372 | AW27: 0.496 | AX27: -0.231 | AY27: 0.814 | AZ27: 0.629 | BA27: 0.479 | BB27: -0.148 | BC27: -0.273 | BD27: 0.338 | BE27: 0.191 | BF27: 0.744 | BG27: 0.708 | BH27: -0.954 | BI27: -0.997 | BJ27: -0.259 | BK27: -0.89 | BM27: =SUMPRODUCT(R27:AD27,$R$225:$AD$225) -> 0.7003428
A28: LEVE3 | B28: =K28 -> 0.011 | C28: =B28-E28 -> 0.011 | D28: =B28-K28 -> 0 | E28: =K28-L28 -> 0 | F28: 2.696 | G28: 3.196 | H28: industrials | I28: =VLOOKUP(A28,Planilha6!$BL$9:$BN$222,2,0) -> capital_goods | J28: =VLOOKUP(A28,Planilha6!$BL$9:$BN$222,3,0) -> very_low_beta | K28: 0.011 | L28: 0.011 | M28: =VLOOKUP(A28,'Mandato Ibov'!$B$1:$C$215,2,0) -> 0.012150787 | N28: =K28-M28 -> -0.001150787 | O28: =B28-M28 -> -0.001150787 | P28: =VLOOKUP(A28,'Mandato Ibov'!$B$2:$D$215,3,0) -> 0.010928911 | Q28: =K28-P28 -> 7.1089482e-05 | R28: 0.303 | S28: 0.75 | T28: 0.358 | U28: 0.359 | V28: 0.72 | W28: 0.556 | X28: 0.698 | Y28: 0.825 | Z28: 0.883 | AA28: 0.888 | AB28: 0.781 | AC28: 0.804 | AD28: 0.788 | AE28: 0.036 | AF28: -0.326 | AG28: 0.117 | AH28: -0.488 | AI28: 0.317 | AJ28: 0.437 | AK28: -0.13 | AL28: 0.264 | AM28: -0.795 | AN28: -0.089 | AO28: 0.503 | AP28: 0.221 | AQ28: 0.323 | AR28: 0.151 | AS28: -0.072 | AT28: 0.989 | AU28: -0.065 | AV28: 0.357 | AW28: 0.664 | AX28: -0.057 | AY28: 0.804 | AZ28: 1 | BA28: 0.4 | BB28: -0.203 | BC28: -0.465 | BD28: -0.421 | BE28: 0.114 | BF28: -0.403 | BG28: 0.802 | BH28: -0.604 | BI28: -0.108 | BJ28: 0.451 | BK28: -0.034 | BM28: =SUMPRODUCT(R28:AD28,$R$225:$AD$225) -> 0.6610803
A29: PETR3 | B29: 0.05 | C29: =B29-E29 -> -0.004 | D29: =B29-K29 -> 0.023 | E29: =K29-L29 -> 0.054 | F29: 2.686 | G29: 5.132 | H29: commodities | I29: =VLOOKUP(A29,Planilha6!$BL$9:$BN$222,2,0) -> crude_oil | J29: =VLOOKUP(A29,Planilha6!$BL$9:$BN$222,3,0) -> very_low_beta | K29: 0.027 | L29: -0.027 | M29: =VLOOKUP(A29,'Mandato Ibov'!$B$1:$C$215,2,0) -> 0.067399922 | N29: =K29-M29 -> -0.040399922 | O29: =B29-M29 -> -0.017399922 | P29: =VLOOKUP(A29,'Mandato Ibov'!$B$2:$D$215,3,0) -> 0.062192443 | Q29: =K29-P29 -> -0.035192443 | R29: 0.005 | S29: 0.981 | T29: -0.562 | U29: 0.586 | V29: 0.679 | W29: 0.731 | X29: 0.753 | Y29: 1 | Z29: 1 | AA29: 1 | AB29: 0.679 | AC29: 0.79 | AD29: 0.899 | AE29: 0.348 | AF29: -0.325 | AG29: 1 | AH29: -0.916 | AI29: -0.569 | AJ29: -0.911 | AK29: 0.218 | AL29: 0.413 | AM29: -0.514 | AN29: -0.658 | AO29: 0.985 | AP29: 1 | AQ29: -0.241 | AR29: 0.669 | AS29: 0.465 | AT29: 0.465 | AU29: 0.344 | AV29: 0.365 | AW29: 0.411 | AX29: -0.231 | AY29: 0.814 | AZ29: 0.654 | BA29: -0.157 | BB29: -0.148 | BC29: -0.273 | BD29: 0.354 | BE29: 0.225 | BF29: 0.997 | BG29: 0.696 | BH29: -0.93 | BI29: -0.997 | BJ29: -0.111 | BK29: -0.89 | BM29: =SUMPRODUCT(R29:AD29,$R$225:$AD$225) -> 0.6573897
A30: ABCB4 | B30: =K30 -> 0.015 | C30: =B30-E30 -> 0.015 | D30: =B30-K30 -> 0 | E30: =K30-L30 -> 0 | F30: 2.667 | G30: 3.453 | H30: pro_cyclicals | I30: =VLOOKUP(A30,Planilha6!$BL$9:$BN$222,2,0) -> banks | J30: =VLOOKUP(A30,Planilha6!$BL$9:$BN$222,3,0) -> neutral_beta | K30: 0.015 | L30: 0.015 | M30: =VLOOKUP(A30,'Mandato Ibov'!$B$1:$C$215,2,0) -> 0.012021468 | N30: =K30-M30 -> 0.0029785315 | O30: =B30-M30 -> 0.0029785315 | P30: =VLOOKUP(A30,'Mandato Ibov'!$B$2:$D$215,3,0) -> 0.0074109281 | Q30: =K30-P30 -> 0.0075890719 | R30: 0.364 | S30: 0.748 | T30: 0.063 | U30: 0.314 | V30: 0.534 | W30: 0.517 | X30: 0.561 | Y30: 0.61 | Z30: 1 | AA30: 1 | AB30: 0.908 | AC30: 0.93 | AD30: 0.994 | AE30: -0.446 | AF30: 0.492 | AG30: 1 | AH30: -0.262 | AI30: 0.597 | AJ30: -0.727 | AK30: -0.052 | AL30: 0.23 | AM30: -0.009 | AN30: 0.214 | AO30: 0.585 | AP30: 0.458 | AQ30: 0.102 | AR30: 0.169 | AS30: -0.314 | AT30: -0.006 | AU30: -0.224 | AV30: -0.281 | AW30: 0.654 | AX30: -0.396 | AY30: 0.818 | AZ30: 0.432 | BA30: 0.576 | BB30: 0.065 | BC30: 0.038 | BD30: 0.392 | BE30: 0.122 | BF30: -0.167 | BG30: 0.875 | BH30: -0.641 | BI30: -0.095 | BJ30: 0.431 | BK30: 0.43 | BM30: =SUMPRODUCT(R30:AD30,$R$225:$AD$225) -> 0.6509591
A31: ALPA4 | B31: =K31 -> 0.009 | C31: =B31-E31 -> 0.009 | D31: =B31-K31 -> 0 | E31: =K31-L31 -> 0 | F31: 2.612 | G31: 2.176 | H31: pro_cyclicals | I31: =VLOOKUP(A31,Planilha6!$BL$9:$BN$222,2,0) -> apparel | J31: =VLOOKUP(A31,Planilha6!$BL$9:$BN$222,3,0) -> high_beta | K31: 0.009 | L31: 0.009 | M31: =VLOOKUP(A31,'Mandato Ibov'!$B$1:$C$215,2,0) -> 0.011772324 | N31: =K31-M31 -> -0.002772324 | O31: =B31-M31 -> -0.002772324 | P31: =VLOOKUP(A31,'Mandato Ibov'!$B$2:$D$215,3,0) -> 0.0066143629 | Q31: =K31-P31 -> 0.0023856371 | R31: 0.769 | S31: 0.503 | T31: 0.539 | U31: 0.854 | V31: 0.765 | W31: 0.622 | X31: 0.521 | Y31: 0.392 | Z31: 0.46 | AA31: 0.462 | AB31: 0.846 | AC31: 0.818 | AD31: 0.794 | AE31: 1 | AF31: 0.947 | AG31: -0.199 | AH31: -0.518 | AI31: -0.122 | AJ31: 0.311 | AK31: -0.406 | AL31: -0.083 | AM31: -0.771 | AN31: 0.575 | AO31: 0.373 | AP31: -0.366 | AQ31: 0.714 | AR31: 1 | AS31: 0.997 | AT31: 0.325 | AU31: -0.056 | AV31: 0.778 | AW31: 0.015 | AX31: -0.052 | AY31: 0.261 | AZ31: 0.362 | BA31: 0.471 | BB31: 0.457 | BC31: -0.16 | BD31: 0.703 | BE31: 0.062 | BF31: -0.297 | BG31: 0.377 | BH31: -0.188 | BI31: 0.093 | BJ31: 0.201 | BK31: -0.211 | BM31: =SUMPRODUCT(R31:AD31,$R$225:$AD$225) -> 0.6312346
A32: SAPR11 | B32: =K32 -> 0.011 | C32: =B32-E32 -> 0.011 | D32: =B32-K32 -> 0 | E32: =K32-L32 -> 0 | F32: 2.581 | G32: 2.765 | H32: bond_proxies | I32: =VLOOKUP(A32,Planilha6!$BL$9:$BN$222,2,0) -> utilities | J32: =VLOOKUP(A32,Planilha6!$BL$9:$BN$222,3,0) -> neutral_beta | K32: 0.011 | L32: 0.011 | M32: =VLOOKUP(A32,'Mandato Ibov'!$B$1:$C$215,2,0) -> 0.011634276 | N32: =K32-M32 -> -0.00063427556 | O32: =B32-M32 -> -0.00063427556 | P32: =VLOOKUP(A32,'Mandato Ibov'!$B$2:$D$215,3,0) -> 0.0079996634 | Q32: =K32-P32 -> 0.0030003366 | R32: 0.34 | S32: 0.749 | T32: -0.043 | U32: 0.709 | V32: 0.738 | W32: 0.64 | X32: 0.76 | Y32: 0.676 | Z32: 0.724 | AA32: 0.733 | AB32: 0.793 | AC32: 0.823 | AD32: 0.73 | AE32: 0.853 | AF32: 0.427 | AG32: 0.612 | AH32: -0.457 | AI32: -0.553 | AJ32: -0.148 | AK32: 0.484 | AL32: -0.228 | AM32: -0.316 | AN32: -0.075 | AO32: 0.21 | AP32: -0.219 | AQ32: 0.276 | AR32: -0.09 | AS32: -0.061 | AT32: 0.395 | AU32: 0.424 | AV32: 0.53 | AW32: 0.726 | AX32: -0.08 | AY32: 0.149 | AZ32: 0.78 | BA32: 0.212 | BB32: -0.133 | BC32: 0.179 | BD32: 0.209 | BE32: 0.131 | BF32: 1 | BG32: 0.423 | BH32: -0.833 | BI32: -0.006 | BJ32: -0.032 | BK32: 0.118 | BM32: =SUMPRODUCT(R32:AD32,$R$225:$AD$225) -> 0.6203108
A33: POMO4 | B33: =K33 -> 0.01 | C33: =B33-E33 -> 0.008 | D33: =B33-K33 -> 0 | E33: =K33-L33 -> 0.002 | F33: 2.564 | G33: 2.46 | H33: industrials | I33: =VLOOKUP(A33,Planilha6!$BL$9:$BN$222,2,0) -> capital_goods | J33: =VLOOKUP(A33,Planilha6!$BL$9:$BN$222,3,0) -> high_beta | K33: 0.01 | L33: 0.008 | M33: =VLOOKUP(A33,'Mandato Ibov'!$B$1:$C$215,2,0) -> 0.013098457 | N33: =K33-M33 -> -0.0030984567 | O33: =B33-M33 -> -0.0030984567 | P33: =VLOOKUP(A33,'Mandato Ibov'!$B$2:$D$215,3,0) -> 0 | Q33: =K33-P33 -> 0.01 | R33: 0.558 | S33: 0.607 | T33: 0.207 | U33: 0.686 | V33: 0.684 | W33: 0.801 | X33: 0.852 | Y33: 0.796 | Z33: 0.269 | AA33: 0.275 | AB33: 0.698 | AC33: 0.645 | AD33: 0.536 | AE33: 0.977 | AF33: 1 | AG33: -0.373 | AH33: -0.438 | AI33: -0.404 | AJ33: 0.405 | AK33: -0.003 | AL33: 0.384 | AM33: -0.614 | AN33: 0.468 | AO33: -0.364 | AP33: 0.378 | AQ33: 0.941 | AR33: 0.126 | AS33: -0.527 | AT33: 0.719 | AU33: -0.029 | AV33: 0.539 | AW33: 0.409 | AX33: 0.163 | AY33: 0.91 | AZ33: 1 | BA33: 0.837 | BB33: -0.046 | BC33: -0.167 | BD33: 0.084 | BE33: -0.345 | BF33: -0.598 | BG33: 0.554 | BH33: -0.923 | BI33: 0.354 | BJ33: -0.494 | BK33: -0.209 | BM33: =SUMPRODUCT(R33:AD33,$R$225:$AD$225) -> 0.6142674
A34: LOGG3 | B34: =K34 -> 0.01 | C34: =B34-E34 -> 0.01 | D34: =B34-K34 -> 0 | E34: =K34-L34 -> 0 | F34: 2.512 | G34: 2.724 | H34: bond_proxies | I34: =VLOOKUP(A34,Planilha6!$BL$9:$BN$222,2,0) -> real_estate | J34: =VLOOKUP(A34,Planilha6!$BL$9:$BN$222,3,0) -> low_beta | K34: 0.01 | L34: 0.01 | M34: =VLOOKUP(A34,'Mandato Ibov'!$B$1:$C$215,2,0) -> 0.011321078 | N34: =K34-M34 -> -0.0013210781 | O34: =B34-M34 -> -0.0013210781 | P34: =VLOOKUP(A34,'Mandato Ibov'!$B$2:$D$215,3,0) -> 0.0060706506 | Q34: =K34-P34 -> 0.0039293494 | R34: 0.234 | S34: 0.711 | T34: 0.135 | U34: 0.235 | V34: 0.525 | W34: 0.44 | X34: 0.755 | Y34: 0.617 | Z34: 0.758 | AA34: 0.764 | AB34: 0.928 | AC34: 0.849 | AD34: 0.899 | AE34: -0.115 | AF34: -0.275 | AG34: 1 | AH34: 0.248 | AI34: 1 | AJ34: -0.239 | AK34: -0.305 | AL34: 0.283 | AM34: -0.155 | AN34: -0.081 | AO34: 0.747 | AP34: 0.064 | AQ34: -0.126 | AR34: -0.043 | AS34: -0.039 | AT34: -0.077 | AU34: 0.688 | AV34: -0.158 | AW34: 0.345 | AX34: -0.782 | AY34: 0.314 | AZ34: -0.012 | BA34: -0.189 | BB34: 0.181 | BC34: 0.235 | BD34: 0.356 | BE34: 0.084 | BF34: -0.185 | BG34: 0.721 | BH34: -0.512 | BI34: 0.063 | BJ34: 0.333 | BK34: 0.283 | BM34: =SUMPRODUCT(R34:AD34,$R$225:$AD$225) -> 0.5958134
A35: ODPV3 | B35: =K35 -> 0.01 | C35: =B35-E35 -> 0.01 | D35: =B35-K35 -> 0 | E35: =K35-L35 -> 0 | F35: 2.474 | G35: 2.261 | H35: defensives | I35: =VLOOKUP(A35,Planilha6!$BL$9:$BN$222,2,0) -> healthcare | J35: =VLOOKUP(A35,Planilha6!$BL$9:$BN$222,3,0) -> very_low_beta | K35: 0.01 | L35: 0.01 | M35: =VLOOKUP(A35,'Mandato Ibov'!$B$1:$C$215,2,0) -> 0.011152737 | N35: =K35-M35 -> -0.0011527375 | O35: =B35-M35 -> -0.0011527375 | P35: =VLOOKUP(A35,'Mandato Ibov'!$B$2:$D$215,3,0) -> 0.0063914334 | Q35: =K35-P35 -> 0.0036085666 | R35: 0.341 | S35: 0.755 | T35: 0.043 | U35: 0.326 | V35: 0.516 | W35: 0.642 | X35: 0.921 | Y35: 0.699 | Z35: 0.543 | AA35: 0.549 | AB35: 0.69 | AC35: 0.702 | AD35: 0.679 | AE35: 0.549 | AF35: -0.607 | AG35: -0.312 | AH35: -0.751 | AI35: -0.03 | AJ35: 0.378 | AK35: -0.315 | AL35: -0.045 | AM35: -0.93 | AN35: -0.345 | AO35: 0.12 | AP35: 1 | AQ35: 0.004 | AR35: 0.134 | AS35: -0.309 | AT35: 0.969 | AU35: 0.426 | AV35: 1 | AW35: 0.764 | AX35: 0.427 | AY35: 0.745 | AZ35: 0.646 | BA35: 0.948 | BB35: 0.186 | BC35: -0.13 | BD35: 0.31 | BE35: -0.506 | BF35: -0.221 | BG35: 0.687 | BH35: -0.484 | BI35: -0.431 | BJ35: -0.028 | BK35: -0.122 | BM35: =SUMPRODUCT(R35:AD35,$R$225:$AD$225) -> 0.5826759
A36: EVEN3 | B36: 0.011 | C36: =B36-E36 -> 0.011 | D36: =B36-K36 -> -0.001 | E36: =K36-L36 -> 0 | F36: 2.352 | G36: 2.419 | H36: pro_cyclicals | I36: =VLOOKUP(A36,Planilha6!$BL$9:$BN$222,2,0) -> homebuilders | J36: =VLOOKUP(A36,Planilha6!$BL$9:$BN$222,3,0) -> high_beta | K36: 0.012 | L36: 0.012 | M36: =VLOOKUP(A36,'Mandato Ibov'!$B$1:$C$215,2,0) -> 0.010599059 | N36: =K36-M36 -> 0.0014009414 | O36: =B36-M36 -> 0.00040094137 | P36: =VLOOKUP(A36,'Mandato Ibov'!$B$2:$D$215,3,0) -> 0 | Q36: =K36-P36 -> 0.012 | R36: 0.59 | S36: 0.187 | T36: 0.708 | U36: 0.431 | V36: 0.506 | W36: 0.459 | X36: 0.34 | Y36: 0.301 | Z36: 0.554 | AA36: 0.556 | AB36: 0.841 | AC36: 0.924 | AD36: 0.776 | AE36: 0.691 | AF36: 0.635 | AG36: -0.165 | AH36: 0.395 | AI36: 0.196 | AJ36: -0.015 | AK36: -0.202 | AL36: 0.257 | AM36: -0.034 | AN36: 0.219 | AO36: -0.191 | AP36: -0.15 | AQ36: 0.405 | AR36: 0.92 | AS36: 0.84 | AT36: 0.016 | AU36: -0.342 | AV36: 0.313 | AW36: 0.061 | AX36: 0.027 | AY36: 0.757 | AZ36: 0.448 | BA36: 0.166 | BB36: -0.021 | BC36: -0.289 | BD36: -0.073 | BE36: 0.466 | BF36: -0.125 | BG36: 0.625 | BH36: -0.393 | BI36: 0.359 | BJ36: 0.485 | BK36: 0.411 | BM36: =SUMPRODUCT(R36:AD36,$R$225:$AD$225) -> 0.5388127
A37: CURY3 | B37: =K37 -> 0.011 | C37: =B37-E37 -> 0.009 | D37: =B37-K37 -> 0 | E37: =K37-L37 -> 0.002 | F37: 2.352 | G37: 2.494 | H37: pro_cyclicals | I37: =VLOOKUP(A37,Planilha6!$BL$9:$BN$222,2,0) -> homebuilders | J37: =VLOOKUP(A37,Planilha6!$BL$9:$BN$222,3,0) -> low_beta | K37: 0.011 | L37: 0.009 | M37: =VLOOKUP(A37,'Mandato Ibov'!$B$1:$C$215,2,0) -> 0.012374801 | N37: =K37-M37 -> -0.0013748005 | O37: =B37-M37 -> -0.0013748005 | P37: =VLOOKUP(A37,'Mandato Ibov'!$B$2:$D$215,3,0) -> 0.0074086906 | Q37: =K37-P37 -> 0.0035913094 | R37: 0.231 | S37: 0.503 | T37: -0.049 | U37: 0.509 | V37: 0.564 | W37: 0.494 | X37: 0.537 | Y37: 0.721 | Z37: 0.622 | AA37: 0.627 | AB37: 0.794 | AC37: 0.796 | AD37: 0.656 | AE37: 0.712 | AF37: 0.257 | AG37: -0.238 | AH37: -0.628 | AI37: -0.21 | AJ37: -0.034 | AK37: -0.137 | AL37: 0.385 | AM37: -0.856 | AN37: 0.119 | AO37: 0.177 | AP37: 0.465 | AQ37: 0.449 | AR37: 0.193 | AS37: 0.385 | AT37: 1 | AU37: 0.102 | AV37: 0.546 | AW37: 0.144 | AX37: 0.31 | AY37: 0.841 | AZ37: 0.963 | BA37: 0.326 | BB37: -0.759 | BC37: -0.295 | BD37: -0.274 | BE37: 0.573 | BF37: -0.043 | BG37: 0.335 | BH37: -0.981 | BI37: 0.172 | BJ37: -0.427 | BK37: -0.336 | BM37: =SUMPRODUCT(R37:AD37,$R$225:$AD$225) -> 0.5391686
A38: ALOS3 | B38: =K38 -> 0.016 | C38: =B38-E38 -> 0.01 | D38: =B38-K38 -> 0 | E38: =K38-L38 -> 0.006 | F38: 2.348 | G38: 3.874 | H38: bond_proxies | I38: =VLOOKUP(A38,Planilha6!$BL$9:$BN$222,2,0) -> real_estate | J38: =VLOOKUP(A38,Planilha6!$BL$9:$BN$222,3,0) -> high_beta | K38: 0.016 | L38: 0.01 | M38: =VLOOKUP(A38,'Mandato Ibov'!$B$1:$C$215,2,0) -> 0.018441014 | N38: =K38-M38 -> -0.0024410138 | O38: =B38-M38 -> -0.0024410138 | P38: =VLOOKUP(A38,'Mandato Ibov'!$B$2:$D$215,3,0) -> 0.013361495 | Q38: =K38-P38 -> 0.0026385051 | R38: 0.19 | S38: 0.836 | T38: -0.35 | U38: 0.447 | V38: 0.505 | W38: 0.613 | X38: 0.906 | Y38: 0.58 | Z38: 0.67 | AA38: 0.675 | AB38: 0.757 | AC38: 0.723 | AD38: 0.693 | AE38: 0.628 | AF38: -0.127 | AG38: 0.518 | AH38: -0.772 | AI38: -0.114 | AJ38: -0.293 | AK38: -0.079 | AL38: -0.193 | AM38: -0.513 | AN38: 0.018 | AO38: 0.598 | AP38: 0.472 | AQ38: 0.265 | AR38: 0.286 | AS38: -0.136 | AT38: 0.015 | AU38: 0.87 | AV38: 0.656 | AW38: 0.319 | AX38: 0.293 | AY38: 0.577 | AZ38: 0.419 | BA38: -0.7 | BB38: -0.048 | BC38: -0.143 | BD38: 0.363 | BE38: -0.388 | BF38: 0.155 | BG38: 0.749 | BH38: -0.489 | BI38: 0.381 | BJ38: -0.587 | BK38: -0.416 | BM38: =SUMPRODUCT(R38:AD38,$R$225:$AD$225) -> 0.5377946
A39: ITSA3 | B39: =K39 -> 0.021 | C39: =B39-E39 -> 0.021 | D39: =B39-K39 -> 0 | E39: =K39-L39 -> 0 | F39: 2.334 | G39: 3.14 | H39: pro_cyclicals | I39: =VLOOKUP(A39,Planilha6!$BL$9:$BN$222,2,0) -> banks | J39: =VLOOKUP(A39,Planilha6!$BL$9:$BN$222,3,0) -> neutral_beta | K39: 0.021 | L39: 0.021 | M39: =VLOOKUP(A39,'Mandato Ibov'!$B$1:$C$215,2,0) -> 0.010521458 | N39: =K39-M39 -> 0.010478542 | O39: =B39-M39 -> 0.010478542 | P39: =VLOOKUP(A39,'Mandato Ibov'!$B$2:$D$215,3,0) -> 0.0075607711 | Q39: =K39-P39 -> 0.013439229 | R39: 0.126 | S39: 0.664 | T39: -0.309 | U39: 0.276 | V39: 0.389 | W39: 0.442 | X39: 0.616 | Y39: 0.61 | Z39: 0.752 | AA39: 0.76 | AB39: 0.8 | AC39: 0.886 | AD39: 0.873 | AE39: 0.106 | AF39: -0.297 | AG39: 0.557 | AH39: -0.966 | AI39: -0.636 | AJ39: -0.845 | AK39: -0.149 | AL39: 0.186 | AM39: -0.665 | AN39: -0.399 | AO39: 0.671 | AP39: 0.685 | AQ39: -0.01 | AR39: 0.171 | AS39: 0.41 | AT39: 0.058 | AU39: 0.051 | AV39: 0.294 | AW39: 0.502 | AX39: -0.451 | AY39: 0.936 | AZ39: 0.252 | BA39: 0.911 | BB39: -0.023 | BC39: 0.321 | BD39: 0.521 | BE39: -0.231 | BF39: -0.275 | BG39: 0.832 | BH39: -0.668 | BI39: -0.017 | BJ39: 0.885 | BK39: -0.689 | BM39: =SUMPRODUCT(R39:AD39,$R$225:$AD$225) -> 0.5327716
A40: MELK3 | B40: 0.0115 | C40: =B40-E40 -> 0.0115 | D40: =B40-K40 -> -0.0015 | E40: =K40-L40 -> 0 | F40: 2.315 | G40: 2.539 | H40: pro_cyclicals | I40: =VLOOKUP(A40,Planilha6!$BL$9:$BN$222,2,0) -> homebuilders | J40: =VLOOKUP(A40,Planilha6!$BL$9:$BN$222,3,0) -> neutral_beta | K40: 0.013 | L40: 0.013 | M40: =VLOOKUP(A40,'Mandato Ibov'!$B$1:$C$215,2,0) -> 0.010436295 | N40: =K40-M40 -> 0.0025637045 | O40: =B40-M40 -> 0.0010637045 | P40: =VLOOKUP(A40,'Mandato Ibov'!$B$2:$D$215,3,0) -> 0.0071146122 | Q40: =K40-P40 -> 0.0058853878 | R40: 0.201 | S40: 0.158 | T40: 0.57 | U40: 0.021 | V40: 0.365 | W40: 0.364 | X40: 0.486 | Y40: 0.733 | Z40: 0.636 | AA40: 0.637 | AB40: 0.825 | AC40: 0.699 | AD40: 0.749 | AE40: 0.156 | AF40: -0.116 | AG40: -0.124 | AH40: 0.978 | AI40: 0.649 | AJ40: -0.077 | AK40: -0.165 | AL40: 0.986 | AM40: -0.031 | AN40: -0.049 | AO40: -0.128 | AP40: -0.022 | AQ40: 0.021 | AR40: -0.13 | AS40: -0.125 | AT40: 0.016 | AU40: -0.412 | AV40: -0.064 | AW40: 0.598 | AX40: -0.367 | AY40: 0.678 | AZ40: 0.411 | BA40: 0.231 | BB40: -0.029 | BC40: -0.434 | BD40: -0.499 | BE40: 0.43 | BF40: 0.671 | BG40: 0.881 | BH40: -0.404 | BI40: 0.265 | BJ40: 0.729 | BK40: 0.638 | BM40: =SUMPRODUCT(R40:AD40,$R$225:$AD$225) -> 0.5260785
...

Sheet 29
L1: =SUM(L3:L95) -> 26109509 | T1: =SUM(T3:T95) -> 26050660 | U1: =T1-L1 -> -58848.695 | V1: MOVI GUSTAVO | W1: =SUM(W3:W95) -> 26311337 | X1: =W1-T1 -> 260677
A2: Data | B2: Cliente | C2: Codigo | D2: Papel | E2: Bolsa. | F2: Qtde Disp. | G2: Qtde Bloq. | H2: Qtde Total | I2: Emp | J2: Pos | K2: Preço | L2: $ | M2: peso | N2: alvo | O2: dif | P2: Novo | Q2: Pos Fin | R2: Mudança | X2: PESO GUSAVO | Y2: dif alvo | AA2: EMP
A3: 46128 | B3: 29 | C3: ABEV3 | D3: AMBEV S/A ON EX | E3: BOVESPA | F3: 44400 | G3: 300 | H3: 44700 | I3: =SUMIF($E$108:$H$127,C3,$H$108:$H$127) -> 1500 | J3: =I3+H3 -> 46200 | K3: =VLOOKUP(C3,$L$138:$M$230,2,0) -> 15.43 | L3: =K3*J3 -> 712866 | M3: =L3/SUM($L$3:$L$95) -> 0.027302927 | N3: =IFERROR(VLOOKUP(C3,'[1]pesos FIA'!$E$2:$F$74,2,0),0) -> 0.0144245 | O3: =M3-N3 -> 0.012878427 | P3: =N3*$L$1 -> 376616.61 | Q3: =ROUND(P3/K3/100,0)*100 -> 24400 | R3: =(Q3-J3) -> -21800 | S3: =IF(R3+H3<0,1,0) -> 0 | T3: =(R3+J3)*K3 -> 376492 | V3: =J3+VLOOKUP(C3,$AH$3:$AJ$95,3,0) -> 24600 | W3: =V3*K3 -> 379578 | X3: =W3/SUM($W$3:$W$95) -> 0.014426405 | Y3: =X3-N3 -> 1.904861e-06 | AA3: =VLOOKUP(C3,$AH$3:$AJ$95,3,0)+H3 -> 23100 | AE3: 29 | AF3: S | AG3: VENDA | AH3: CMIN3 | AI3: 12100 | AJ3: =IF(AG3="VENDA",-AI3,AI3) -> -12100
A4: 46128 | B4: 29 | C4: ALLD3 | D4: ALLIED ON NM | E4: BOVESPA | F4: 38300 | G4: 200 | H4: 38500 | I4: =SUMIF($E$108:$H$127,C4,$H$108:$H$127) -> 0 | J4: =I4+H4 -> 38500 | K4: =VLOOKUP(C4,$L$138:$M$230,2,0) -> 6.69 | L4: =K4*J4 -> 257565 | M4: =L4/SUM($L$3:$L$95) -> 0.0098647969 | N4: =IFERROR(VLOOKUP(C4,'[1]pesos FIA'!$E$2:$F$74,2,0),0) -> 0.0076365 | O4: =M4-N4 -> 0.0022282969 | P4: =N4*$L$1 -> 199385.26 | Q4: =ROUND(P4/K4/100,0)*100 -> 29800 | R4: =(Q4-J4) -> -8700 | S4: =IF(R4+H4<0,1,0) -> 0 | T4: =(R4+J4)*K4 -> 199362 | V4: =J4+VLOOKUP(C4,$AH$3:$AJ$95,3,0) -> 29600 | W4: =V4*K4 -> 198024 | X4: =W4/SUM($W$3:$W$95) -> 0.0075261854 | Y4: =X4-N4 -> -0.00011031461 | AA4: =VLOOKUP(C4,$AH$3:$AJ$95,3,0)+H4 -> 29600 | AE4: 29 | AF4: S | AG4: VENDA | AH4: HBOR3 | AI4: 37000 | AJ4: =IF(AG4="VENDA",-AI4,AI4) -> -37000
A5: 46128 | B5: 29 | C5: ALOS3 | D5: ALLOS ON NM | E5: BOVESPA | F5: 6000 | G5: 0 | H5: 6000 | I5: =SUMIF($E$108:$H$127,C5,$H$108:$H$127) -> 0 | J5: =I5+H5 -> 6000 | K5: 33.27 | L5: =K5*J5 -> 199620 | M5: =L5/SUM($L$3:$L$95) -> 0.0076454905 | N5: =IFERROR(VLOOKUP(C5,'[1]pesos FIA'!$E$2:$F$74,2,0),0) -> 0.013576 | O5: =M5-N5 -> -0.0059305095 | P5: =N5*$L$1 -> 354462.69 | Q5: =ROUND(P5/K5/100,0)*100 -> 10700 | R5: =(Q5-J5) -> 4700 | S5: =IF(R5+H5<0,1,0) -> 0 | T5: =(R5+J5)*K5 -> 355989 | V5: =J5+VLOOKUP(C5,$AH$3:$AJ$95,3,0) -> 9900 | W5: =V5*K5 -> 329373 | X5: =W5/SUM($W$3:$W$95) -> 0.012518292 | Y5: =X5-N5 -> -0.001057708 | AA5: =VLOOKUP(C5,$AH$3:$AJ$95,3,0)+H5 -> 9900 | AE5: 29 | AF5: S | AG5: VENDA | AH5: BBAS3 | AI5: 10500 | AJ5: =IF(AG5="VENDA",-AI5,AI5) -> -10500
A6: 46128 | B6: 29 | C6: ALPA4 | D6: ALPARGATAS PN EDJ N1 | E6: BOVESPA | F6: 3800 | G6: 0 | H6: 3800 | I6: =SUMIF($E$108:$H$127,C6,$H$108:$H$127) -> 0 | J6: =I6+H6 -> 3800 | K6: =VLOOKUP(C6,$L$138:$M$230,2,0) -> 12.24 | L6: =K6*J6 -> 46512 | M6: =L6/SUM($L$3:$L$95) -> 0.00178142 | N6: =IFERROR(VLOOKUP(C6,'[1]pesos FIA'!$E$2:$F$74,2,0),0) -> 0.0076365 | O6: =M6-N6 -> -0.00585508 | P6: =N6*$L$1 -> 199385.26 | Q6: =ROUND(P6/K6/100,0)*100 -> 16300 | R6: =(Q6-J6) -> 12500 | S6: =IF(R6+H6<0,1,0) -> 0 | T6: =(R6+J6)*K6 -> 199512 | V6: =J6+VLOOKUP(C6,$AH$3:$AJ$95,3,0) -> 14100 | W6: =V6*K6 -> 172584 | X6: =W6/SUM($W$3:$W$95) -> 0.0065593018 | Y6: =X6-N6 -> -0.0010771982 | AA6: =VLOOKUP(C6,$AH$3:$AJ$95,3,0)+H6 -> 14100 | AE6: 29 | AF6: S | AG6: VENDA | AH6: LIGT3 | AI6: 9400 | AJ6: =IF(AG6="VENDA",-AI6,AI6) -> -9400
A7: 46128 | B7: 29 | C7: AXIA3 | D7: AXIA ENERGIAON EB N1 | E7: BOVESPA | F7: 11400 | G7: 0 | H7: 11400 | I7: =SUMIF($E$108:$H$127,C7,$H$108:$H$127) -> 0 | J7: =I7+H7 -> 11400 | K7: =VLOOKUP(C7,$L$138:$M$230,2,0) -> 65.56 | L7: =K7*J7 -> 747384 | M7: =L7/SUM($L$3:$L$95) -> 0.028624974 | N7: =IFERROR(VLOOKUP(C7,'[1]pesos FIA'!$E$2:$F$74,2,0),0) -> 0 | O7: =M7-N7 -> 0.028624974 | P7: =N7*$L$1 -> 0 | Q7: =ROUND(P7/K7/100,0)*100 -> 0 | R7: =(Q7-J7) -> -11400 | S7: =IF(R7+H7<0,1,0) -> 0 | T7: =(R7+J7)*K7 -> 0 | V7: =J7+VLOOKUP(C7,$AH$3:$AJ$95,3,0) -> 0 | W7: =V7*K7 -> 0 | X7: =W7/SUM($W$3:$W$95) -> 0 | Y7: =X7-N7 -> 0 | AA7: =VLOOKUP(C7,$AH$3:$AJ$95,3,0)+H7 -> 0 | AE7: 29 | AF7: S | AG7: VENDA | AH7: BBDC4 | AI7: 25900 | AJ7: =IF(AG7="VENDA",-AI7,AI7) -> -25900
A8: 46128 | B8: 29 | C8: AXIA6 | D8: AXIA ENERGIAPNB EB N1 | E8: BOVESPA | F8: 4500 | G8: 0 | H8: 4500 | I8: =SUMIF($E$108:$H$127,C8,$H$108:$H$127) -> 0 | J8: =I8+H8 -> 4500 | K8: =VLOOKUP(C8,$L$138:$M$230,2,0) -> 71.86 | L8: =K8*J8 -> 323370 | M8: =L8/SUM($L$3:$L$95) -> 0.012385143 | N8: =IFERROR(VLOOKUP(C8,'[1]pesos FIA'!$E$2:$F$74,2,0),0) -> 0.0195155 | O8: =M8-N8 -> -0.007130357 | P8: =N8*$L$1 -> 509540.12 | Q8: =ROUND(P8/K8/100,0)*100 -> 7100 | R8: =(Q8-J8) -> 2600 | S8: =IF(R8+H8<0,1,0) -> 0 | T8: =(R8+J8)*K8 -> 510206 | V8: =J8+VLOOKUP(C8,$AH$3:$AJ$95,3,0) -> 6900 | W8: =V8*K8 -> 495834 | X8: =W8/SUM($W$3:$W$95) -> 0.01884488 | Y8: =X8-N8 -> -0.00067061956 | AA8: =VLOOKUP(C8,$AH$3:$AJ$95,3,0)+H8 -> 6900 | AE8: 29 | AF8: S | AG8: VENDA | AH8: PGMN3 | AI8: 25000 | AJ8: =IF(AG8="VENDA",-AI8,AI8) -> -25000
A9: 46128 | B9: 29 | C9: BBAS3 | D9: BRASIL ON EJ NM | E9: BOVESPA | F9: 10300 | G9: 400 | H9: 10700 | I9: =SUMIF($E$108:$H$127,C9,$H$108:$H$127) -> 24000 | J9: =I9+H9 -> 34700 | K9: =VLOOKUP(C9,$L$138:$M$230,2,0) -> 24.28 | L9: =K9*J9 -> 842516 | M9: =L9/SUM($L$3:$L$95) -> 0.032268551 | N9: =IFERROR(VLOOKUP(C9,'[1]pesos FIA'!$E$2:$F$74,2,0),0) -> 0 | O9: =M9-N9 -> 0.032268551 | P9: =N9*$L$1 -> 0 | Q9: =ROUND(P9/K9/100,0)*100 -> 0 | R9: =(Q9-J9) -> -34700 | S9: =IF(R9+H9<0,1,0) -> 1 | T9: =(R9+J9)*K9 -> 0 | V9: =J9+VLOOKUP(C9,$AH$3:$AJ$95,3,0) -> 24200 | W9: =V9*K9 -> 587576 | X9: =W9/SUM($W$3:$W$95) -> 0.022331666 | Y9: =X9-N9 -> 0.022331666 | AA9: =VLOOKUP(C9,$AH$3:$AJ$95,3,0)+H9 -> 200 | AE9: 29 | AF9: S | AG9: VENDA | AH9: MGLU3 | AI9: 10800 | AJ9: =IF(AG9="VENDA",-AI9,AI9) -> -10800
A10: 46128 | B10: 29 | C10: BBDC3 | D10: BRADESCO ON N1 | E10: BOVESPA | F10: 32500 | G10: 0 | H10: 32500 | I10: =SUMIF($E$108:$H$127,C10,$H$108:$H$127) -> 0 | J10: =I10+H10 -> 32500 | K10: =VLOOKUP(C10,$L$138:$M$230,2,0) -> 18.12 | L10: =K10*J10 -> 588900 | M10: =L10/SUM($L$3:$L$95) -> 0.022555001 | N10: =IFERROR(VLOOKUP(C10,'[1]pesos FIA'!$E$2:$F$74,2,0),0) -> 0.0195155 | O10: =M10-N10 -> 0.0030395012 | P10: =N10*$L$1 -> 509540.12 | Q10: =ROUND(P10/K10/100,0)*100 -> 28100 | R10: =(Q10-J10) -> -4400 | S10: =IF(R10+H10<0,1,0) -> 0 | T10: =(R10+J10)*K10 -> 509172 | V10: =J10+VLOOKUP(C10,$AH$3:$AJ$95,3,0) -> 28000 | W10: =V10*K10 -> 507360 | X10: =W10/SUM($W$3:$W$95) -> 0.019282943 | Y10: =X10-N10 -> -0.00023255744 | AA10: =VLOOKUP(C10,$AH$3:$AJ$95,3,0)+H10 -> 28000 | AE10: 29 | AF10: S | AG10: VENDA | AH10: ABEV3 | AI10: 21600 | AJ10: =IF(AG10="VENDA",-AI10,AI10) -> -21600
A11: 46128 | B11: 29 | C11: BBDC4 | D11: BRADESCO PN N1 | E11: BOVESPA | F11: 25900 | G11: 0 | H11: 25900 | I11: =SUMIF($E$108:$H$127,C11,$H$108:$H$127) -> 0 | J11: =I11+H11 -> 25900 | K11: =VLOOKUP(C11,$L$138:$M$230,2,0) -> 20.85 | L11: =K11*J11 -> 540015 | M11: =L11/SUM($L$3:$L$95) -> 0.020682695 | N11: =IFERROR(VLOOKUP(C11,'[1]pesos FIA'!$E$2:$F$74,2,0),0) -> 0 | O11: =M11-N11 -> 0.020682695 | P11: =N11*$L$1 -> 0 | Q11: =ROUND(P11/K11/100,0)*100 -> 0 | R11: =(Q11-J11) -> -25900 | S11: =IF(R11+H11<0,1,0) -> 0 | T11: =(R11+J11)*K11 -> 0 | V11: =J11+VLOOKUP(C11,$AH$3:$AJ$95,3,0) -> 0 | W11: =V11*K11 -> 0 | X11: =W11/SUM($W$3:$W$95) -> 0 | Y11: =X11-N11 -> 0 | AA11: =VLOOKUP(C11,$AH$3:$AJ$95,3,0)+H11 -> 0 | AE11: 29 | AF11: S | AG11: VENDA | AH11: GOAU4 | AI11: 19466 | AJ11: =IF(AG11="VENDA",-AI11,AI11) -> -19466
A12: 46128 | B12: 29 | C12: BBSE3 | D12: BBSEGURIDADEON EDR NM | E12: BOVESPA | F12: 4400 | G12: 100 | H12: 4500 | I12: =SUMIF($E$108:$H$127,C12,$H$108:$H$127) -> 5500 | J12: =I12+H12 -> 10000 | K12: =VLOOKUP(C12,$L$138:$M$230,2,0) -> 35.01 | L12: =K12*J12 -> 350100 | M12: =L12/SUM($L$3:$L$95) -> 0.013408908 | N12: =IFERROR(VLOOKUP(C12,'[1]pesos FIA'!$E$2:$F$74,2,0),0) -> 0.01697 | O12: =M12-N12 -> -0.003561092 | P12: =N12*$L$1 -> 443078.36 | Q12: =ROUND(P12/K12/100,0)*100 -> 12700 | R12: =(Q12-J12) -> 2700 | S12: =IF(R12+H12<0,1,0) -> 0 | T12: =(R12+J12)*K12 -> 444627 | V12: =J12+VLOOKUP(C12,$AH$3:$AJ$95,3,0) -> 12300 | W12: =V12*K12 -> 430623 | X12: =W12/SUM($W$3:$W$95) -> 0.016366443 | Y12: =X12-N12 -> -0.0006035569 | AA12: =VLOOKUP(C12,$AH$3:$AJ$95,3,0)+H12 -> 6800 | AE12: 29 | AF12: S | AG12: VENDA | AH12: ECOR3 | AI12: 18800 | AJ12: =IF(AG12="VENDA",-AI12,AI12) -> -18800
A13: 46128 | B13: 29 | C13: BMEB4 | D13: MERCANTIL PN N1 | E13: BOVESPA | F13: 3000 | G13: 0 | H13: 3000 | I13: =SUMIF($E$108:$H$127,C13,$H$108:$H$127) -> 0 | J13: =I13+H13 -> 3000 | K13: =VLOOKUP(C13,$L$138:$M$230,2,0) -> 80.3 | L13: =K13*J13 -> 240900 | M13: =L13/SUM($L$3:$L$95) -> 0.0092265237 | N13: =IFERROR(VLOOKUP(C13,'[1]pesos FIA'!$E$2:$F$74,2,0),0) -> 0.006788 | O13: =M13-N13 -> 0.0024385237 | P13: =N13*$L$1 -> 177231.35 | Q13: =ROUND(P13/K13/100,0)*100 -> 2200 | R13: =(Q13-J13) -> -800 | S13: =IF(R13+H13<0,1,0) -> 0 | T13: =(R13+J13)*K13 -> 176660 | V13: =J13+VLOOKUP(C13,$AH$3:$AJ$95,3,0) -> 2300 | W13: =V13*K13 -> 184690 | X13: =W13/SUM($W$3:$W$95) -> 0.0070194076 | Y13: =X13-N13 -> 0.00023140764 | AA13: =VLOOKUP(C13,$AH$3:$AJ$95,3,0)+H13 -> 2300 | AE13: 29 | AF13: S | AG13: VENDA | AH13: BRAP4 | AI13: 17900 | AJ13: =IF(AG13="VENDA",-AI13,AI13) -> -17900
A14: 46128 | B14: 29 | C14: BMGB4 | D14: BANCO BMG PN N1 | E14: BOVESPA | F14: 31900 | G14: 1000 | H14: 32900 | I14: =SUMIF($E$108:$H$127,C14,$H$108:$H$127) -> 0 | J14: =I14+H14 -> 32900 | K14: =VLOOKUP(C14,$L$138:$M$230,2,0) -> 5.53 | L14: =K14*J14 -> 181937 | M14: =L14/SUM($L$3:$L$95) -> 0.0069682276 | N14: =IFERROR(VLOOKUP(C14,'[1]pesos FIA'!$E$2:$F$74,2,0),0) -> 0.008485 | O14: =M14-N14 -> -0.0015167724 | P14: =N14*$L$1 -> 221539.18 | Q14: =ROUND(P14/K14/100,0)*100 -> 40100 | R14: =(Q14-J14) -> 7200 | S14: =IF(R14+H14<0,1,0) -> 0 | T14: =(R14+J14)*K14 -> 221753 | V14: =J14+VLOOKUP(C14,$AH$3:$AJ$95,3,0) -> 39100 | W14: =V14*K14 -> 216223 | X14: =W14/SUM($W$3:$W$95) -> 0.0082178644 | Y14: =X14-N14 -> -0.00026713559 | AA14: =VLOOKUP(C14,$AH$3:$AJ$95,3,0)+H14 -> 39100 | AE14: 29 | AF14: S | AG14: VENDA | AH14: CXSE3 | AI14: 17900 | AJ14: =IF(AG14="VENDA",-AI14,AI14) -> -17900
A15: 46128 | B15: 29 | C15: BOVA11 | D15: ISHARES BOVACI | E15: BOVESPA | F15: 3891 | G15: 0 | H15: 3891 | I15: =SUMIF($E$108:$H$127,C15,$H$108:$H$127) -> 9909 | J15: =I15+H15 -> 13800 | K15: =VLOOKUP(C15,$L$138:$M$230,2,0) -> 193.05 | L15: =K15*J15 -> 2664090 | M15: =L15/SUM($L$3:$L$95) -> 0.10203524 | N15: =IFERROR(VLOOKUP(C15,'[1]pesos FIA'!$E$2:$F$74,2,0),0) -> 0.1 | O15: =M15-N15 -> 0.0020352405 | P15: =N15*$L$1 -> 2610950.9 | Q15: =ROUND(P15/K15/100,0)*100 -> 13500 | R15: =(Q15-J15) -> -300 | S15: =IF(R15+H15<0,1,0) -> 0 | T15: =(R15+J15)*K15 -> 2606175 | V15: =J15+VLOOKUP(C15,$AH$3:$AJ$95,3,0) -> 12800 | W15: =V15*K15 -> 2471040 | X15: =W15/SUM($W$3:$W$95) -> 0.09391541 | Y15: =X15-N15 -> -0.0060845901 | AA15: =VLOOKUP(C15,$AH$3:$AJ$95,3,0)+H15 -> 2891 | AE15: 29 | AF15: S | AG15: VENDA | AH15: MBRF3 | AI15: 5800 | AJ15: =IF(AG15="VENDA",-AI15,AI15) -> -5800
A16: 46128 | B16: 29 | C16: BOVV11 | D16: IT NOW IBOV CI | E16: BOVESPA | F16: 3095 | G16: 200 | H16: 3295 | I16: =SUMIF($E$108:$H$127,C16,$H$108:$H$127) -> 3405 | J16: =I16+H16 -> 6700 | K16: =VLOOKUP(C16,$L$138:$M$230,2,0) -> 202.6 | L16: =K16*J16 -> 1357420 | M16: =L16/SUM($L$3:$L$95) -> 0.051989488 | N16: =IFERROR(VLOOKUP(C16,'[1]pesos FIA'!$E$2:$F$74,2,0),0) -> 0.05 | O16: =M16-N16 -> 0.0019894884 | P16: =N16*$L$1 -> 1305475.4 | Q16: =ROUND(P16/K16/100,0)*100 -> 6400 | R16: =(Q16-J16) -> -300 | S16: =IF(R16+H16<0,1,0) -> 0 | T16: =(R16+J16)*K16 -> 1296640 | V16: =J16+VLOOKUP(C16,$AH$3:$AJ$95,3,0) -> 5900 | W16: =V16*K16 -> 1195340 | X16: =W16/SUM($W$3:$W$95) -> 0.045430607 | Y16: =X16-N16 -> -0.0045693934 | AA16: =VLOOKUP(C16,$AH$3:$AJ$95,3,0)+H16 -> 2495 | AE16: 29 | AF16: S | AG16: VENDA | AH16: ITUB3 | AI16: 8800 | AJ16: =IF(AG16="VENDA",-AI16,AI16) -> -8800
A17: 46128 | B17: 29 | C17: BRAP4 | D17: BRADESPAR PN EDJ N1 | E17: BOVESPA | F17: 22300 | G17: 0 | H17: 22300 | I17: =SUMIF($E$108:$H$127,C17,$H$108:$H$127) -> 0 | J17: =I17+H17 -> 22300 | K17: =VLOOKUP(C17,$L$138:$M$230,2,0) -> 25.05 | L17: =K17*J17 -> 558615 | M17: =L17/SUM($L$3:$L$95) -> 0.021395079 | N17: =IFERROR(VLOOKUP(C17,'[1]pesos FIA'!$E$2:$F$74,2,0),0) -> 0.0042425 | O17: =M17-N17 -> 0.017152579 | P17: =N17*$L$1 -> 110769.59 | Q17: =ROUND(P17/K17/100,0)*100 -> 4400 | R17: =(Q17-J17) -> -17900 | S17: =IF(R17+H17<0,1,0) -> 0 | T17: =(R17+J17)*K17 -> 110220 | V17: =J17+VLOOKUP(C17,$AH$3:$AJ$95,3,0) -> 4400 | W17: =V17*K17 -> 110220 | X17: =W17/SUM($W$3:$W$95) -> 0.0041890688 | Y17: =X17-N17 -> -5.3431235e-05 | AA17: =VLOOKUP(C17,$AH$3:$AJ$95,3,0)+H17 -> 4400 | AE17: 29 | AF17: S | AG17: VENDA | AH17: AXIA3 | AI17: 11400 | AJ17: =IF(AG17="VENDA",-AI17,AI17) -> -11400
... A69: 46128 | B69: 29 | C69: ABCB4 | D69: ABC BRASIL PN N2 | E69: BOVESPA | F69: 6900 | G69: 0 | H69: 6900 | I69: =SUMIF($E$108:$H$127,C69,$H$108:$H$127) -> 0 | J69: =I69+H69 -> 6900 | K69: =VLOOKUP(C69,$L$138:$M$230,2,0) -> 26.7 | L69: =K69*J69 -> 184230 | M69: =L69/SUM($L$3:$L$95) -> 0.00705605 | N69: =IFERROR(VLOOKUP(C69,'[1]pesos FIA'!$E$2:$F$74,2,0),0) -> 0.0127275 | O69: =M69-N69 -> -0.00567145 | P69: =N69*$L$1 -> 332308.77 | Q69: =ROUND(P69/K69/100,0)*100 -> 12400 | R69: =(Q69-J69) -> 5500 | S69: =IF(R69+H69<0,1,0) -> 0 | T69: =(R69+J69)*K69 -> 331080 | V69: =J69+VLOOKUP(C69,$AH$3:$AJ$95,3,0) -> 11600 | W69: =V69*K69 -> 309720 | X69: =W69/SUM($W$3:$W$95) -> 0.011771352 | Y69: =X69-N69 -> -0.00095614836 | AA69: =VLOOKUP(C69,$AH$3:$AJ$95,3,0)+H69 -> 11600 | AE69: 29 | AF69: B | AG69: COMPRA | AH69: ALPA4 | AI69: 10300 | AJ69: =IF(AG69="VENDA",-AI69,AI69) -> 10300
C70: SHUL4 | K70: =VLOOKUP(C70,$L$138:$M$230,2,0) -> 5.33 | L70: =K70*J70 -> 0 | M70: =L70/SUM($L$3:$L$95) -> 0 | N70: =IFERROR(VLOOKUP(C70,'[1]pesos FIA'!$E$2:$F$74,2,0),0) -> 0.010182 | O70: =M70-N70 -> -0.010182 | P70: =N70*$L$1 -> 265847.02 | Q70: =ROUND(P70/K70/100,0)*100 -> 49900 | R70: =(Q70-J70) -> 49900 | S70: =IF(R70+H70<0,1,0) -> 0 | T70: =(R70+J70)*K70 -> 265967 | V70: =J70+VLOOKUP(C70,$AH$3:$AJ$95,3,0) -> 42500 | W70: =V70*K70 -> 226525 | X70: =W70/SUM($W$3:$W$95) -> 0.0086094067 | Y70: =X70-N70 -> -0.0015725933 | AA70: =VLOOKUP(C70,$AH$3:$AJ$95,3,0)+H70 -> 42500 | AE70: 29 | AF70: B | AG70: COMPRA | AH70: ALUP11 | AI70: 10300 | AJ70: =IF(AG70="VENDA",-AI70,AI70) -> 10300
C71: MTRE3 | K71: =VLOOKUP(C71,$L$138:$M$230,2,0) -> 3.86 | L71: =K71*J71 -> 0 | M71: =L71/SUM($L$3:$L$95) -> 0 | N71: =IFERROR(VLOOKUP(C71,'[1]pesos FIA'!$E$2:$F$74,2,0),0) -> 0.011879 | O71: =M71-N71 -> -0.011879 | P71: =N71*$L$1 -> 310154.85 | Q71: =ROUND(P71/K71/100,0)*100 -> 80400 | R71: =(Q71-J71) -> 80400 | S71: =IF(R71+H71<0,1,0) -> 0 | T71: =(R71+J71)*K71 -> 310344 | V71: =J71+VLOOKUP(C71,$AH$3:$AJ$95,3,0) -> 69400 | W71: =V71*K71 -> 267884 | X71: =W71/SUM($W$3:$W$95) -> 0.010181315 | Y71: =X71-N71 -> -0.0016976854 | AA71: =VLOOKUP(C71,$AH$3:$AJ$95,3,0)+H71 -> 69400 | AE71: 29 | AF71: B | AG71: COMPRA | AH71: BRBI11 | AI71: 10400 | AJ71: =IF(AG71="VENDA",-AI71,AI71) -> 10400
C72: PFRM3 | K72: =VLOOKUP(C72,$L$138:$M$230,2,0) -> 8.06 | L72: =K72*J72 -> 0 | M72: =L72/SUM($L$3:$L$95) -> 0 | N72: =IFERROR(VLOOKUP(C72,'[1]pesos FIA'!$E$2:$F$74,2,0),0) -> 0.006788 | O72: =M72-N72 -> -0.006788 | P72: =N72*$L$1 -> 177231.35 | Q72: =ROUND(P72/K72/100,0)*100 -> 22000 | R72: =(Q72-J72) -> 22000 | S72: =IF(R72+H72<0,1,0) -> 0 | T72: =(R72+J72)*K72 -> 177320 | V72: =J72+VLOOKUP(C72,$AH$3:$AJ$95,3,0) -> 18900 | W72: =V72*K72 -> 152334 | X72: =W72/SUM($W$3:$W$95) -> 0.0057896716 | Y72: =X72-N72 -> -0.00099832842 | AA72: =VLOOKUP(C72,$AH$3:$AJ$95,3,0)+H72 -> 18900 | AE72: 29 | AF72: B | AG72: COMPRA | AH72: ODPV3 | AI72: 11900 | AJ72: =IF(AG72="VENDA",-AI72,AI72) -> 11900
C73: DEXP3 | K73: =VLOOKUP(C73,$L$138:$M$230,2,0) -> 7.33 | L73: =K73*J73 -> 0 | M73: =L73/SUM($L$3:$L$95) -> 0 | N73: =IFERROR(VLOOKUP(C73,'[1]pesos FIA'!$E$2:$F$74,2,0),0) -> 0.0093335 | O73: =M73-N73 -> -0.0093335 | P73: =N73*$L$1 -> 243693.1 | Q73: =ROUND(P73/K73/100,0)*100 -> 33200 | R73: =(Q73-J73) -> 33200 | S73: =IF(R73+H73<0,1,0) -> 0 | T73: =(R73+J73)*K73 -> 243356 | V73: =J73+VLOOKUP(C73,$AH$3:$AJ$95,3,0) -> 28200 | W73: =V73*K73 -> 206706 | X73: =W73/SUM($W$3:$W$95) -> 0.0078561572 | Y73: =X73-N73 -> -0.0014773428 | AA73: =VLOOKUP(C73,$AH$3:$AJ$95,3,0)+H73 -> 28200 | AE73: 29 | AF73: B | AG73: COMPRA | AH73: LREN3 | AI73: 12300 | AJ73: =IF(AG73="VENDA",-AI73,AI73) -> 12300
